Workbook

Sheet Summary
A1: Party-wise Summary (Total Pieces & Total Weight) | K1: 7861 | Z1: =IFERROR("'"&INDEX($N$3:$N$10,MATCH($D$13,$A$3:$A$10,0))&"'!","")
A2: Party | B2: Section | C2: Total Pieces | D2: Total Weight (MT) | E2: Hold Pieces | F2: Hold Weight (MT) | G2: Accepted Pieces | H2: Accepted Weight (MT) | Z2: =IFERROR(INDEX($O$3:$O$10,MATCH($D$13,$A$3:$A$10,0)),"NA")
A3: VRKP | B3: 130 X 130 | C3: =SUMIF(Master!$A$2:$A$1001,"VRKP",Master!$K$2:$K$1001) | D3: =ROUND(SUMIF(Master!$A$2:$A$1001,"VRKP",Master!$L$2:$L$1001),3) | E3: =SUMIF(VRKP!$N$5:$N$304,"HOLD",VRKP!$L$5:$L$304) | F3: =ROUND(SUMIF(VRKP!$N$5:$N$304,"HOLD",VRKP!$M$5:$M$304),3) | G3: =C3-E3 | H3: =D3-F3 | N3: VRKP | O3: NA | P3: 0.12 | Q3: 0.05 | R3: NA | S3: 0.085 | T3: 0.5 | U3: 120 | V3: 0.08 | W3: NA | X3: NA | Z3: =IFERROR(INDEX($P$3:$P$10,MATCH($D$13,$A$3:$A$10,0)),"NA")
A4: SHREE RADHE | B4: 130 X 130 | C4: =SUMIF(Master!$A$2:$A$1001,"SHREE RADHE",Master!$K$2:$K$1001) | D4: =ROUND(SUMIF(Master!$A$2:$A$1001,"SHREE RADHE",Master!$L$2:$L$1001),3) | E4: =SUMIF('Shree Radhe'!$N$5:$N$304,"HOLD",'Shree Radhe'!$L$5:$L$304) | F4: =ROUND(SUMIF('Shree Radhe'!$N$5:$N$304,"HOLD",'Shree Radhe'!$M$5:$M$304),3) | G4: =C4-E4 | H4: =D4-F4 | N4: Shree Radhe | O4: NA | P4: 0.15 | Q4: 0.045 | R4: NA | S4: 0.08 | T4: 0.5 | U4: NA | V4: 0.1 | W4: NA | X4: NA | Z4: =IFERROR(INDEX($Q$3:$Q$10,MATCH($D$13,$A$3:$A$10,0)),"NA")
A5: SWADESH | B5: 160 X 160 | C5: =SUMIF(Master!$A$2:$A$1001,"SWADESH",Master!$K$2:$K$1001) | D5: =ROUND(SUMIF(Master!$A$2:$A$1001,"SWADESH",Master!$L$2:$L$1001),3) | E5: =SUMIF(Swadesh!$N$5:$N$304,"HOLD",Swadesh!$L$5:$L$304) | F5: =ROUND(SUMIF(Swadesh!$N$5:$N$304,"HOLD",Swadesh!$M$5:$M$304),3) | G5: =C5-E5 | H5: =D5-F5 | N5: Swadesh | O5: NA | P5: 0.15 | Q5: 0.045 | R5: NA | S5: 0.08 | T5: 0.5 | U5: NA | V5: 0.1 | W5: NA | X5: NA | Z5: =IFERROR(INDEX($R$3:$R$10,MATCH($D$13,$A$3:$A$10,0)),"NA")
A6: SHYAM METALLIKS (130x130) | B6: 130 X 130 | C6: =SUMIFS(Master!$K$2:$K$1001,Master!$A$2:$A$1001,"SHYAM METALLIKS",Master!$M$2:$M$1001,"130 x 130 x 6MTR") | D6: =ROUND(SUMIFS(Master!$L$2:$L$1001,Master!$A$2:$A$1001,"SHYAM METALLIKS",Master!$M$2:$M$1001,"130 x 130 x 6MTR"),3) | E6: =SUMIF('Shyam Metaliks'!$N$5:$N$304,"HOLD",'Shyam Metaliks'!$L$5:$L$304) | F6: =ROUND(SUMIF('Shyam Metaliks'!$N$5:$N$304,"HOLD",'Shyam Metaliks'!$M$5:$M$304),3) | G6: =C6-E6 | H6: =D6-F6 | N6: Shyam Metaliks | O6: NA | P6: 0.18 | Q6: 0.045 | R6: NA | S6: 0.08 | T6: 0.4 | U6: NA | V6: 0.1 | W6: NA | X6: 0.14 | Z6: =IFERROR(INDEX($S$3:$S$10,MATCH($D$13,$A$3:$A$10,0)),"NA")
A7: SHYAM METALLIKS (160x160) | B7: 160 X 160 | C7: =SUMIFS(Master!$K$2:$K$1001,Master!$A$2:$A$1001,"SHYAM METALLIKS",Master!$M$2:$M$1001,"160 x 160 x 6MTR") | D7: =ROUND(SUMIFS(Master!$L$2:$L$1001,Master!$A$2:$A$1001,"SHYAM METALLIKS",Master!$M$2:$M$1001,"160 x 160 x 6MTR"),3) | E7: =SUMIF('Shyam Metaliks (160)'!$N$5:$N$304,"HOLD",'Shyam Metaliks (160)'!$L$5:$L$304) | F7: =ROUND(SUMIF('Shyam Metaliks (160)'!$N$5:$N$304,"HOLD",'Shyam Metaliks (160)'!$M$5:$M$304),3) | G7: =C7-E7 | H7: =D7-F7 | N7: Shyam Metaliks (160) | O7: NA | P7: 0.18 | Q7: NA | R7: NA | S7: NA | T7: 0.4 | U7: NA | V7: 0.1 | W7: NA | X7: 0.14 | Z7: =IFERROR(INDEX($T$3:$T$10,MATCH($D$13,$A$3:$A$10,0)),"NA")
A8: MASHIVA STEEL AND ALLOYS LLP | B8: 160 X 160 | C8: =SUMIF(Master!$A$2:$A$1001,"MASHIVA STEEL AND ALLOYS LLP",Master!$K$2:$K$1001) | D8: =ROUND(SUMIF(Master!$A$2:$A$1001,"MASHIVA STEEL AND ALLOYS LLP",Master!$L$2:$L$1001),3) | E8: =SUMIF(MASHIVA!$N$5:$N$304,"HOLD",MASHIVA!$L$5:$L$304) | F8: =ROUND(SUMIF(MASHIVA!$N$5:$N$304,"HOLD",MASHIVA!$M$5:$M$304),3) | G8: =C8-E8 | H8: =D8-F8 | N8: MASHIVA | O8: NA | P8: 0.15 | Q8: NA | R8: NA | S8: NA | T8: 0.45 | U8: NA | V8: 0.1 | W8: NA | X8: 0.15 | Z8: =IFERROR(INDEX($U$3:$U$10,MATCH($D$13,$A$3:$A$10,0)),"NA")
A9: AKASH SALES | B9: 130 X 130 | C9: =SUMIF(Master!$A$2:$A$1001,"AKASH SALES",Master!$K$2:$K$1001) | D9: =ROUND(SUMIF(Master!$A$2:$A$1001,"AKASH SALES",Master!$L$2:$L$1001),3) | E9: =SUMIF('Akash Sales'!$N$5:$N$304,"HOLD",'Akash Sales'!$L$5:$L$304) | F9: =ROUND(SUMIF('Akash Sales'!$N$5:$N$304,"HOLD",'Akash Sales'!$M$5:$M$304),3) | G9: =C9-E9 | H9: =D9-F9 | N9: Akash Sales | O9: NA | P9: 0.18 | Q9: NA | R9: NA | S9: NA | T9: 0.45 | U9: NA | V9: 0.1 | W9: NA | X9: 0.15 | Z9: =IFERROR(INDEX($V$3:$V$10,MATCH($D$13,$A$3:$A$10,0)),"NA")
A10: AR ISPAT | B10: 160 X 160 | C10: =SUMIF(Master!$A$2:$A$1001,"AR ISPAT",Master!$K$2:$K$1001) | D10: =ROUND(SUMIF(Master!$A$2:$A$1001,"AR ISPAT",Master!$L$2:$L$1001),3) | E10: =SUMIF('AR Ispat'!$N$5:$N$304,"HOLD",'AR Ispat'!$L$5:$L$304) | F10: =ROUND(SUMIF('AR Ispat'!$N$5:$N$304,"HOLD",'AR Ispat'!$M$5:$M$304),3) | G10: =C10-E10 | H10: =D10-F10 | N10: AR Ispat | O10: NA | P10: 0.18 | Q10: NA | R10: NA | S10: NA | T10: 0.45 | U10: NA | V10: 0.1 | W10: NA | X10: 0.15 | Z10: =IFERROR(INDEX($W$3:$W$10,MATCH($D$13,$A$3:$A$10,0)),"NA")
A11: TOTAL | C11: =SUM(C3:C10) | D11: =ROUND(SUM(D3:D10),3) | E11: =SUM(E3:E10) | F11: =ROUND(SUM(F3:F10),3) | G11: =ROUND(SUM(G3:G10),3) | H11: =ROUND(SUM(H3:H10),3) | Z11: =IFERROR(INDEX($X$3:$X$10,MATCH($D$13,$A$3:$A$10,0)),"NA")
B13: Select Party (Out-of-Spec Heats): | D13: SHYAM METALLIKS (160x160)
B15: Heat No. | C15: Dated | D15: Vehicle No | E15: C | F15: S | G15: P | H15: Mn | I15: N | J15: Si
B16: =IF($M16="","",INDEX(INDIRECT($Z$1&"$A$5:$A$304"),$M16)) | C16: =IF($M16="","",INDEX(INDIRECT($Z$1&"$B$5:$B$304"),$M16)) | D16: =IF($M16="","",INDEX(INDIRECT($Z$1&"$C$5:$C$304"),$M16)) | E16: =IF($M16="","",INDEX(INDIRECT($Z$1&"$E$5:$E$304"),$M16)) | F16: =IF($M16="","",INDEX(INDIRECT($Z$1&"$F$5:$F$304"),$M16)) | G16: =IF($M16="","",INDEX(INDIRECT($Z$1&"$G$5:$G$304"),$M16)) | H16: =IF($M16="","",INDEX(INDIRECT($Z$1&"$H$5:$H$304"),$M16)) | I16: =IF($M16="","",INDEX(INDIRECT($Z$1&"$I$5:$I$304"),$M16)) | J16: =IF($M16="","",INDEX(INDIRECT($Z$1&"$J$5:$J$304"),$M16)) | M16: {=IFERROR(SMALL(IF(INDIRECT($Z$1&"$P$5:$P$304")=1,ROW(INDIRECT($Z$1&"$A$5:$A$304"))-ROW(INDIRECT($Z$1&"$A$5"))+1),1),"")}
B17: =IF($M17="","",INDEX(INDIRECT($Z$1&"$A$5:$A$304"),$M17)) | C17: =IF($M17="","",INDEX(INDIRECT($Z$1&"$B$5:$B$304"),$M17)) | D17: =IF($M17="","",INDEX(INDIRECT($Z$1&"$C$5:$C$304"),$M17)) | E17: =IF($M17="","",INDEX(INDIRECT($Z$1&"$E$5:$E$304"),$M17)) | F17: =IF($M17="","",INDEX(INDIRECT($Z$1&"$F$5:$F$304"),$M17)) | G17: =IF($M17="","",INDEX(INDIRECT($Z$1&"$G$5:$G$304"),$M17)) | H17: =IF($M17="","",INDEX(INDIRECT($Z$1&"$H$5:$H$304"),$M17)) | I17: =IF($M17="","",INDEX(INDIRECT($Z$1&"$I$5:$I$304"),$M17)) | J17: =IF($M17="","",INDEX(INDIRECT($Z$1&"$J$5:$J$304"),$M17)) | M17: {=IFERROR(SMALL(IF(INDIRECT($Z$1&"$P$5:$P$304")=1,ROW(INDIRECT($Z$1&"$A$5:$A$304"))-ROW(INDIRECT($Z$1&"$A$5"))+1),2),"")}
B18: =IF($M18="","",INDEX(INDIRECT($Z$1&"$A$5:$A$304"),$M18)) | C18: =IF($M18="","",INDEX(INDIRECT($Z$1&"$B$5:$B$304"),$M18)) | D18: =IF($M18="","",INDEX(INDIRECT($Z$1&"$C$5:$C$304"),$M18)) | E18: =IF($M18="","",INDEX(INDIRECT($Z$1&"$E$5:$E$304"),$M18)) | F18: =IF($M18="","",INDEX(INDIRECT($Z$1&"$F$5:$F$304"),$M18)) | G18: =IF($M18="","",INDEX(INDIRECT($Z$1&"$G$5:$G$304"),$M18)) | H18: =IF($M18="","",INDEX(INDIRECT($Z$1&"$H$5:$H$304"),$M18)) | I18: =IF($M18="","",INDEX(INDIRECT($Z$1&"$I$5:$I$304"),$M18)) | J18: =IF($M18="","",INDEX(INDIRECT($Z$1&"$J$5:$J$304"),$M18)) | M18: {=IFERROR(SMALL(IF(INDIRECT($Z$1&"$P$5:$P$304")=1,ROW(INDIRECT($Z$1&"$A$5:$A$304"))-ROW(INDIRECT($Z$1&"$A$5"))+1),3),"")}
B19: =IF($M19="","",INDEX(INDIRECT($Z$1&"$A$5:$A$304"),$M19)) | C19: =IF($M19="","",INDEX(INDIRECT($Z$1&"$B$5:$B$304"),$M19)) | D19: =IF($M19="","",INDEX(INDIRECT($Z$1&"$C$5:$C$304"),$M19)) | E19: =IF($M19="","",INDEX(INDIRECT($Z$1&"$E$5:$E$304"),$M19)) | F19: =IF($M19="","",INDEX(INDIRECT($Z$1&"$F$5:$F$304"),$M19)) | G19: =IF($M19="","",INDEX(INDIRECT($Z$1&"$G$5:$G$304"),$M19)) | H19: =IF($M19="","",INDEX(INDIRECT($Z$1&"$H$5:$H$304"),$M19)) | I19: =IF($M19="","",INDEX(INDIRECT($Z$1&"$I$5:$I$304"),$M19)) | J19: =IF($M19="","",INDEX(INDIRECT($Z$1&"$J$5:$J$304"),$M19)) | M19: {=IFERROR(SMALL(IF(INDIRECT($Z$1&"$P$5:$P$304")=1,ROW(INDIRECT($Z$1&"$A$5:$A$304"))-ROW(INDIRECT($Z$1&"$A$5"))+1),4),"")}
B20: =IF($M20="","",INDEX(INDIRECT($Z$1&"$A$5:$A$304"),$M20)) | C20: =IF($M20="","",INDEX(INDIRECT($Z$1&"$B$5:$B$304"),$M20)) | D20: =IF($M20="","",INDEX(INDIRECT($Z$1&"$C$5:$C$304"),$M20)) | E20: =IF($M20="","",INDEX(INDIRECT($Z$1&"$E$5:$E$304"),$M20)) | F20: =IF($M20="","",INDEX(INDIRECT($Z$1&"$F$5:$F$304"),$M20)) | G20: =IF($M20="","",INDEX(INDIRECT($Z$1&"$G$5:$G$304"),$M20)) | H20: =IF($M20="","",INDEX(INDIRECT($Z$1&"$H$5:$H$304"),$M20)) | I20: =IF($M20="","",INDEX(INDIRECT($Z$1&"$I$5:$I$304"),$M20)) | J20: =IF($M20="","",INDEX(INDIRECT($Z$1&"$J$5:$J$304"),$M20)) | M20: {=IFERROR(SMALL(IF(INDIRECT($Z$1&"$P$5:$P$304")=1,ROW(INDIRECT($Z$1&"$A$5:$A$304"))-ROW(INDIRECT($Z$1&"$A$5"))+1),5),"")}
B21: =IF($M21="","",INDEX(INDIRECT($Z$1&"$A$5:$A$304"),$M21)) | C21: =IF($M21="","",INDEX(INDIRECT($Z$1&"$B$5:$B$304"),$M21)) | D21: =IF($M21="","",INDEX(INDIRECT($Z$1&"$C$5:$C$304"),$M21)) | E21: =IF($M21="","",INDEX(INDIRECT($Z$1&"$E$5:$E$304"),$M21)) | F21: =IF($M21="","",INDEX(INDIRECT($Z$1&"$F$5:$F$304"),$M21)) | G21: =IF($M21="","",INDEX(INDIRECT($Z$1&"$G$5:$G$304"),$M21)) | H21: =IF($M21="","",INDEX(INDIRECT($Z$1&"$H$5:$H$304"),$M21)) | I21: =IF($M21="","",INDEX(INDIRECT($Z$1&"$I$5:$I$304"),$M21)) | J21: =IF($M21="","",INDEX(INDIRECT($Z$1&"$J$5:$J$304"),$M21)) | M21: {=IFERROR(SMALL(IF(INDIRECT($Z$1&"$P$5:$P$304")=1,ROW(INDIRECT($Z$1&"$A$5:$A$304"))-ROW(INDIRECT($Z$1&"$A$5"))+1),6),"")}
B22: =IF($M22="","",INDEX(INDIRECT($Z$1&"$A$5:$A$304"),$M22)) | C22: =IF($M22="","",INDEX(INDIRECT($Z$1&"$B$5:$B$304"),$M22)) | D22: =IF($M22="","",INDEX(INDIRECT($Z$1&"$C$5:$C$304"),$M22)) | E22: =IF($M22="","",INDEX(INDIRECT($Z$1&"$E$5:$E$304"),$M22)) | F22: =IF($M22="","",INDEX(INDIRECT($Z$1&"$F$5:$F$304"),$M22)) | G22: =IF($M22="","",INDEX(INDIRECT($Z$1&"$G$5:$G$304"),$M22)) | H22: =IF($M22="","",INDEX(INDIRECT($Z$1&"$H$5:$H$304"),$M22)) | I22: =IF($M22="","",INDEX(INDIRECT($Z$1&"$I$5:$I$304"),$M22)) | J22: =IF($M22="","",INDEX(INDIRECT($Z$1&"$J$5:$J$304"),$M22)) | M22: {=IFERROR(SMALL(IF(INDIRECT($Z$1&"$P$5:$P$304")=1,ROW(INDIRECT($Z$1&"$A$5:$A$304"))-ROW(INDIRECT($Z$1&"$A$5"))+1),7),"")}
B23: =IF($M23="","",INDEX(INDIRECT($Z$1&"$A$5:$A$304"),$M23)) | C23: =IF($M23="","",INDEX(INDIRECT($Z$1&"$B$5:$B$304"),$M23)) | D23: =IF($M23="","",INDEX(INDIRECT($Z$1&"$C$5:$C$304"),$M23)) | E23: =IF($M23="","",INDEX(INDIRECT($Z$1&"$E$5:$E$304"),$M23)) | F23: =IF($M23="","",INDEX(INDIRECT($Z$1&"$F$5:$F$304"),$M23)) | G23: =IF($M23="","",INDEX(INDIRECT($Z$1&"$G$5:$G$304"),$M23)) | H23: =IF($M23="","",INDEX(INDIRECT($Z$1&"$H$5:$H$304"),$M23)) | I23: =IF($M23="","",INDEX(INDIRECT($Z$1&"$I$5:$I$304"),$M23)) | J23: =IF($M23="","",INDEX(INDIRECT($Z$1&"$J$5:$J$304"),$M23)) | M23: {=IFERROR(SMALL(IF(INDIRECT($Z$1&"$P$5:$P$304")=1,ROW(INDIRECT($Z$1&"$A$5:$A$304"))-ROW(INDIRECT($Z$1&"$A$5"))+1),8),"")}
B24: =IF($M24="","",INDEX(INDIRECT($Z$1&"$A$5:$A$304"),$M24)) | C24: =IF($M24="","",INDEX(INDIRECT($Z$1&"$B$5:$B$304"),$M24)) | D24: =IF($M24="","",INDEX(INDIRECT($Z$1&"$C$5:$C$304"),$M24)) | E24: =IF($M24="","",INDEX(INDIRECT($Z$1&"$E$5:$E$304"),$M24)) | F24: =IF($M24="","",INDEX(INDIRECT($Z$1&"$F$5:$F$304"),$M24)) | G24: =IF($M24="","",INDEX(INDIRECT($Z$1&"$G$5:$G$304"),$M24)) | H24: =IF($M24="","",INDEX(INDIRECT($Z$1&"$H$5:$H$304"),$M24)) | I24: =IF($M24="","",INDEX(INDIRECT($Z$1&"$I$5:$I$304"),$M24)) | J24: =IF($M24="","",INDEX(INDIRECT($Z$1&"$J$5:$J$304"),$M24)) | M24: {=IFERROR(SMALL(IF(INDIRECT($Z$1&"$P$5:$P$304")=1,ROW(INDIRECT($Z$1&"$A$5:$A$304"))-ROW(INDIRECT($Z$1&"$A$5"))+1),9),"")}
B25: =IF($M25="","",INDEX(INDIRECT($Z$1&"$A$5:$A$304"),$M25)) | C25: =IF($M25="","",INDEX(INDIRECT($Z$1&"$B$5:$B$304"),$M25)) | D25: =IF($M25="","",INDEX(INDIRECT($Z$1&"$C$5:$C$304"),$M25)) | E25: =IF($M25="","",INDEX(INDIRECT($Z$1&"$E$5:$E$304"),$M25)) | F25: =IF($M25="","",INDEX(INDIRECT($Z$1&"$F$5:$F$304"),$M25)) | G25: =IF($M25="","",INDEX(INDIRECT($Z$1&"$G$5:$G$304"),$M25)) | H25: =IF($M25="","",INDEX(INDIRECT($Z$1&"$H$5:$H$304"),$M25)) | I25: =IF($M25="","",INDEX(INDIRECT($Z$1&"$I$5:$I$304"),$M25)) | J25: =IF($M25="","",INDEX(INDIRECT($Z$1&"$J$5:$J$304"),$M25)) | M25: {=IFERROR(SMALL(IF(INDIRECT($Z$1&"$P$5:$P$304")=1,ROW(INDIRECT($Z$1&"$A$5:$A$304"))-ROW(INDIRECT($Z$1&"$A$5"))+1),10),"")}
B26: =IF($M26="","",INDEX(INDIRECT($Z$1&"$A$5:$A$304"),$M26)) | C26: =IF($M26="","",INDEX(INDIRECT($Z$1&"$B$5:$B$304"),$M26)) | D26: =IF($M26="","",INDEX(INDIRECT($Z$1&"$C$5:$C$304"),$M26)) | E26: =IF($M26="","",INDEX(INDIRECT($Z$1&"$E$5:$E$304"),$M26)) | F26: =IF($M26="","",INDEX(INDIRECT($Z$1&"$F$5:$F$304"),$M26)) | G26: =IF($M26="","",INDEX(INDIRECT($Z$1&"$G$5:$G$304"),$M26)) | H26: =IF($M26="","",INDEX(INDIRECT($Z$1&"$H$5:$H$304"),$M26)) | I26: =IF($M26="","",INDEX(INDIRECT($Z$1&"$I$5:$I$304"),$M26)) | J26: =IF($M26="","",INDEX(INDIRECT($Z$1&"$J$5:$J$304"),$M26)) | M26: {=IFERROR(SMALL(IF(INDIRECT($Z$1&"$P$5:$P$304")=1,ROW(INDIRECT($Z$1&"$A$5:$A$304"))-ROW(INDIRECT($Z$1&"$A$5"))+1),11),"")}
B27: =IF($M27="","",INDEX(INDIRECT($Z$1&"$A$5:$A$304"),$M27)) | C27: =IF($M27="","",INDEX(INDIRECT($Z$1&"$B$5:$B$304"),$M27)) | D27: =IF($M27="","",INDEX(INDIRECT($Z$1&"$C$5:$C$304"),$M27)) | E27: =IF($M27="","",INDEX(INDIRECT($Z$1&"$E$5:$E$304"),$M27)) | F27: =IF($M27="","",INDEX(INDIRECT($Z$1&"$F$5:$F$304"),$M27)) | G27: =IF($M27="","",INDEX(INDIRECT($Z$1&"$G$5:$G$304"),$M27)) | H27: =IF($M27="","",INDEX(INDIRECT($Z$1&"$H$5:$H$304"),$M27)) | I27: =IF($M27="","",INDEX(INDIRECT($Z$1&"$I$5:$I$304"),$M27)) | J27: =IF($M27="","",INDEX(INDIRECT($Z$1&"$J$5:$J$304"),$M27)) | M27: {=IFERROR(SMALL(IF(INDIRECT($Z$1&"$P$5:$P$304")=1,ROW(INDIRECT($Z$1&"$A$5:$A$304"))-ROW(INDIRECT($Z$1&"$A$5"))+1),12),"")}
B28: =IF($M28="","",INDEX(INDIRECT($Z$1&"$A$5:$A$304"),$M28)) | C28: =IF($M28="","",INDEX(INDIRECT($Z$1&"$B$5:$B$304"),$M28)) | D28: =IF($M28="","",INDEX(INDIRECT($Z$1&"$C$5:$C$304"),$M28)) | E28: =IF($M28="","",INDEX(INDIRECT($Z$1&"$E$5:$E$304"),$M28)) | F28: =IF($M28="","",INDEX(INDIRECT($Z$1&"$F$5:$F$304"),$M28)) | G28: =IF($M28="","",INDEX(INDIRECT($Z$1&"$G$5:$G$304"),$M28)) | H28: =IF($M28="","",INDEX(INDIRECT($Z$1&"$H$5:$H$304"),$M28)) | I28: =IF($M28="","",INDEX(INDIRECT($Z$1&"$I$5:$I$304"),$M28)) | J28: =IF($M28="","",INDEX(INDIRECT($Z$1&"$J$5:$J$304"),$M28)) | M28: {=IFERROR(SMALL(IF(INDIRECT($Z$1&"$P$5:$P$304")=1,ROW(INDIRECT($Z$1&"$A$5:$A$304"))-ROW(INDIRECT($Z$1&"$A$5"))+1),13),"")}
B29: =IF($M29="","",INDEX(INDIRECT($Z$1&"$A$5:$A$304"),$M29)) | C29: =IF($M29="","",INDEX(INDIRECT($Z$1&"$B$5:$B$304"),$M29)) | D29: =IF($M29="","",INDEX(INDIRECT($Z$1&"$C$5:$C$304"),$M29)) | E29: =IF($M29="","",INDEX(INDIRECT($Z$1&"$E$5:$E$304"),$M29)) | F29: =IF($M29="","",INDEX(INDIRECT($Z$1&"$F$5:$F$304"),$M29)) | G29: =IF($M29="","",INDEX(INDIRECT($Z$1&"$G$5:$G$304"),$M29)) | H29: =IF($M29="","",INDEX(INDIRECT($Z$1&"$H$5:$H$304"),$M29)) | I29: =IF($M29="","",INDEX(INDIRECT($Z$1&"$I$5:$I$304"),$M29)) | J29: =IF($M29="","",INDEX(INDIRECT($Z$1&"$J$5:$J$304"),$M29)) | M29: {=IFERROR(SMALL(IF(INDIRECT($Z$1&"$P$5:$P$304")=1,ROW(INDIRECT($Z$1&"$A$5:$A$304"))-ROW(INDIRECT($Z$1&"$A$5"))+1),14),"")}
B30: =IF($M30="","",INDEX(INDIRECT($Z$1&"$A$5:$A$304"),$M30)) | C30: =IF($M30="","",INDEX(INDIRECT($Z$1&"$B$5:$B$304"),$M30)) | D30: =IF($M30="","",INDEX(INDIRECT($Z$1&"$C$5:$C$304"),$M30)) | E30: =IF($M30="","",INDEX(INDIRECT($Z$1&"$E$5:$E$304"),$M30)) | F30: =IF($M30="","",INDEX(INDIRECT($Z$1&"$F$5:$F$304"),$M30)) | G30: =IF($M30="","",INDEX(INDIRECT($Z$1&"$G$5:$G$304"),$M30)) | H30: =IF($M30="","",INDEX(INDIRECT($Z$1&"$H$5:$H$304"),$M30)) | I30: =IF($M30="","",INDEX(INDIRECT($Z$1&"$I$5:$I$304"),$M30)) | J30: =IF($M30="","",INDEX(INDIRECT($Z$1&"$J$5:$J$304"),$M30)) | M30: {=IFERROR(SMALL(IF(INDIRECT($Z$1&"$P$5:$P$304")=1,ROW(INDIRECT($Z$1&"$A$5:$A$304"))-ROW(INDIRECT($Z$1&"$A$5"))+1),15),"")}
B31: =IF($M31="","",INDEX(INDIRECT($Z$1&"$A$5:$A$304"),$M31)) | C31: =IF($M31="","",INDEX(INDIRECT($Z$1&"$B$5:$B$304"),$M31)) | D31: =IF($M31="","",INDEX(INDIRECT($Z$1&"$C$5:$C$304"),$M31)) | E31: =IF($M31="","",INDEX(INDIRECT($Z$1&"$E$5:$E$304"),$M31)) | F31: =IF($M31="","",INDEX(INDIRECT($Z$1&"$F$5:$F$304"),$M31)) | G31: =IF($M31="","",INDEX(INDIRECT($Z$1&"$G$5:$G$304"),$M31)) | H31: =IF($M31="","",INDEX(INDIRECT($Z$1&"$H$5:$H$304"),$M31)) | I31: =IF($M31="","",INDEX(INDIRECT($Z$1&"$I$5:$I$304"),$M31)) | J31: =IF($M31="","",INDEX(INDIRECT($Z$1&"$J$5:$J$304"),$M31)) | M31: {=IFERROR(SMALL(IF(INDIRECT($Z$1&"$P$5:$P$304")=1,ROW(INDIRECT($Z$1&"$A$5:$A$304"))-ROW(INDIRECT($Z$1&"$A$5"))+1),16),"")}
B32: =IF($M32="","",INDEX(INDIRECT($Z$1&"$A$5:$A$304"),$M32)) | C32: =IF($M32="","",INDEX(INDIRECT($Z$1&"$B$5:$B$304"),$M32)) | D32: =IF($M32="","",INDEX(INDIRECT($Z$1&"$C$5:$C$304"),$M32)) | E32: =IF($M32="","",INDEX(INDIRECT($Z$1&"$E$5:$E$304"),$M32)) | F32: =IF($M32="","",INDEX(INDIRECT($Z$1&"$F$5:$F$304"),$M32)) | G32: =IF($M32="","",INDEX(INDIRECT($Z$1&"$G$5:$G$304"),$M32)) | H32: =IF($M32="","",INDEX(INDIRECT($Z$1&"$H$5:$H$304"),$M32)) | I32: =IF($M32="","",INDEX(INDIRECT($Z$1&"$I$5:$I$304"),$M32)) | J32: =IF($M32="","",INDEX(INDIRECT($Z$1&"$J$5:$J$304"),$M32)) | M32: {=IFERROR(SMALL(IF(INDIRECT($Z$1&"$P$5:$P$304")=1,ROW(INDIRECT($Z$1&"$A$5:$A$304"))-ROW(INDIRECT($Z$1&"$A$5"))+1),17),"")}
B33: =IF($M33="","",INDEX(INDIRECT($Z$1&"$A$5:$A$304"),$M33)) | C33: =IF($M33="","",INDEX(INDIRECT($Z$1&"$B$5:$B$304"),$M33)) | D33: =IF($M33="","",INDEX(INDIRECT($Z$1&"$C$5:$C$304"),$M33)) | E33: =IF($M33="","",INDEX(INDIRECT($Z$1&"$E$5:$E$304"),$M33)) | F33: =IF($M33="","",INDEX(INDIRECT($Z$1&"$F$5:$F$304"),$M33)) | G33: =IF($M33="","",INDEX(INDIRECT($Z$1&"$G$5:$G$304"),$M33)) | H33: =IF($M33="","",INDEX(INDIRECT($Z$1&"$H$5:$H$304"),$M33)) | I33: =IF($M33="","",INDEX(INDIRECT($Z$1&"$I$5:$I$304"),$M33)) | J33: =IF($M33="","",INDEX(INDIRECT($Z$1&"$J$5:$J$304"),$M33)) | M33: {=IFERROR(SMALL(IF(INDIRECT($Z$1&"$P$5:$P$304")=1,ROW(INDIRECT($Z$1&"$A$5:$A$304"))-ROW(INDIRECT($Z$1&"$A$5"))+1),18),"")}
B34: =IF($M34="","",INDEX(INDIRECT($Z$1&"$A$5:$A$304"),$M34)) | C34: =IF($M34="","",INDEX(INDIRECT($Z$1&"$B$5:$B$304"),$M34)) | D34: =IF($M34="","",INDEX(INDIRECT($Z$1&"$C$5:$C$304"),$M34)) | E34: =IF($M34="","",INDEX(INDIRECT($Z$1&"$E$5:$E$304"),$M34)) | F34: =IF($M34="","",INDEX(INDIRECT($Z$1&"$F$5:$F$304"),$M34)) | G34: =IF($M34="","",INDEX(INDIRECT($Z$1&"$G$5:$G$304"),$M34)) | H34: =IF($M34="","",INDEX(INDIRECT($Z$1&"$H$5:$H$304"),$M34)) | I34: =IF($M34="","",INDEX(INDIRECT($Z$1&"$I$5:$I$304"),$M34)) | J34: =IF($M34="","",INDEX(INDIRECT($Z$1&"$J$5:$J$304"),$M34)) | M34: {=IFERROR(SMALL(IF(INDIRECT($Z$1&"$P$5:$P$304")=1,ROW(INDIRECT($Z$1&"$A$5:$A$304"))-ROW(INDIRECT($Z$1&"$A$5"))+1),19),"")}
B35: =IF($M35="","",INDEX(INDIRECT($Z$1&"$A$5:$A$304"),$M35)) | C35: =IF($M35="","",INDEX(INDIRECT($Z$1&"$B$5:$B$304"),$M35)) | D35: =IF($M35="","",INDEX(INDIRECT($Z$1&"$C$5:$C$304"),$M35)) | E35: =IF($M35="","",INDEX(INDIRECT($Z$1&"$E$5:$E$304"),$M35)) | F35: =IF($M35="","",INDEX(INDIRECT($Z$1&"$F$5:$F$304"),$M35)) | G35: =IF($M35="","",INDEX(INDIRECT($Z$1&"$G$5:$G$304"),$M35)) | H35: =IF($M35="","",INDEX(INDIRECT($Z$1&"$H$5:$H$304"),$M35)) | I35: =IF($M35="","",INDEX(INDIRECT($Z$1&"$I$5:$I$304"),$M35)) | J35: =IF($M35="","",INDEX(INDIRECT($Z$1&"$J$5:$J$304"),$M35)) | M35: {=IFERROR(SMALL(IF(INDIRECT($Z$1&"$P$5:$P$304")=1,ROW(INDIRECT($Z$1&"$A$5:$A$304"))-ROW(INDIRECT($Z$1&"$A$5"))+1),20),"")}
B36: =IF($M36="","",INDEX(INDIRECT($Z$1&"$A$5:$A$304"),$M36)) | C36: =IF($M36="","",INDEX(INDIRECT($Z$1&"$B$5:$B$304"),$M36)) | D36: =IF($M36="","",INDEX(INDIRECT($Z$1&"$C$5:$C$304"),$M36)) | E36: =IF($M36="","",INDEX(INDIRECT($Z$1&"$E$5:$E$304"),$M36)) | F36: =IF($M36="","",INDEX(INDIRECT($Z$1&"$F$5:$F$304"),$M36)) | G36: =IF($M36="","",INDEX(INDIRECT($Z$1&"$G$5:$G$304"),$M36)) | H36: =IF($M36="","",INDEX(INDIRECT($Z$1&"$H$5:$H$304"),$M36)) | I36: =IF($M36="","",INDEX(INDIRECT($Z$1&"$I$5:$I$304"),$M36)) | J36: =IF($M36="","",INDEX(INDIRECT($Z$1&"$J$5:$J$304"),$M36)) | M36: {=IFERROR(SMALL(IF(INDIRECT($Z$1&"$P$5:$P$304")=1,ROW(INDIRECT($Z$1&"$A$5:$A$304"))-ROW(INDIRECT($Z$1&"$A$5"))+1),21),"")}
B37: =IF($M37="","",INDEX(INDIRECT($Z$1&"$A$5:$A$304"),$M37)) | C37: =IF($M37="","",INDEX(INDIRECT($Z$1&"$B$5:$B$304"),$M37)) | D37: =IF($M37="","",INDEX(INDIRECT($Z$1&"$C$5:$C$304"),$M37)) | E37: =IF($M37="","",INDEX(INDIRECT($Z$1&"$E$5:$E$304"),$M37)) | F37: =IF($M37="","",INDEX(INDIRECT($Z$1&"$F$5:$F$304"),$M37)) | G37: =IF($M37="","",INDEX(INDIRECT($Z$1&"$G$5:$G$304"),$M37)) | H37: =IF($M37="","",INDEX(INDIRECT($Z$1&"$H$5:$H$304"),$M37)) | I37: =IF($M37="","",INDEX(INDIRECT($Z$1&"$I$5:$I$304"),$M37)) | J37: =IF($M37="","",INDEX(INDIRECT($Z$1&"$J$5:$J$304"),$M37)) | M37: {=IFERROR(SMALL(IF(INDIRECT($Z$1&"$P$5:$P$304")=1,ROW(INDIRECT($Z$1&"$A$5:$A$304"))-ROW(INDIRECT($Z$1&"$A$5"))+1),22),"")}
B38: =IF($M38="","",INDEX(INDIRECT($Z$1&"$A$5:$A$304"),$M38)) | C38: =IF($M38="","",INDEX(INDIRECT($Z$1&"$B$5:$B$304"),$M38)) | D38: =IF($M38="","",INDEX(INDIRECT($Z$1&"$C$5:$C$304"),$M38)) | E38: =IF($M38="","",INDEX(INDIRECT($Z$1&"$E$5:$E$304"),$M38)) | F38: =IF($M38="","",INDEX(INDIRECT($Z$1&"$F$5:$F$304"),$M38)) | G38: =IF($M38="","",INDEX(INDIRECT($Z$1&"$G$5:$G$304"),$M38)) | H38: =IF($M38="","",INDEX(INDIRECT($Z$1&"$H$5:$H$304"),$M38)) | I38: =IF($M38="","",INDEX(INDIRECT($Z$1&"$I$5:$I$304"),$M38)) | J38: =IF($M38="","",INDEX(INDIRECT($Z$1&"$J$5:$J$304"),$M38)) | M38: {=IFERROR(SMALL(IF(INDIRECT($Z$1&"$P$5:$P$304")=1,ROW(INDIRECT($Z$1&"$A$5:$A$304"))-ROW(INDIRECT($Z$1&"$A$5"))+1),23),"")}
B39: =IF($M39="","",INDEX(INDIRECT($Z$1&"$A$5:$A$304"),$M39)) | C39: =IF($M39="","",INDEX(INDIRECT($Z$1&"$B$5:$B$304"),$M39)) | D39: =IF($M39="","",INDEX(INDIRECT($Z$1&"$C$5:$C$304"),$M39)) | E39: =IF($M39="","",INDEX(INDIRECT($Z$1&"$E$5:$E$304"),$M39)) | F39: =IF($M39="","",INDEX(INDIRECT($Z$1&"$F$5:$F$304"),$M39)) | G39: =IF($M39="","",INDEX(INDIRECT($Z$1&"$G$5:$G$304"),$M39)) | H39: =IF($M39="","",INDEX(INDIRECT($Z$1&"$H$5:$H$304"),$M39)) | I39: =IF($M39="","",INDEX(INDIRECT($Z$1&"$I$5:$I$304"),$M39)) | J39: =IF($M39="","",INDEX(INDIRECT($Z$1&"$J$5:$J$304"),$M39)) | M39: {=IFERROR(SMALL(IF(INDIRECT($Z$1&"$P$5:$P$304")=1,ROW(INDIRECT($Z$1&"$A$5:$A$304"))-ROW(INDIRECT($Z$1&"$A$5"))+1),24),"")}
B40: =IF($M40="","",INDEX(INDIRECT($Z$1&"$A$5:$A$304"),$M40)) | C40: =IF($M40="","",INDEX(INDIRECT($Z$1&"$B$5:$B$304"),$M40)) | D40: =IF($M40="","",INDEX(INDIRECT($Z$1&"$C$5:$C$304"),$M40)) | E40: =IF($M40="","",INDEX(INDIRECT($Z$1&"$E$5:$E$304"),$M40)) | F40: =IF($M40="","",INDEX(INDIRECT($Z$1&"$F$5:$F$304"),$M40)) | G40: =IF($M40="","",INDEX(INDIRECT($Z$1&"$G$5:$G$304"),$M40)) | H40: =IF($M40="","",INDEX(INDIRECT($Z$1&"$H$5:$H$304"),$M40)) | I40: =IF($M40="","",INDEX(INDIRECT($Z$1&"$I$5:$I$304"),$M40)) | J40: =IF($M40="","",INDEX(INDIRECT($Z$1&"$J$5:$J$304"),$M40)) | M40: {=IFERROR(SMALL(IF(INDIRECT($Z$1&"$P$5:$P$304")=1,ROW(INDIRECT($Z$1&"$A$5:$A$304"))-ROW(INDIRECT($Z$1&"$A$5"))+1),25),"")}
B41: =IF($M41="","",INDEX(INDIRECT($Z$1&"$A$5:$A$304"),$M41)) | C41: =IF($M41="","",INDEX(INDIRECT($Z$1&"$B$5:$B$304"),$M41)) | D41: =IF($M41="","",INDEX(INDIRECT($Z$1&"$C$5:$C$304"),$M41)) | E41: =IF($M41="","",INDEX(INDIRECT($Z$1&"$E$5:$E$304"),$M41)) | F41: =IF($M41="","",INDEX(INDIRECT($Z$1&"$F$5:$F$304"),$M41)) | G41: =IF($M41="","",INDEX(INDIRECT($Z$1&"$G$5:$G$304"),$M41)) | H41: =IF($M41="","",INDEX(INDIRECT($Z$1&"$H$5:$H$304"),$M41)) | I41: =IF($M41="","",INDEX(INDIRECT($Z$1&"$I$5:$I$304"),$M41)) | J41: =IF($M41="","",INDEX(INDIRECT($Z$1&"$J$5:$J$304"),$M41)) | M41: {=IFERROR(SMALL(IF(INDIRECT($Z$1&"$P$5:$P$304")=1,ROW(INDIRECT($Z$1&"$A$5:$A$304"))-ROW(INDIRECT($Z$1&"$A$5"))+1),26),"")}
B42: =IF($M42="","",INDEX(INDIRECT($Z$1&"$A$5:$A$304"),$M42)) | C42: =IF($M42="","",INDEX(INDIRECT($Z$1&"$B$5:$B$304"),$M42)) | D42: =IF($M42="","",INDEX(INDIRECT($Z$1&"$C$5:$C$304"),$M42)) | E42: =IF($M42="","",INDEX(INDIRECT($Z$1&"$E$5:$E$304"),$M42)) | F42: =IF($M42="","",INDEX(INDIRECT($Z$1&"$F$5:$F$304"),$M42)) | G42: =IF($M42="","",INDEX(INDIRECT($Z$1&"$G$5:$G$304"),$M42)) | H42: =IF($M42="","",INDEX(INDIRECT($Z$1&"$H$5:$H$304"),$M42)) | I42: =IF($M42="","",INDEX(INDIRECT($Z$1&"$I$5:$I$304"),$M42)) | J42: =IF($M42="","",INDEX(INDIRECT($Z$1&"$J$5:$J$304"),$M42)) | M42: {=IFERROR(SMALL(IF(INDIRECT($Z$1&"$P$5:$P$304")=1,ROW(INDIRECT($Z$1&"$A$5:$A$304"))-ROW(INDIRECT($Z$1&"$A$5"))+1),27),"")}
...

Sheet R.M Billets Reports

Sheet VRKP
A1: VRKP | Size: 130 x 130 x 6MTR
A2: Heat No. | B2: Dated | C2: Vehicle number | D2: Party | E2: Parameters | K2: Mn/S | L2: No. of Pieces | M2: Weight (MT) | N2: Hold | P2: OutOfSpec
E3: C | F3: S | G3: P | H3: Mn | I3: N | J3: Si
E4: % | F4: % | G4: % | H4: % | I4: ppm | J4: %
A5: =IF($O5="","",INDEX(Master!$D$2:$D$1001,$O5)) | B5: =IF($O5="","",INDEX(Master!$B$2:$B$1001,$O5)) | C5: =IF($O5="","",INDEX(Master!$C$2:$C$1001,$O5)) | D5: =IF($O5="","",INDEX(Master!$A$2:$A$1001,$O5)) | E5: =IF($O5="","",INDEX(Master!$E$2:$E$1001,$O5)) | F5: =IF($O5="","",INDEX(Master!$F$2:$F$1001,$O5)) | G5: =IF($O5="","",INDEX(Master!$G$2:$G$1001,$O5)) | H5: =IF($O5="","",INDEX(Master!$H$2:$H$1001,$O5)) | I5: =IF($O5="","",INDEX(Master!$I$2:$I$1001,$O5)) | J5: =IF($O5="","",INDEX(Master!$J$2:$J$1001,$O5)) | K5: =IF(OR($O5="",$F5="",$F5=0),"",$H5/$F5) | L5: =IF($O5="","",INDEX(Master!$K$2:$K$1001,$O5)) | M5: =IF($O5="","",INDEX(Master!$L$2:$L$1001,$O5)) | O5: {=IFERROR(SMALL(IF(Master!$A$2:$A$1001="VRKP",ROW(Master!$A$2:$A$1001)-ROW(Master!$A$2)+1),1),"")} | P5: =IF($A5="",0,IF(OR(AND($E5<>"",OR($E5>0.12)),AND($F5<>"",OR($F5>0.05)),AND($G5<>"",OR($G5>0.085)),AND($H5<>"",$H5<0.5),AND($I5<>"",$I5>120),AND($J5<>"",OR($J5<0.08))),1,0))
A6: =IF($O6="","",INDEX(Master!$D$2:$D$1001,$O6)) | B6: =IF($O6="","",INDEX(Master!$B$2:$B$1001,$O6)) | C6: =IF($O6="","",INDEX(Master!$C$2:$C$1001,$O6)) | D6: =IF($O6="","",INDEX(Master!$A$2:$A$1001,$O6)) | E6: =IF($O6="","",INDEX(Master!$E$2:$E$1001,$O6)) | F6: =IF($O6="","",INDEX(Master!$F$2:$F$1001,$O6)) | G6: =IF($O6="","",INDEX(Master!$G$2:$G$1001,$O6)) | H6: =IF($O6="","",INDEX(Master!$H$2:$H$1001,$O6)) | I6: =IF($O6="","",INDEX(Master!$I$2:$I$1001,$O6)) | J6: =IF($O6="","",INDEX(Master!$J$2:$J$1001,$O6)) | K6: =IF(OR($O6="",$F6="",$F6=0),"",$H6/$F6) | L6: =IF($O6="","",INDEX(Master!$K$2:$K$1001,$O6)) | M6: =IF($O6="","",INDEX(Master!$L$2:$L$1001,$O6)) | O6: {=IFERROR(SMALL(IF(Master!$A$2:$A$1001="VRKP",ROW(Master!$A$2:$A$1001)-ROW(Master!$A$2)+1),2),"")} | P6: =IF($A6="",0,IF(OR(AND($E6<>"",OR($E6>0.12)),AND($F6<>"",OR($F6>0.05)),AND($G6<>"",OR($G6>0.085)),AND($H6<>"",$H6<0.5),AND($I6<>"",$I6>120),AND($J6<>"",OR($J6<0.08))),1,0))
A7: =IF($O7="","",INDEX(Master!$D$2:$D$1001,$O7)) | B7: =IF($O7="","",INDEX(Master!$B$2:$B$1001,$O7)) | C7: =IF($O7="","",INDEX(Master!$C$2:$C$1001,$O7)) | D7: =IF($O7="","",INDEX(Master!$A$2:$A$1001,$O7)) | E7: =IF($O7="","",INDEX(Master!$E$2:$E$1001,$O7)) | F7: =IF($O7="","",INDEX(Master!$F$2:$F$1001,$O7)) | G7: =IF($O7="","",INDEX(Master!$G$2:$G$1001,$O7)) | H7: =IF($O7="","",INDEX(Master!$H$2:$H$1001,$O7)) | I7: =IF($O7="","",INDEX(Master!$I$2:$I$1001,$O7)) | J7: =IF($O7="","",INDEX(Master!$J$2:$J$1001,$O7)) | K7: =IF(OR($O7="",$F7="",$F7=0),"",$H7/$F7) | L7: =IF($O7="","",INDEX(Master!$K$2:$K$1001,$O7)) | M7: =IF($O7="","",INDEX(Master!$L$2:$L$1001,$O7)) | O7: {=IFERROR(SMALL(IF(Master!$A$2:$A$1001="VRKP",ROW(Master!$A$2:$A$1001)-ROW(Master!$A$2)+1),3),"")} | P7: =IF($A7="",0,IF(OR(AND($E7<>"",OR($E7>0.12)),AND($F7<>"",OR($F7>0.05)),AND($G7<>"",OR($G7>0.085)),AND($H7<>"",$H7<0.5),AND($I7<>"",$I7>120),AND($J7<>"",OR($J7<0.08))),1,0))
A8: =IF($O8="","",INDEX(Master!$D$2:$D$1001,$O8)) | B8: =IF($O8="","",INDEX(Master!$B$2:$B$1001,$O8)) | C8: =IF($O8="","",INDEX(Master!$C$2:$C$1001,$O8)) | D8: =IF($O8="","",INDEX(Master!$A$2:$A$1001,$O8)) | E8: =IF($O8="","",INDEX(Master!$E$2:$E$1001,$O8)) | F8: =IF($O8="","",INDEX(Master!$F$2:$F$1001,$O8)) | G8: =IF($O8="","",INDEX(Master!$G$2:$G$1001,$O8)) | H8: =IF($O8="","",INDEX(Master!$H$2:$H$1001,$O8)) | I8: =IF($O8="","",INDEX(Master!$I$2:$I$1001,$O8)) | J8: =IF($O8="","",INDEX(Master!$J$2:$J$1001,$O8)) | K8: =IF(OR($O8="",$F8="",$F8=0),"",$H8/$F8) | L8: =IF($O8="","",INDEX(Master!$K$2:$K$1001,$O8)) | M8: =IF($O8="","",INDEX(Master!$L$2:$L$1001,$O8)) | O8: {=IFERROR(SMALL(IF(Master!$A$2:$A$1001="VRKP",ROW(Master!$A$2:$A$1001)-ROW(Master!$A$2)+1),4),"")} | P8: =IF($A8="",0,IF(OR(AND($E8<>"",OR($E8>0.12)),AND($F8<>"",OR($F8>0.05)),AND($G8<>"",OR($G8>0.085)),AND($H8<>"",$H8<0.5),AND($I8<>"",$I8>120),AND($J8<>"",OR($J8<0.08))),1,0))
A9: =IF($O9="","",INDEX(Master!$D$2:$D$1001,$O9)) | B9: =IF($O9="","",INDEX(Master!$B$2:$B$1001,$O9)) | C9: =IF($O9="","",INDEX(Master!$C$2:$C$1001,$O9)) | D9: =IF($O9="","",INDEX(Master!$A$2:$A$1001,$O9)) | E9: =IF($O9="","",INDEX(Master!$E$2:$E$1001,$O9)) | F9: =IF($O9="","",INDEX(Master!$F$2:$F$1001,$O9)) | G9: =IF($O9="","",INDEX(Master!$G$2:$G$1001,$O9)) | H9: =IF($O9="","",INDEX(Master!$H$2:$H$1001,$O9)) | I9: =IF($O9="","",INDEX(Master!$I$2:$I$1001,$O9)) | J9: =IF($O9="","",INDEX(Master!$J$2:$J$1001,$O9)) | K9: =IF(OR($O9="",$F9="",$F9=0),"",$H9/$F9) | L9: =IF($O9="","",INDEX(Master!$K$2:$K$1001,$O9)) | M9: =IF($O9="","",INDEX(Master!$L$2:$L$1001,$O9)) | O9: {=IFERROR(SMALL(IF(Master!$A$2:$A$1001="VRKP",ROW(Master!$A$2:$A$1001)-ROW(Master!$A$2)+1),5),"")} | P9: =IF($A9="",0,IF(OR(AND($E9<>"",OR($E9>0.12)),AND($F9<>"",OR($F9>0.05)),AND($G9<>"",OR($G9>0.085)),AND($H9<>"",$H9<0.5),AND($I9<>"",$I9>120),AND($J9<>"",OR($J9<0.08))),1,0))
A10: =IF($O10="","",INDEX(Master!$D$2:$D$1001,$O10)) | B10: =IF($O10="","",INDEX(Master!$B$2:$B$1001,$O10)) | C10: =IF($O10="","",INDEX(Master!$C$2:$C$1001,$O10)) | D10: =IF($O10="","",INDEX(Master!$A$2:$A$1001,$O10)) | E10: =IF($O10="","",INDEX(Master!$E$2:$E$1001,$O10)) | F10: =IF($O10="","",INDEX(Master!$F$2:$F$1001,$O10)) | G10: =IF($O10="","",INDEX(Master!$G$2:$G$1001,$O10)) | H10: =IF($O10="","",INDEX(Master!$H$2:$H$1001,$O10)) | I10: =IF($O10="","",INDEX(Master!$I$2:$I$1001,$O10)) | J10: =IF($O10="","",INDEX(Master!$J$2:$J$1001,$O10)) | K10: =IF(OR($O10="",$F10="",$F10=0),"",$H10/$F10) | L10: =IF($O10="","",INDEX(Master!$K$2:$K$1001,$O10)) | M10: =IF($O10="","",INDEX(Master!$L$2:$L$1001,$O10)) | O10: {=IFERROR(SMALL(IF(Master!$A$2:$A$1001="VRKP",ROW(Master!$A$2:$A$1001)-ROW(Master!$A$2)+1),6),"")} | P10: =IF($A10="",0,IF(OR(AND($E10<>"",OR($E10>0.12)),AND($F10<>"",OR($F10>0.05)),AND($G10<>"",OR($G10>0.085)),AND($H10<>"",$H10<0.5),AND($I10<>"",$I10>120),AND($J10<>"",OR($J10<0.08))),1,0))
A11: =IF($O11="","",INDEX(Master!$D$2:$D$1001,$O11)) | B11: =IF($O11="","",INDEX(Master!$B$2:$B$1001,$O11)) | C11: =IF($O11="","",INDEX(Master!$C$2:$C$1001,$O11)) | D11: =IF($O11="","",INDEX(Master!$A$2:$A$1001,$O11)) | E11: =IF($O11="","",INDEX(Master!$E$2:$E$1001,$O11)) | F11: =IF($O11="","",INDEX(Master!$F$2:$F$1001,$O11)) | G11: =IF($O11="","",INDEX(Master!$G$2:$G$1001,$O11)) | H11: =IF($O11="","",INDEX(Master!$H$2:$H$1001,$O11)) | I11: =IF($O11="","",INDEX(Master!$I$2:$I$1001,$O11)) | J11: =IF($O11="","",INDEX(Master!$J$2:$J$1001,$O11)) | K11: =IF(OR($O11="",$F11="",$F11=0),"",$H11/$F11) | L11: =IF($O11="","",INDEX(Master!$K$2:$K$1001,$O11)) | M11: =IF($O11="","",INDEX(Master!$L$2:$L$1001,$O11)) | O11: {=IFERROR(SMALL(IF(Master!$A$2:$A$1001="VRKP",ROW(Master!$A$2:$A$1001)-ROW(Master!$A$2)+1),7),"")} | P11: =IF($A11="",0,IF(OR(AND($E11<>"",OR($E11>0.12)),AND($F11<>"",OR($F11>0.05)),AND($G11<>"",OR($G11>0.085)),AND($H11<>"",$H11<0.5),AND($I11<>"",$I11>120),AND($J11<>"",OR($J11<0.08))),1,0))
A12: =IF($O12="","",INDEX(Master!$D$2:$D$1001,$O12)) | B12: =IF($O12="","",INDEX(Master!$B$2:$B$1001,$O12)) | C12: =IF($O12="","",INDEX(Master!$C$2:$C$1001,$O12)) | D12: =IF($O12="","",INDEX(Master!$A$2:$A$1001,$O12)) | E12: =IF($O12="","",INDEX(Master!$E$2:$E$1001,$O12)) | F12: =IF($O12="","",INDEX(Master!$F$2:$F$1001,$O12)) | G12: =IF($O12="","",INDEX(Master!$G$2:$G$1001,$O12)) | H12: =IF($O12="","",INDEX(Master!$H$2:$H$1001,$O12)) | I12: =IF($O12="","",INDEX(Master!$I$2:$I$1001,$O12)) | J12: =IF($O12="","",INDEX(Master!$J$2:$J$1001,$O12)) | K12: =IF(OR($O12="",$F12="",$F12=0),"",$H12/$F12) | L12: =IF($O12="","",INDEX(Master!$K$2:$K$1001,$O12)) | M12: =IF($O12="","",INDEX(Master!$L$2:$L$1001,$O12)) | O12: {=IFERROR(SMALL(IF(Master!$A$2:$A$1001="VRKP",ROW(Master!$A$2:$A$1001)-ROW(Master!$A$2)+1),8),"")} | P12: =IF($A12="",0,IF(OR(AND($E12<>"",OR($E12>0.12)),AND($F12<>"",OR($F12>0.05)),AND($G12<>"",OR($G12>0.085)),AND($H12<>"",$H12<0.5),AND($I12<>"",$I12>120),AND($J12<>"",OR($J12<0.08))),1,0))
A13: =IF($O13="","",INDEX(Master!$D$2:$D$1001,$O13)) | B13: =IF($O13="","",INDEX(Master!$B$2:$B$1001,$O13)) | C13: =IF($O13="","",INDEX(Master!$C$2:$C$1001,$O13)) | D13: =IF($O13="","",INDEX(Master!$A$2:$A$1001,$O13)) | E13: =IF($O13="","",INDEX(Master!$E$2:$E$1001,$O13)) | F13: =IF($O13="","",INDEX(Master!$F$2:$F$1001,$O13)) | G13: =IF($O13="","",INDEX(Master!$G$2:$G$1001,$O13)) | H13: =IF($O13="","",INDEX(Master!$H$2:$H$1001,$O13)) | I13: =IF($O13="","",INDEX(Master!$I$2:$I$1001,$O13)) | J13: =IF($O13="","",INDEX(Master!$J$2:$J$1001,$O13)) | K13: =IF(OR($O13="",$F13="",$F13=0),"",$H13/$F13) | L13: =IF($O13="","",INDEX(Master!$K$2:$K$1001,$O13)) | M13: =IF($O13="","",INDEX(Master!$L$2:$L$1001,$O13)) | O13: {=IFERROR(SMALL(IF(Master!$A$2:$A$1001="VRKP",ROW(Master!$A$2:$A$1001)-ROW(Master!$A$2)+1),9),"")} | P13: =IF($A13="",0,IF(OR(AND($E13<>"",OR($E13>0.12)),AND($F13<>"",OR($F13>0.05)),AND($G13<>"",OR($G13>0.085)),AND($H13<>"",$H13<0.5),AND($I13<>"",$I13>120),AND($J13<>"",OR($J13<0.08))),1,0))
A14: =IF($O14="","",INDEX(Master!$D$2:$D$1001,$O14)) | B14: =IF($O14="","",INDEX(Master!$B$2:$B$1001,$O14)) | C14: =IF($O14="","",INDEX(Master!$C$2:$C$1001,$O14)) | D14: =IF($O14="","",INDEX(Master!$A$2:$A$1001,$O14)) | E14: =IF($O14="","",INDEX(Master!$E$2:$E$1001,$O14)) | F14: =IF($O14="","",INDEX(Master!$F$2:$F$1001,$O14)) | G14: =IF($O14="","",INDEX(Master!$G$2:$G$1001,$O14)) | H14: =IF($O14="","",INDEX(Master!$H$2:$H$1001,$O14)) | I14: =IF($O14="","",INDEX(Master!$I$2:$I$1001,$O14)) | J14: =IF($O14="","",INDEX(Master!$J$2:$J$1001,$O14)) | K14: =IF(OR($O14="",$F14="",$F14=0),"",$H14/$F14) | L14: =IF($O14="","",INDEX(Master!$K$2:$K$1001,$O14)) | M14: =IF($O14="","",INDEX(Master!$L$2:$L$1001,$O14)) | O14: {=IFERROR(SMALL(IF(Master!$A$2:$A$1001="VRKP",ROW(Master!$A$2:$A$1001)-ROW(Master!$A$2)+1),10),"")} | P14: =IF($A14="",0,IF(OR(AND($E14<>"",OR($E14>0.12)),AND($F14<>"",OR($F14>0.05)),AND($G14<>"",OR($G14>0.085)),AND($H14<>"",$H14<0.5),AND($I14<>"",$I14>120),AND($J14<>"",OR($J14<0.08))),1,0))
A15: =IF($O15="","",INDEX(Master!$D$2:$D$1001,$O15)) | B15: =IF($O15="","",INDEX(Master!$B$2:$B$1001,$O15)) | C15: =IF($O15="","",INDEX(Master!$C$2:$C$1001,$O15)) | D15: =IF($O15="","",INDEX(Master!$A$2:$A$1001,$O15)) | E15: =IF($O15="","",INDEX(Master!$E$2:$E$1001,$O15)) | F15: =IF($O15="","",INDEX(Master!$F$2:$F$1001,$O15)) | G15: =IF($O15="","",INDEX(Master!$G$2:$G$1001,$O15)) | H15: =IF($O15="","",INDEX(Master!$H$2:$H$1001,$O15)) | I15: =IF($O15="","",INDEX(Master!$I$2:$I$1001,$O15)) | J15: =IF($O15="","",INDEX(Master!$J$2:$J$1001,$O15)) | K15: =IF(OR($O15="",$F15="",$F15=0),"",$H15/$F15) | L15: =IF($O15="","",INDEX(Master!$K$2:$K$1001,$O15)) | M15: =IF($O15="","",INDEX(Master!$L$2:$L$1001,$O15)) | O15: {=IFERROR(SMALL(IF(Master!$A$2:$A$1001="VRKP",ROW(Master!$A$2:$A$1001)-ROW(Master!$A$2)+1),11),"")} | P15: =IF($A15="",0,IF(OR(AND($E15<>"",OR($E15>0.12)),AND($F15<>"",OR($F15>0.05)),AND($G15<>"",OR($G15>0.085)),AND($H15<>"",$H15<0.5),AND($I15<>"",$I15>120),AND($J15<>"",OR($J15<0.08))),1,0))
A16: =IF($O16="","",INDEX(Master!$D$2:$D$1001,$O16)) | B16: =IF($O16="","",INDEX(Master!$B$2:$B$1001,$O16)) | C16: =IF($O16="","",INDEX(Master!$C$2:$C$1001,$O16)) | D16: =IF($O16="","",INDEX(Master!$A$2:$A$1001,$O16)) | E16: =IF($O16="","",INDEX(Master!$E$2:$E$1001,$O16)) | F16: =IF($O16="","",INDEX(Master!$F$2:$F$1001,$O16)) | G16: =IF($O16="","",INDEX(Master!$G$2:$G$1001,$O16)) | H16: =IF($O16="","",INDEX(Master!$H$2:$H$1001,$O16)) | I16: =IF($O16="","",INDEX(Master!$I$2:$I$1001,$O16)) | J16: =IF($O16="","",INDEX(Master!$J$2:$J$1001,$O16)) | K16: =IF(OR($O16="",$F16="",$F16=0),"",$H16/$F16) | L16: =IF($O16="","",INDEX(Master!$K$2:$K$1001,$O16)) | M16: =IF($O16="","",INDEX(Master!$L$2:$L$1001,$O16)) | O16: {=IFERROR(SMALL(IF(Master!$A$2:$A$1001="VRKP",ROW(Master!$A$2:$A$1001)-ROW(Master!$A$2)+1),12),"")} | P16: =IF($A16="",0,IF(OR(AND($E16<>"",OR($E16>0.12)),AND($F16<>"",OR($F16>0.05)),AND($G16<>"",OR($G16>0.085)),AND($H16<>"",$H16<0.5),AND($I16<>"",$I16>120),AND($J16<>"",OR($J16<0.08))),1,0))
A17: =IF($O17="","",INDEX(Master!$D$2:$D$1001,$O17)) | B17: =IF($O17="","",INDEX(Master!$B$2:$B$1001,$O17)) | C17: =IF($O17="","",INDEX(Master!$C$2:$C$1001,$O17)) | D17: =IF($O17="","",INDEX(Master!$A$2:$A$1001,$O17)) | E17: =IF($O17="","",INDEX(Master!$E$2:$E$1001,$O17)) | F17: =IF($O17="","",INDEX(Master!$F$2:$F$1001,$O17)) | G17: =IF($O17="","",INDEX(Master!$G$2:$G$1001,$O17)) | H17: =IF($O17="","",INDEX(Master!$H$2:$H$1001,$O17)) | I17: =IF($O17="","",INDEX(Master!$I$2:$I$1001,$O17)) | J17: =IF($O17="","",INDEX(Master!$J$2:$J$1001,$O17)) | K17: =IF(OR($O17="",$F17="",$F17=0),"",$H17/$F17) | L17: =IF($O17="","",INDEX(Master!$K$2:$K$1001,$O17)) | M17: =IF($O17="","",INDEX(Master!$L$2:$L$1001,$O17)) | O17: {=IFERROR(SMALL(IF(Master!$A$2:$A$1001="VRKP",ROW(Master!$A$2:$A$1001)-ROW(Master!$A$2)+1),13),"")} | P17: =IF($A17="",0,IF(OR(AND($E17<>"",OR($E17>0.12)),AND($F17<>"",OR($F17>0.05)),AND($G17<>"",OR($G17>0.085)),AND($H17<>"",$H17<0.5),AND($I17<>"",$I17>120),AND($J17<>"",OR($J17<0.08))),1,0))
A18: =IF($O18="","",INDEX(Master!$D$2:$D$1001,$O18)) | B18: =IF($O18="","",INDEX(Master!$B$2:$B$1001,$O18)) | C18: =IF($O18="","",INDEX(Master!$C$2:$C$1001,$O18)) | D18: =IF($O18="","",INDEX(Master!$A$2:$A$1001,$O18)) | E18: =IF($O18="","",INDEX(Master!$E$2:$E$1001,$O18)) | F18: =IF($O18="","",INDEX(Master!$F$2:$F$1001,$O18)) | G18: =IF($O18="","",INDEX(Master!$G$2:$G$1001,$O18)) | H18: =IF($O18="","",INDEX(Master!$H$2:$H$1001,$O18)) | I18: =IF($O18="","",INDEX(Master!$I$2:$I$1001,$O18)) | J18: =IF($O18="","",INDEX(Master!$J$2:$J$1001,$O18)) | K18: =IF(OR($O18="",$F18="",$F18=0),"",$H18/$F18) | L18: =IF($O18="","",INDEX(Master!$K$2:$K$1001,$O18)) | M18: =IF($O18="","",INDEX(Master!$L$2:$L$1001,$O18)) | O18: {=IFERROR(SMALL(IF(Master!$A$2:$A$1001="VRKP",ROW(Master!$A$2:$A$1001)-ROW(Master!$A$2)+1),14),"")} | P18: =IF($A18="",0,IF(OR(AND($E18<>"",OR($E18>0.12)),AND($F18<>"",OR($F18>0.05)),AND($G18<>"",OR($G18>0.085)),AND($H18<>"",$H18<0.5),AND($I18<>"",$I18>120),AND($J18<>"",OR($J18<0.08))),1,0))
A19: =IF($O19="","",INDEX(Master!$D$2:$D$1001,$O19)) | B19: =IF($O19="","",INDEX(Master!$B$2:$B$1001,$O19)) | C19: =IF($O19="","",INDEX(Master!$C$2:$C$1001,$O19)) | D19: =IF($O19="","",INDEX(Master!$A$2:$A$1001,$O19)) | E19: =IF($O19="","",INDEX(Master!$E$2:$E$1001,$O19)) | F19: =IF($O19="","",INDEX(Master!$F$2:$F$1001,$O19)) | G19: =IF($O19="","",INDEX(Master!$G$2:$G$1001,$O19)) | H19: =IF($O19="","",INDEX(Master!$H$2:$H$1001,$O19)) | I19: =IF($O19="","",INDEX(Master!$I$2:$I$1001,$O19)) | J19: =IF($O19="","",INDEX(Master!$J$2:$J$1001,$O19)) | K19: =IF(OR($O19="",$F19="",$F19=0),"",$H19/$F19) | L19: =IF($O19="","",INDEX(Master!$K$2:$K$1001,$O19)) | M19: =IF($O19="","",INDEX(Master!$L$2:$L$1001,$O19)) | O19: {=IFERROR(SMALL(IF(Master!$A$2:$A$1001="VRKP",ROW(Master!$A$2:$A$1001)-ROW(Master!$A$2)+1),15),"")} | P19: =IF($A19="",0,IF(OR(AND($E19<>"",OR($E19>0.12)),AND($F19<>"",OR($F19>0.05)),AND($G19<>"",OR($G19>0.085)),AND($H19<>"",$H19<0.5),AND($I19<>"",$I19>120),AND($J19<>"",OR($J19<0.08))),1,0))
A20: =IF($O20="","",INDEX(Master!$D$2:$D$1001,$O20)) | B20: =IF($O20="","",INDEX(Master!$B$2:$B$1001,$O20)) | C20: =IF($O20="","",INDEX(Master!$C$2:$C$1001,$O20)) | D20: =IF($O20="","",INDEX(Master!$A$2:$A$1001,$O20)) | E20: =IF($O20="","",INDEX(Master!$E$2:$E$1001,$O20)) | F20: =IF($O20="","",INDEX(Master!$F$2:$F$1001,$O20)) | G20: =IF($O20="","",INDEX(Master!$G$2:$G$1001,$O20)) | H20: =IF($O20="","",INDEX(Master!$H$2:$H$1001,$O20)) | I20: =IF($O20="","",INDEX(Master!$I$2:$I$1001,$O20)) | J20: =IF($O20="","",INDEX(Master!$J$2:$J$1001,$O20)) | K20: =IF(OR($O20="",$F20="",$F20=0),"",$H20/$F20) | L20: =IF($O20="","",INDEX(Master!$K$2:$K$1001,$O20)) | M20: =IF($O20="","",INDEX(Master!$L$2:$L$1001,$O20)) | O20: {=IFERROR(SMALL(IF(Master!$A$2:$A$1001="VRKP",ROW(Master!$A$2:$A$1001)-ROW(Master!$A$2)+1),16),"")} | P20: =IF($A20="",0,IF(OR(AND($E20<>"",OR($E20>0.12)),AND($F20<>"",OR($F20>0.05)),AND($G20<>"",OR($G20>0.085)),AND($H20<>"",$H20<0.5),AND($I20<>"",$I20>120),AND($J20<>"",OR($J20<0.08))),1,0))
A21: =IF($O21="","",INDEX(Master!$D$2:$D$1001,$O21)) | B21: =IF($O21="","",INDEX(Master!$B$2:$B$1001,$O21)) | C21: =IF($O21="","",INDEX(Master!$C$2:$C$1001,$O21)) | D21: =IF($O21="","",INDEX(Master!$A$2:$A$1001,$O21)) | E21: =IF($O21="","",INDEX(Master!$E$2:$E$1001,$O21)) | F21: =IF($O21="","",INDEX(Master!$F$2:$F$1001,$O21)) | G21: =IF($O21="","",INDEX(Master!$G$2:$G$1001,$O21)) | H21: =IF($O21="","",INDEX(Master!$H$2:$H$1001,$O21)) | I21: =IF($O21="","",INDEX(Master!$I$2:$I$1001,$O21)) | J21: =IF($O21="","",INDEX(Master!$J$2:$J$1001,$O21)) | K21: =IF(OR($O21="",$F21="",$F21=0),"",$H21/$F21) | L21: =IF($O21="","",INDEX(Master!$K$2:$K$1001,$O21)) | M21: =IF($O21="","",INDEX(Master!$L$2:$L$1001,$O21)) | O21: {=IFERROR(SMALL(IF(Master!$A$2:$A$1001="VRKP",ROW(Master!$A$2:$A$1001)-ROW(Master!$A$2)+1),17),"")} | P21: =IF($A21="",0,IF(OR(AND($E21<>"",OR($E21>0.12)),AND($F21<>"",OR($F21>0.05)),AND($G21<>"",OR($G21>0.085)),AND($H21<>"",$H21<0.5),AND($I21<>"",$I21>120),AND($J21<>"",OR($J21<0.08))),1,0))
A22: =IF($O22="","",INDEX(Master!$D$2:$D$1001,$O22)) | B22: =IF($O22="","",INDEX(Master!$B$2:$B$1001,$O22)) | C22: =IF($O22="","",INDEX(Master!$C$2:$C$1001,$O22)) | D22: =IF($O22="","",INDEX(Master!$A$2:$A$1001,$O22)) | E22: =IF($O22="","",INDEX(Master!$E$2:$E$1001,$O22)) | F22: =IF($O22="","",INDEX(Master!$F$2:$F$1001,$O22)) | G22: =IF($O22="","",INDEX(Master!$G$2:$G$1001,$O22)) | H22: =IF($O22="","",INDEX(Master!$H$2:$H$1001,$O22)) | I22: =IF($O22="","",INDEX(Master!$I$2:$I$1001,$O22)) | J22: =IF($O22="","",INDEX(Master!$J$2:$J$1001,$O22)) | K22: =IF(OR($O22="",$F22="",$F22=0),"",$H22/$F22) | L22: =IF($O22="","",INDEX(Master!$K$2:$K$1001,$O22)) | M22: =IF($O22="","",INDEX(Master!$L$2:$L$1001,$O22)) | O22: {=IFERROR(SMALL(IF(Master!$A$2:$A$1001="VRKP",ROW(Master!$A$2:$A$1001)-ROW(Master!$A$2)+1),18),"")} | P22: =IF($A22="",0,IF(OR(AND($E22<>"",OR($E22>0.12)),AND($F22<>"",OR($F22>0.05)),AND($G22<>"",OR($G22>0.085)),AND($H22<>"",$H22<0.5),AND($I22<>"",$I22>120),AND($J22<>"",OR($J22<0.08))),1,0))
A23: =IF($O23="","",INDEX(Master!$D$2:$D$1001,$O23)) | B23: =IF($O23="","",INDEX(Master!$B$2:$B$1001,$O23)) | C23: =IF($O23="","",INDEX(Master!$C$2:$C$1001,$O23)) | D23: =IF($O23="","",INDEX(Master!$A$2:$A$1001,$O23)) | E23: =IF($O23="","",INDEX(Master!$E$2:$E$1001,$O23)) | F23: =IF($O23="","",INDEX(Master!$F$2:$F$1001,$O23)) | G23: =IF($O23="","",INDEX(Master!$G$2:$G$1001,$O23)) | H23: =IF($O23="","",INDEX(Master!$H$2:$H$1001,$O23)) | I23: =IF($O23="","",INDEX(Master!$I$2:$I$1001,$O23)) | J23: =IF($O23="","",INDEX(Master!$J$2:$J$1001,$O23)) | K23: =IF(OR($O23="",$F23="",$F23=0),"",$H23/$F23) | L23: =IF($O23="","",INDEX(Master!$K$2:$K$1001,$O23)) | M23: =IF($O23="","",INDEX(Master!$L$2:$L$1001,$O23)) | O23: {=IFERROR(SMALL(IF(Master!$A$2:$A$1001="VRKP",ROW(Master!$A$2:$A$1001)-ROW(Master!$A$2)+1),19),"")} | P23: =IF($A23="",0,IF(OR(AND($E23<>"",OR($E23>0.12)),AND($F23<>"",OR($F23>0.05)),AND($G23<>"",OR($G23>0.085)),AND($H23<>"",$H23<0.5),AND($I23<>"",$I23>120),AND($J23<>"",OR($J23<0.08))),1,0))
A24: =IF($O24="","",INDEX(Master!$D$2:$D$1001,$O24)) | B24: =IF($O24="","",INDEX(Master!$B$2:$B$1001,$O24)) | C24: =IF($O24="","",INDEX(Master!$C$2:$C$1001,$O24)) | D24: =IF($O24="","",INDEX(Master!$A$2:$A$1001,$O24)) | E24: =IF($O24="","",INDEX(Master!$E$2:$E$1001,$O24)) | F24: =IF($O24="","",INDEX(Master!$F$2:$F$1001,$O24)) | G24: =IF($O24="","",INDEX(Master!$G$2:$G$1001,$O24)) | H24: =IF($O24="","",INDEX(Master!$H$2:$H$1001,$O24)) | I24: =IF($O24="","",INDEX(Master!$I$2:$I$1001,$O24)) | J24: =IF($O24="","",INDEX(Master!$J$2:$J$1001,$O24)) | K24: =IF(OR($O24="",$F24="",$F24=0),"",$H24/$F24) | L24: =IF($O24="","",INDEX(Master!$K$2:$K$1001,$O24)) | M24: =IF($O24="","",INDEX(Master!$L$2:$L$1001,$O24)) | O24: {=IFERROR(SMALL(IF(Master!$A$2:$A$1001="VRKP",ROW(Master!$A$2:$A$1001)-ROW(Master!$A$2)+1),20),"")} | P24: =IF($A24="",0,IF(OR(AND($E24<>"",OR($E24>0.12)),AND($F24<>"",OR($F24>0.05)),AND($G24<>"",OR($G24>0.085)),AND($H24<>"",$H24<0.5),AND($I24<>"",$I24>120),AND($J24<>"",OR($J24<0.08))),1,0))
A25: =IF($O25="","",INDEX(Master!$D$2:$D$1001,$O25)) | B25: =IF($O25="","",INDEX(Master!$B$2:$B$1001,$O25)) | C25: =IF($O25="","",INDEX(Master!$C$2:$C$1001,$O25)) | D25: =IF($O25="","",INDEX(Master!$A$2:$A$1001,$O25)) | E25: =IF($O25="","",INDEX(Master!$E$2:$E$1001,$O25)) | F25: =IF($O25="","",INDEX(Master!$F$2:$F$1001,$O25)) | G25: =IF($O25="","",INDEX(Master!$G$2:$G$1001,$O25)) | H25: =IF($O25="","",INDEX(Master!$H$2:$H$1001,$O25)) | I25: =IF($O25="","",INDEX(Master!$I$2:$I$1001,$O25)) | J25: =IF($O25="","",INDEX(Master!$J$2:$J$1001,$O25)) | K25: =IF(OR($O25="",$F25="",$F25=0),"",$H25/$F25) | L25: =IF($O25="","",INDEX(Master!$K$2:$K$1001,$O25)) | M25: =IF($O25="","",INDEX(Master!$L$2:$L$1001,$O25)) | O25: {=IFERROR(SMALL(IF(Master!$A$2:$A$1001="VRKP",ROW(Master!$A$2:$A$1001)-ROW(Master!$A$2)+1),21),"")} | P25: =IF($A25="",0,IF(OR(AND($E25<>"",OR($E25>0.12)),AND($F25<>"",OR($F25>0.05)),AND($G25<>"",OR($G25>0.085)),AND($H25<>"",$H25<0.5),AND($I25<>"",$I25>120),AND($J25<>"",OR($J25<0.08))),1,0))
A26: =IF($O26="","",INDEX(Master!$D$2:$D$1001,$O26)) | B26: =IF($O26="","",INDEX(Master!$B$2:$B$1001,$O26)) | C26: =IF($O26="","",INDEX(Master!$C$2:$C$1001,$O26)) | D26: =IF($O26="","",INDEX(Master!$A$2:$A$1001,$O26)) | E26: =IF($O26="","",INDEX(Master!$E$2:$E$1001,$O26)) | F26: =IF($O26="","",INDEX(Master!$F$2:$F$1001,$O26)) | G26: =IF($O26="","",INDEX(Master!$G$2:$G$1001,$O26)) | H26: =IF($O26="","",INDEX(Master!$H$2:$H$1001,$O26)) | I26: =IF($O26="","",INDEX(Master!$I$2:$I$1001,$O26)) | J26: =IF($O26="","",INDEX(Master!$J$2:$J$1001,$O26)) | K26: =IF(OR($O26="",$F26="",$F26=0),"",$H26/$F26) | L26: =IF($O26="","",INDEX(Master!$K$2:$K$1001,$O26)) | M26: =IF($O26="","",INDEX(Master!$L$2:$L$1001,$O26)) | O26: {=IFERROR(SMALL(IF(Master!$A$2:$A$1001="VRKP",ROW(Master!$A$2:$A$1001)-ROW(Master!$A$2)+1),22),"")} | P26: =IF($A26="",0,IF(OR(AND($E26<>"",OR($E26>0.12)),AND($F26<>"",OR($F26>0.05)),AND($G26<>"",OR($G26>0.085)),AND($H26<>"",$H26<0.5),AND($I26<>"",$I26>120),AND($J26<>"",OR($J26<0.08))),1,0))
A27: =IF($O27="","",INDEX(Master!$D$2:$D$1001,$O27)) | B27: =IF($O27="","",INDEX(Master!$B$2:$B$1001,$O27)) | C27: =IF($O27="","",INDEX(Master!$C$2:$C$1001,$O27)) | D27: =IF($O27="","",INDEX(Master!$A$2:$A$1001,$O27)) | E27: =IF($O27="","",INDEX(Master!$E$2:$E$1001,$O27)) | F27: =IF($O27="","",INDEX(Master!$F$2:$F$1001,$O27)) | G27: =IF($O27="","",INDEX(Master!$G$2:$G$1001,$O27)) | H27: =IF($O27="","",INDEX(Master!$H$2:$H$1001,$O27)) | I27: =IF($O27="","",INDEX(Master!$I$2:$I$1001,$O27)) | J27: =IF($O27="","",INDEX(Master!$J$2:$J$1001,$O27)) | K27: =IF(OR($O27="",$F27="",$F27=0),"",$H27/$F27) | L27: =IF($O27="","",INDEX(Master!$K$2:$K$1001,$O27)) | M27: =IF($O27="","",INDEX(Master!$L$2:$L$1001,$O27)) | O27: {=IFERROR(SMALL(IF(Master!$A$2:$A$1001="VRKP",ROW(Master!$A$2:$A$1001)-ROW(Master!$A$2)+1),23),"")} | P27: =IF($A27="",0,IF(OR(AND($E27<>"",OR($E27>0.12)),AND($F27<>"",OR($F27>0.05)),AND($G27<>"",OR($G27>0.085)),AND($H27<>"",$H27<0.5),AND($I27<>"",$I27>120),AND($J27<>"",OR($J27<0.08))),1,0))
A28: =IF($O28="","",INDEX(Master!$D$2:$D$1001,$O28)) | B28: =IF($O28="","",INDEX(Master!$B$2:$B$1001,$O28)) | C28: =IF($O28="","",INDEX(Master!$C$2:$C$1001,$O28)) | D28: =IF($O28="","",INDEX(Master!$A$2:$A$1001,$O28)) | E28: =IF($O28="","",INDEX(Master!$E$2:$E$1001,$O28)) | F28: =IF($O28="","",INDEX(Master!$F$2:$F$1001,$O28)) | G28: =IF($O28="","",INDEX(Master!$G$2:$G$1001,$O28)) | H28: =IF($O28="","",INDEX(Master!$H$2:$H$1001,$O28)) | I28: =IF($O28="","",INDEX(Master!$I$2:$I$1001,$O28)) | J28: =IF($O28="","",INDEX(Master!$J$2:$J$1001,$O28)) | K28: =IF(OR($O28="",$F28="",$F28=0),"",$H28/$F28) | L28: =IF($O28="","",INDEX(Master!$K$2:$K$1001,$O28)) | M28: =IF($O28="","",INDEX(Master!$L$2:$L$1001,$O28)) | O28: {=IFERROR(SMALL(IF(Master!$A$2:$A$1001="VRKP",ROW(Master!$A$2:$A$1001)-ROW(Master!$A$2)+1),24),"")} | P28: =IF($A28="",0,IF(OR(AND($E28<>"",OR($E28>0.12)),AND($F28<>"",OR($F28>0.05)),AND($G28<>"",OR($G28>0.085)),AND($H28<>"",$H28<0.5),AND($I28<>"",$I28>120),AND($J28<>"",OR($J28<0.08))),1,0))
A29: =IF($O29="","",INDEX(Master!$D$2:$D$1001,$O29)) | B29: =IF($O29="","",INDEX(Master!$B$2:$B$1001,$O29)) | C29: =IF($O29="","",INDEX(Master!$C$2:$C$1001,$O29)) | D29: =IF($O29="","",INDEX(Master!$A$2:$A$1001,$O29)) | E29: =IF($O29="","",INDEX(Master!$E$2:$E$1001,$O29)) | F29: =IF($O29="","",INDEX(Master!$F$2:$F$1001,$O29)) | G29: =IF($O29="","",INDEX(Master!$G$2:$G$1001,$O29)) | H29: =IF($O29="","",INDEX(Master!$H$2:$H$1001,$O29)) | I29: =IF($O29="","",INDEX(Master!$I$2:$I$1001,$O29)) | J29: =IF($O29="","",INDEX(Master!$J$2:$J$1001,$O29)) | K29: =IF(OR($O29="",$F29="",$F29=0),"",$H29/$F29) | L29: =IF($O29="","",INDEX(Master!$K$2:$K$1001,$O29)) | M29: =IF($O29="","",INDEX(Master!$L$2:$L$1001,$O29)) | O29: {=IFERROR(SMALL(IF(Master!$A$2:$A$1001="VRKP",ROW(Master!$A$2:$A$1001)-ROW(Master!$A$2)+1),25),"")} | P29: =IF($A29="",0,IF(OR(AND($E29<>"",OR($E29>0.12)),AND($F29<>"",OR($F29>0.05)),AND($G29<>"",OR($G29>0.085)),AND($H29<>"",$H29<0.5),AND($I29<>"",$I29>120),AND($J29<>"",OR($J29<0.08))),1,0))
A30: =IF($O30="","",INDEX(Master!$D$2:$D$1001,$O30)) | B30: =IF($O30="","",INDEX(Master!$B$2:$B$1001,$O30)) | C30: =IF($O30="","",INDEX(Master!$C$2:$C$1001,$O30)) | D30: =IF($O30="","",INDEX(Master!$A$2:$A$1001,$O30)) | E30: =IF($O30="","",INDEX(Master!$E$2:$E$1001,$O30)) | F30: =IF($O30="","",INDEX(Master!$F$2:$F$1001,$O30)) | G30: =IF($O30="","",INDEX(Master!$G$2:$G$1001,$O30)) | H30: =IF($O30="","",INDEX(Master!$H$2:$H$1001,$O30)) | I30: =IF($O30="","",INDEX(Master!$I$2:$I$1001,$O30)) | J30: =IF($O30="","",INDEX(Master!$J$2:$J$1001,$O30)) | K30: =IF(OR($O30="",$F30="",$F30=0),"",$H30/$F30) | L30: =IF($O30="","",INDEX(Master!$K$2:$K$1001,$O30)) | M30: =IF($O30="","",INDEX(Master!$L$2:$L$1001,$O30)) | O30: {=IFERROR(SMALL(IF(Master!$A$2:$A$1001="VRKP",ROW(Master!$A$2:$A$1001)-ROW(Master!$A$2)+1),26),"")} | P30: =IF($A30="",0,IF(OR(AND($E30<>"",OR($E30>0.12)),AND($F30<>"",OR($F30>0.05)),AND($G30<>"",OR($G30>0.085)),AND($H30<>"",$H30<0.5),AND($I30<>"",$I30>120),AND($J30<>"",OR($J30<0.08))),1,0))
A31: =IF($O31="","",INDEX(Master!$D$2:$D$1001,$O31)) | B31: =IF($O31="","",INDEX(Master!$B$2:$B$1001,$O31)) | C31: =IF($O31="","",INDEX(Master!$C$2:$C$1001,$O31)) | D31: =IF($O31="","",INDEX(Master!$A$2:$A$1001,$O31)) | E31: =IF($O31="","",INDEX(Master!$E$2:$E$1001,$O31)) | F31: =IF($O31="","",INDEX(Master!$F$2:$F$1001,$O31)) | G31: =IF($O31="","",INDEX(Master!$G$2:$G$1001,$O31)) | H31: =IF($O31="","",INDEX(Master!$H$2:$H$1001,$O31)) | I31: =IF($O31="","",INDEX(Master!$I$2:$I$1001,$O31)) | J31: =IF($O31="","",INDEX(Master!$J$2:$J$1001,$O31)) | K31: =IF(OR($O31="",$F31="",$F31=0),"",$H31/$F31) | L31: =IF($O31="","",INDEX(Master!$K$2:$K$1001,$O31)) | M31: =IF($O31="","",INDEX(Master!$L$2:$L$1001,$O31)) | O31: {=IFERROR(SMALL(IF(Master!$A$2:$A$1001="VRKP",ROW(Master!$A$2:$A$1001)-ROW(Master!$A$2)+1),27),"")} | P31: =IF($A31="",0,IF(OR(AND($E31<>"",OR($E31>0.12)),AND($F31<>"",OR($F31>0.05)),AND($G31<>"",OR($G31>0.085)),AND($H31<>"",$H31<0.5),AND($I31<>"",$I31>120),AND($J31<>"",OR($J31<0.08))),1,0))
A32: =IF($O32="","",INDEX(Master!$D$2:$D$1001,$O32)) | B32: =IF($O32="","",INDEX(Master!$B$2:$B$1001,$O32)) | C32: =IF($O32="","",INDEX(Master!$C$2:$C$1001,$O32)) | D32: =IF($O32="","",INDEX(Master!$A$2:$A$1001,$O32)) | E32: =IF($O32="","",INDEX(Master!$E$2:$E$1001,$O32)) | F32: =IF($O32="","",INDEX(Master!$F$2:$F$1001,$O32)) | G32: =IF($O32="","",INDEX(Master!$G$2:$G$1001,$O32)) | H32: =IF($O32="","",INDEX(Master!$H$2:$H$1001,$O32)) | I32: =IF($O32="","",INDEX(Master!$I$2:$I$1001,$O32)) | J32: =IF($O32="","",INDEX(Master!$J$2:$J$1001,$O32)) | K32: =IF(OR($O32="",$F32="",$F32=0),"",$H32/$F32) | L32: =IF($O32="","",INDEX(Master!$K$2:$K$1001,$O32)) | M32: =IF($O32="","",INDEX(Master!$L$2:$L$1001,$O32)) | O32: {=IFERROR(SMALL(IF(Master!$A$2:$A$1001="VRKP",ROW(Master!$A$2:$A$1001)-ROW(Master!$A$2)+1),28),"")} | P32: =IF($A32="",0,IF(OR(AND($E32<>"",OR($E32>0.12)),AND($F32<>"",OR($F32>0.05)),AND($G32<>"",OR($G32>0.085)),AND($H32<>"",$H32<0.5),AND($I32<>"",$I32>120),AND($J32<>"",OR($J32<0.08))),1,0))
A33: =IF($O33="","",INDEX(Master!$D$2:$D$1001,$O33)) | B33: =IF($O33="","",INDEX(Master!$B$2:$B$1001,$O33)) | C33: =IF($O33="","",INDEX(Master!$C$2:$C$1001,$O33)) | D33: =IF($O33="","",INDEX(Master!$A$2:$A$1001,$O33)) | E33: =IF($O33="","",INDEX(Master!$E$2:$E$1001,$O33)) | F33: =IF($O33="","",INDEX(Master!$F$2:$F$1001,$O33)) | G33: =IF($O33="","",INDEX(Master!$G$2:$G$1001,$O33)) | H33: =IF($O33="","",INDEX(Master!$H$2:$H$1001,$O33)) | I33: =IF($O33="","",INDEX(Master!$I$2:$I$1001,$O33)) | J33: =IF($O33="","",INDEX(Master!$J$2:$J$1001,$O33)) | K33: =IF(OR($O33="",$F33="",$F33=0),"",$H33/$F33) | L33: =IF($O33="","",INDEX(Master!$K$2:$K$1001,$O33)) | M33: =IF($O33="","",INDEX(Master!$L$2:$L$1001,$O33)) | O33: {=IFERROR(SMALL(IF(Master!$A$2:$A$1001="VRKP",ROW(Master!$A$2:$A$1001)-ROW(Master!$A$2)+1),29),"")} | P33: =IF($A33="",0,IF(OR(AND($E33<>"",OR($E33>0.12)),AND($F33<>"",OR($F33>0.05)),AND($G33<>"",OR($G33>0.085)),AND($H33<>"",$H33<0.5),AND($I33<>"",$I33>120),AND($J33<>"",OR($J33<0.08))),1,0))
A34: =IF($O34="","",INDEX(Master!$D$2:$D$1001,$O34)) | B34: =IF($O34="","",INDEX(Master!$B$2:$B$1001,$O34)) | C34: =IF($O34="","",INDEX(Master!$C$2:$C$1001,$O34)) | D34: =IF($O34="","",INDEX(Master!$A$2:$A$1001,$O34)) | E34: =IF($O34="","",INDEX(Master!$E$2:$E$1001,$O34)) | F34: =IF($O34="","",INDEX(Master!$F$2:$F$1001,$O34)) | G34: =IF($O34="","",INDEX(Master!$G$2:$G$1001,$O34)) | H34: =IF($O34="","",INDEX(Master!$H$2:$H$1001,$O34)) | I34: =IF($O34="","",INDEX(Master!$I$2:$I$1001,$O34)) | J34: =IF($O34="","",INDEX(Master!$J$2:$J$1001,$O34)) | K34: =IF(OR($O34="",$F34="",$F34=0),"",$H34/$F34) | L34: =IF($O34="","",INDEX(Master!$K$2:$K$1001,$O34)) | M34: =IF($O34="","",INDEX(Master!$L$2:$L$1001,$O34)) | O34: {=IFERROR(SMALL(IF(Master!$A$2:$A$1001="VRKP",ROW(Master!$A$2:$A$1001)-ROW(Master!$A$2)+1),30),"")} | P34: =IF($A34="",0,IF(OR(AND($E34<>"",OR($E34>0.12)),AND($F34<>"",OR($F34>0.05)),AND($G34<>"",OR($G34>0.085)),AND($H34<>"",$H34<0.5),AND($I34<>"",$I34>120),AND($J34<>"",OR($J34<0.08))),1,0))
A35: =IF($O35="","",INDEX(Master!$D$2:$D$1001,$O35)) | B35: =IF($O35="","",INDEX(Master!$B$2:$B$1001,$O35)) | C35: =IF($O35="","",INDEX(Master!$C$2:$C$1001,$O35)) | D35: =IF($O35="","",INDEX(Master!$A$2:$A$1001,$O35)) | E35: =IF($O35="","",INDEX(Master!$E$2:$E$1001,$O35)) | F35: =IF($O35="","",INDEX(Master!$F$2:$F$1001,$O35)) | G35: =IF($O35="","",INDEX(Master!$G$2:$G$1001,$O35)) | H35: =IF($O35="","",INDEX(Master!$H$2:$H$1001,$O35)) | I35: =IF($O35="","",INDEX(Master!$I$2:$I$1001,$O35)) | J35: =IF($O35="","",INDEX(Master!$J$2:$J$1001,$O35)) | K35: =IF(OR($O35="",$F35="",$F35=0),"",$H35/$F35) | L35: =IF($O35="","",INDEX(Master!$K$2:$K$1001,$O35)) | M35: =IF($O35="","",INDEX(Master!$L$2:$L$1001,$O35)) | O35: {=IFERROR(SMALL(IF(Master!$A$2:$A$1001="VRKP",ROW(Master!$A$2:$A$1001)-ROW(Master!$A$2)+1),31),"")} | P35: =IF($A35="",0,IF(OR(AND($E35<>"",OR($E35>0.12)),AND($F35<>"",OR($F35>0.05)),AND($G35<>"",OR($G35>0.085)),AND($H35<>"",$H35<0.5),AND($I35<>"",$I35>120),AND($J35<>"",OR($J35<0.08))),1,0))
A36: =IF($O36="","",INDEX(Master!$D$2:$D$1001,$O36)) | B36: =IF($O36="","",INDEX(Master!$B$2:$B$1001,$O36)) | C36: =IF($O36="","",INDEX(Master!$C$2:$C$1001,$O36)) | D36: =IF($O36="","",INDEX(Master!$A$2:$A$1001,$O36)) | E36: =IF($O36="","",INDEX(Master!$E$2:$E$1001,$O36)) | F36: =IF($O36="","",INDEX(Master!$F$2:$F$1001,$O36)) | G36: =IF($O36="","",INDEX(Master!$G$2:$G$1001,$O36)) | H36: =IF($O36="","",INDEX(Master!$H$2:$H$1001,$O36)) | I36: =IF($O36="","",INDEX(Master!$I$2:$I$1001,$O36)) | J36: =IF($O36="","",INDEX(Master!$J$2:$J$1001,$O36)) | K36: =IF(OR($O36="",$F36="",$F36=0),"",$H36/$F36) | L36: =IF($O36="","",INDEX(Master!$K$2:$K$1001,$O36)) | M36: =IF($O36="","",INDEX(Master!$L$2:$L$1001,$O36)) | O36: {=IFERROR(SMALL(IF(Master!$A$2:$A$1001="VRKP",ROW(Master!$A$2:$A$1001)-ROW(Master!$A$2)+1),32),"")} | P36: =IF($A36="",0,IF(OR(AND($E36<>"",OR($E36>0.12)),AND($F36<>"",OR($F36>0.05)),AND($G36<>"",OR($G36>0.085)),AND($H36<>"",$H36<0.5),AND($I36<>"",$I36>120),AND($J36<>"",OR($J36<0.08))),1,0))
A37: =IF($O37="","",INDEX(Master!$D$2:$D$1001,$O37)) | B37: =IF($O37="","",INDEX(Master!$B$2:$B$1001,$O37)) | C37: =IF($O37="","",INDEX(Master!$C$2:$C$1001,$O37)) | D37: =IF($O37="","",INDEX(Master!$A$2:$A$1001,$O37)) | E37: =IF($O37="","",INDEX(Master!$E$2:$E$1001,$O37)) | F37: =IF($O37="","",INDEX(Master!$F$2:$F$1001,$O37)) | G37: =IF($O37="","",INDEX(Master!$G$2:$G$1001,$O37)) | H37: =IF($O37="","",INDEX(Master!$H$2:$H$1001,$O37)) | I37: =IF($O37="","",INDEX(Master!$I$2:$I$1001,$O37)) | J37: =IF($O37="","",INDEX(Master!$J$2:$J$1001,$O37)) | K37: =IF(OR($O37="",$F37="",$F37=0),"",$H37/$F37) | L37: =IF($O37="","",INDEX(Master!$K$2:$K$1001,$O37)) | M37: =IF($O37="","",INDEX(Master!$L$2:$L$1001,$O37)) | O37: {=IFERROR(SMALL(IF(Master!$A$2:$A$1001="VRKP",ROW(Master!$A$2:$A$1001)-ROW(Master!$A$2)+1),33),"")} | P37: =IF($A37="",0,IF(OR(AND($E37<>"",OR($E37>0.12)),AND($F37<>"",OR($F37>0.05)),AND($G37<>"",OR($G37>0.085)),AND($H37<>"",$H37<0.5),AND($I37<>"",$I37>120),AND($J37<>"",OR($J37<0.08))),1,0))
A38: =IF($O38="","",INDEX(Master!$D$2:$D$1001,$O38)) | B38: =IF($O38="","",INDEX(Master!$B$2:$B$1001,$O38)) | C38: =IF($O38="","",INDEX(Master!$C$2:$C$1001,$O38)) | D38: =IF($O38="","",INDEX(Master!$A$2:$A$1001,$O38)) | E38: =IF($O38="","",INDEX(Master!$E$2:$E$1001,$O38)) | F38: =IF($O38="","",INDEX(Master!$F$2:$F$1001,$O38)) | G38: =IF($O38="","",INDEX(Master!$G$2:$G$1001,$O38)) | H38: =IF($O38="","",INDEX(Master!$H$2:$H$1001,$O38)) | I38: =IF($O38="","",INDEX(Master!$I$2:$I$1001,$O38)) | J38: =IF($O38="","",INDEX(Master!$J$2:$J$1001,$O38)) | K38: =IF(OR($O38="",$F38="",$F38=0),"",$H38/$F38) | L38: =IF($O38="","",INDEX(Master!$K$2:$K$1001,$O38)) | M38: =IF($O38="","",INDEX(Master!$L$2:$L$1001,$O38)) | O38: {=IFERROR(SMALL(IF(Master!$A$2:$A$1001="VRKP",ROW(Master!$A$2:$A$1001)-ROW(Master!$A$2)+1),34),"")} | P38: =IF($A38="",0,IF(OR(AND($E38<>"",OR($E38>0.12)),AND($F38<>"",OR($F38>0.05)),AND($G38<>"",OR($G38>0.085)),AND($H38<>"",$H38<0.5),AND($I38<>"",$I38>120),AND($J38<>"",OR($J38<0.08))),1,0))
A39: =IF($O39="","",INDEX(Master!$D$2:$D$1001,$O39)) | B39: =IF($O39="","",INDEX(Master!$B$2:$B$1001,$O39)) | C39: =IF($O39="","",INDEX(Master!$C$2:$C$1001,$O39)) | D39: =IF($O39="","",INDEX(Master!$A$2:$A$1001,$O39)) | E39: =IF($O39="","",INDEX(Master!$E$2:$E$1001,$O39)) | F39: =IF($O39="","",INDEX(Master!$F$2:$F$1001,$O39)) | G39: =IF($O39="","",INDEX(Master!$G$2:$G$1001,$O39)) | H39: =IF($O39="","",INDEX(Master!$H$2:$H$1001,$O39)) | I39: =IF($O39="","",INDEX(Master!$I$2:$I$1001,$O39)) | J39: =IF($O39="","",INDEX(Master!$J$2:$J$1001,$O39)) | K39: =IF(OR($O39="",$F39="",$F39=0),"",$H39/$F39) | L39: =IF($O39="","",INDEX(Master!$K$2:$K$1001,$O39)) | M39: =IF($O39="","",INDEX(Master!$L$2:$L$1001,$O39)) | O39: {=IFERROR(SMALL(IF(Master!$A$2:$A$1001="VRKP",ROW(Master!$A$2:$A$1001)-ROW(Master!$A$2)+1),35),"")} | P39: =IF($A39="",0,IF(OR(AND($E39<>"",OR($E39>0.12)),AND($F39<>"",OR($F39>0.05)),AND($G39<>"",OR($G39>0.085)),AND($H39<>"",$H39<0.5),AND($I39<>"",$I39>120),AND($J39<>"",OR($J39<0.08))),1,0))
