Workbook
Name DISPATCH: Prod.!$O$16

Sheet Daily Stock
A1: 30/9/2026
A2: SIZE | B2: TOTAL PROD | D2: HOT ROLLED | F2: RHF | H2: DISPATCH | J2: BYPASS | L2: HOTOUT | N2: MANUAL STOCK | P2: ERP STOCK | R2: DIFFERENCE
B3: PCS | C3: WEIGHT | D3: PCS | E3: WEIGHT | F3: PCS | G3: WEIGHT | H3: PCS | I3: WEIGHT | J3: PCS | K3: WEIGHT | L3: PCS | M3: WEIGHT | N3: PCS | O3: WEIGHT | P3: PCS | Q3: WEIGHT | R3: PCS | S3: WEIGHT | U3: MANUAL
A4: 110 X 6 | N4: 0 | O4: =(N4*0.57) -> 0 | P4: 0 | Q4: 0 | R4: 0 | S4: 0 | V4: =U4-P4 -> 0 | W4: =U4*0.57 -> 0
A5: 110X 5.25 | N5: 0 | O5: =(N5*5.25*0.095) -> 0 | P5: 0 | Q5: 0 | R5: 0 | S5: 0 | V5: =U5-P5 -> 0 | W5: =U5*0.798 -> 0
A6: RAN 110 | N6: 73 | O6: =N6*0.095 -> 6.935 | P6: =Q6/0.095 -> 72.747368 | Q6: 6.911 | R6: =N6-P6 -> 0.25263158 | S6: =O6-Q6 -> 0.024 | U6: 118 | V6: =U6-P6 -> 45.252632 | W6: =(U6*0.095) -> 11.21
A7: 130 X 6 | N7: 95 | O7: =N7*6*0.132335 -> 75.43095 | P7: =Q7/6/0.132335 -> 94.293523 | Q7: 74.87 | R7: =N7-P7 -> 0.70647725 | S7: =O7-Q7 -> 0.56095 | U7: 47 | V7: =U7-P7 -> -47.293523 | W7: =U7*6*0.132335 -> 37.31847
A8: 130 X 5 | N8: 50 | O8: =N8*5*0.132335 -> 33.08375 | P8: =Q8/5/0.132335 -> 50.000378 | Q8: =34.364-1.28 -> 33.084 | R8: =N8-P8 -> -0.00037782899 | S8: =O8-Q8 -> -0.00025 | U8: 17 | V8: =U8-P8 -> -33.000378 | W8: =U8*5*0.132335 -> 11.248475
A9: 130 X 4 | N9: 63 | O9: =N9*4*0.132335 -> 33.34842 | P9: =Q9/4/0.132335 -> 62.519364 | Q9: =25.935+5.879+1.28 -> 33.094 | R9: =N9-P9 -> 0.48063626 | S9: =O9-Q9 -> 0.25442 | U9: 27 | V9: =U9-P9 -> -35.519364 | W9: =U9*4*0.132335 -> 14.29218
A10: 130 X 3 | N10: 308 | O10: =N10*3*0.132335 -> 122.27754 | P10: =Q10/3/0.132335 -> 308.00116 | Q10: =128.157-5.879 -> 122.278 | R10: =N10-P10 -> -0.0011586756 | S10: =O10-Q10 -> -0.00046 | U10: 19 | V10: =U10-P10 -> -289.00116 | W10: =U10*3*0.132335 -> 7.543095
A11: RAN 160 | N11: 0 | O11: =N11*0.198005 -> 0 | P11: =Q11/0.198005 -> 0 | Q11: 0 | R11: =N11-P11 -> 0 | S11: =O11-Q11 -> 0 | U11: 0 | V11: =U11-P11 -> 0 | W11: =U11*0.198005 -> 0
A12: 160 X 5 | N12: =57-5 -> 52 | O12: =N12*5*0.198005 -> 51.4813 | P12: =Q12/5/0.198005 -> 51.049216 | Q12: 50.54 | R12: =N12-P12 -> 0.95078407 | S12: =O12-Q12 -> 0.9413 | U12: 4 | V12: =U12-P12 -> -47.049216 | W12: =U12*5*0.198005 -> 3.9601
A13: 160 X 4 | N13: =118-1 -> 117 | O13: =N13*4*0.198005 -> 92.66634 | P13: =Q13/4/0.198005 -> 103.89889 | Q13: 82.29 | R13: =N13-P13 -> 13.101109 | S13: =O13-Q13 -> 10.37634 | U13: 21 | V13: =U13-P13 -> -82.898891 | W13: =U13*4*0.198005 -> 16.63242
A14: 160 X 3 | N14: =431+6 -> 437 | O14: =N14*3*0.198005 -> 259.58455 | P14: =Q14/3/0.198005 -> 437.34081 | Q14: 259.787 | R14: =N14-P14 -> -0.34080789 | S14: =O14-Q14 -> -0.202445 | U14: 235 | V14: =U14-P14 -> -202.34081 | W14: =U14*3*0.198005 -> 139.59352
C15: =SUM(C4:C14) -> 0 | E15: =SUM(E4:E14) -> 0 | G15: =SUM(G4:G14) -> 0 | I15: =SUM(I4:I14) -> 0 | K15: =SUM(K4:K14) -> 0 | M15: =SUM(M4:M14) -> 0 | O15: =SUM(O4:O14) -> 674.80786 | Q15: =SUM(Q4:Q14) -> 662.854 | S15: =SUM(S4:S14) -> 11.953855
A19: =Prod.!A4 -> 46296
A20: SIZE | B20: TOTAL PROD | D20: HOT ROLLED | F20: RHF | H20: DISPATCH | J20: BYPASS | L20: HOTOUT | N20: MANUAL STOCK | P20: ERP STOCK | R20: DIFFERENCE
B21: PCS | C21: WEIGHT | D21: PCS | E21: WEIGHT | F21: PCS | G21: WEIGHT | H21: PCS | I21: WEIGHT | J21: PCS | K21: WEIGHT | L21: PCS | M21: WEIGHT | N21: PCS | O21: WEIGHT | P21: PCS | Q21: WEIGHT | R21: PCS | S21: WEIGHT
A22: 110 X 6 | B22: =D22+J22 -> 0 | C22: =B22*0.57 -> 0 | E22: =D22*0.57 -> 0 | G22: =F22*0.57 -> 0 | H22: =I22/6/0.095 -> 0 | J22: =Prod.!M16 -> 0 | K22: =(J22*0.57) -> 0 | N22: =((J22+L22+N4)-(F22+H22)) -> 0 | O22: =(N22*0.57) -> 0 | P22: =Q22/6/0.095 -> 0 | Q22: =(Q4+K22+M22)-(G22+I22) -> 0 | R22: =N22-P22 -> 0 | S22: =O22-Q22 -> 0 | V22: =U22-P22 -> 0 | W22: =U22*0.57 -> 0
A23: 110X 5.25 | B23: =D23+J23 -> 0 | C23: =B23*5.25*0.095 -> 0 | E23: =D23*5.25*0.095 -> 0 | G23: =F23*5.25*0.095 -> 0 | H23: =I23/5.25/0.095 -> 0 | K23: =J23*5.25*0.095 -> 0 | N23: =((J23+L23+N5)-(F23+H23)) -> 0 | O23: =(N23*5.25*0.095) -> 0 | P23: =Q23/5.25/0.095 -> 0 | Q23: =(Q5+K23+M23)-(G23+I23) -> 0 | R23: =N23-P23 -> 0 | S23: =O23-Q23 -> 0 | V23: =U23-P23 -> 0 | W23: =U23*0.798 -> 0
A24: RAN 110 | B24: =D24+J24 -> 0 | C24: =B24*0.095 -> 0 | D24: =Prod.!S18 -> 0 | E24: =D24*0.095 -> 0 | G24: =F24*0.095 -> 0 | H24: =I24/0.095 -> 0 | J24: =Prod.!J16*3+Prod.!K16*4+Prod.!L16*5 -> 0 | K24: =J24*0.095 -> 0 | N24: =((J24+L24+N6)-(F24+H24)) -> 73 | O24: =N24*0.095 -> 6.935 | P24: =Q24/0.095 -> 72.747368 | Q24: =(Q6+K24+M24)-(G24+I24) -> 6.911 | R24: =N24-P24 -> 0.25263158 | S24: =O24-Q24 -> 0.024 | U24: 118 | V24: =U24-P24 -> 45.252632 | W24: =(U24*0.095) -> 11.21
A25: 130 X 6 | B25: =D25+J25 -> 0 | C25: =B25*6*0.132335 -> 0 | D25: =Prod.!S17 -> 0 | E25: =D25*6*0.132335 -> 0 | F25: =Prod.!M17 -> 0 | G25: =F25*6*0.132335 -> 0 | H25: =I25/6/0.132335 -> 0 | J25: =Prod.!Y17 -> 0 | K25: =J25*6*0.132335 -> 0 | L25: =M25/6/0.132335 -> 0 | M25: =Prod.!AR5 -> 0 | N25: =((J25+L25+N7)-(F25+H25)) -> 95 | O25: =N25*6*0.132335 -> 75.43095 | P25: =Q25/6/0.132335 -> 94.293523 | Q25: =(Q7+K25+M25)-(G25+I25) -> 74.87 | R25: =N25-P25 -> 0.70647725 | S25: =O25-Q25 -> 0.56095 | U25: 465 | V25: =U25-P25 -> 370.70648 | W25: =U25*6*0.132335 -> 369.21465
A26: 130 X 5 | B26: =D26+J26 -> 0 | C26: =B26*5*0.132335 -> 0 | D26: =Prod.!R17 -> 0 | E26: =D26*5*0.132335 -> 0 | F26: =Prod.!L17 -> 0 | G26: =F26*5*0.132335 -> 0 | H26: =I26/5/0.132335 -> 0 | J26: =Prod.!X17 -> 0 | K26: =J26*5*0.132335 -> 0 | L26: =M26/5/0.132335 -> 0 | M26: =Prod.!AR6 -> 0 | N26: =((J26+L26+N8)-(F26+H26)) -> 50 | O26: =N26*5*0.132335 -> 33.08375 | P26: =Q26/5/0.132335 -> 50.000378 | Q26: =(Q8+K26+M26)-(G26+I26) -> 33.084 | R26: =N26-P26 -> -0.00037782899 | S26: =O26-Q26 -> -0.00025 | U26: 38 | V26: =U26-P26 -> -12.000378 | W26: =U26*5*0.132335 -> 25.14365
A27: 130 X 4 | B27: =D27+J27 -> 0 | C27: =B27*4*0.132335 -> 0 | D27: =Prod.!Q17 -> 0 | E27: =D27*4*0.132335 -> 0 | F27: =Prod.!K17 -> 0 | G27: =F27*4*0.132335 -> 0 | H27: =I27/4/0.132335 -> 0 | J27: =Prod.!W17 -> 0 | K27: =J27*4*0.132335 -> 0 | L27: =M27/4/0.132335 -> 0 | M27: =Prod.!AR7 -> 0 | N27: =((J27+L27+N9)-(F27+H27)) -> 63 | O27: =N27*4*0.132335 -> 33.34842 | P27: =Q27/4/0.132335 -> 62.519364 | Q27: =(Q9+K27+M27)-(G27+I27) -> 33.094 | R27: =N27-P27 -> 0.48063626 | S27: =O27-Q27 -> 0.25442 | U27: 158 | V27: =U27-P27 -> 95.480636 | W27: =U27*4*0.132335 -> 83.63572
A28: 130 X 3 | B28: =D28+J28 -> 0 | C28: =B28*3*0.132335 -> 0 | D28: =Prod.!P17 -> 0 | E28: =D28*3*0.132335 -> 0 | F28: =Prod.!J17 -> 0 | G28: =F28*3*0.132335 -> 0 | H28: =I28/3/0.132335 -> 0 | J28: =Prod.!V17 -> 0 | K28: =J28*3*0.132335 -> 0 | L28: =M28/3/0.132335 -> 0 | M28: =Prod.!AR8 -> 0 | N28: =((J28+L28+N10)-(F28+H28)) -> 308 | O28: =N28*3*0.132335 -> 122.27754 | P28: =Q28/3/0.132335 -> 308.00116 | Q28: =(Q10+K28+M28)-(G28+I28) -> 122.278 | R28: =N28-P28 -> -0.0011586756 | S28: =O28-Q28 -> -0.00046 | U28: 383 | V28: =U28-P28 -> 74.998841 | W28: =U28*3*0.132335 -> 152.05292
A29: RAN 160 | B29: =D29+J29 -> 0 | C29: =B29*0.198005 -> 0 | E29: =D29*0.198005 -> 0 | G29: =F29*0.198005 -> 0 | H29: =I29/0.095 -> 0 | K29: =J29*0.198005 -> 0 | N29: =((J29+L29+N11)-(F29+H29)) -> 0 | O29: =N29*0.198005 -> 0 | P29: =Q29/0.198005 -> 0 | Q29: =(Q11+K29+M29)-(G29+I29) -> 0 | R29: =N29-P29 -> 0 | S29: =O29-Q29 -> 0 | U29: 0 | V29: =U29-P29 -> 0 | W29: =U29*0.198005 -> 0
A30: 160 X 5 | B30: =D30+J30 -> 0 | C30: =B30*5*0.198005 -> 0 | D30: =Prod.!R18 -> 0 | E30: =D30*5*0.198005 -> 0 | F30: =Prod.!L18 -> 0 | G30: =F30*5*0.198005 -> 0 | H30: =I30/5/0.198005 -> 0 | J30: =Prod.!X18 -> 0 | K30: =J30*5*0.198005 -> 0 | L30: =M30/5/0.198005 -> 0 | M30: =Prod.!AR14 -> 0 | N30: =((J30+L30+N12)-(F30+H30)) -> 52 | O30: =N30*5*0.198005 -> 51.4813 | P30: =Q30/5/0.198005 -> 51.049216 | Q30: =(Q12+K30+M30)-(G30+I30) -> 50.54 | R30: =N30-P30 -> 0.95078407 | S30: =O30-Q30 -> 0.9413 | U30: 93 | V30: =U30-P30 -> 41.950784 | W30: =U30*5*0.198005 -> 92.072325
A31: 160 X 4 | B31: =D31+J31 -> 0 | C31: =B31*4*0.198005 -> 0 | D31: =Prod.!Q18 -> 0 | E31: =D31*4*0.198005 -> 0 | F31: =Prod.!K18 -> 0 | G31: =F31*4*0.198005 -> 0 | H31: =I31/4/0.198005 -> 0 | J31: =Prod.!W18 -> 0 | K31: =J31*4*0.198005 -> 0 | L31: =M31/4/0.198005 -> 0 | M31: =Prod.!AR15 -> 0 | N31: =((J31+L31+N13)-(F31+H31)) -> 117 | O31: =N31*4*0.198005 -> 92.66634 | P31: =Q31/4/0.198005 -> 103.89889 | Q31: =(Q13+K31+M31)-(G31+I31) -> 82.29 | R31: =N31-P31 -> 13.101109 | S31: =O31-Q31 -> 10.37634 | U31: 134 | V31: =U31-P31 -> 30.101109 | W31: =U31*4*0.198005 -> 106.13068
A32: 160 X 3 | B32: =D32+J32 -> 0 | C32: =B32*3*0.198005 -> 0 | D32: =Prod.!P18 -> 0 | E32: =D32*3*0.198005 -> 0 | F32: =Prod.!J18 -> 0 | G32: =F32*3*0.198005 -> 0 | H32: =I32/3/0.198005 -> 0 | J32: =Prod.!V18 -> 0 | K32: =J32*3*0.198005 -> 0 | L32: =M32/3/0.198005 -> 0 | M32: =Prod.!AR16 -> 0 | N32: =((J32+L32+N14)-(F32+H32)) -> 437 | O32: =N32*3*0.198005 -> 259.58455 | P32: =Q32/3/0.198005 -> 437.34081 | Q32: =(Q14+K32+M32)-(G32+I32) -> 259.787 | R32: =N32-P32 -> -0.34080789 | S32: =O32-Q32 -> -0.202445 | U32: 837 | V32: =U32-P32 -> 399.65919 | W32: =U32*3*0.198005 -> 497.19055
C33: =SUM(C22:C32) -> 0 | E33: =SUM(E22:E32) -> 0 | G33: =SUM(G22:G32) -> 0 | I33: =SUM(I22:I32) -> 0 | K33: =SUM(K22:K32) -> 0 | M33: =SUM(M22:M32) -> 0 | O33: =SUM(O22:O32) -> 674.80786 | Q33: =SUM(Q22:Q32) -> 662.854 | S33: =SUM(S22:S32) -> 11.953855

Sheet Prod.
M1: TOTAL PROD SHEET
A2: DATE | B2: H.No. | C2: Analysis Report | H2: SIZE | I2: WEIGHT/MTR | J2: 130 X 130 | N2: TOTAL MTR | O2: Quantity (MT) | P2: HOT CHARGING | T2: TOTAL MTR | U2: Quantity (MT) | V2: BYPASS | Z2: TOTAL MTR | AA2: Quantity (MT) | AB2: Total Prod | AC2: HOT OUT | AG2: TOTAL MTR | AH2: Quantity (MT) | AK2: HEAT WISE TRANSFER | AP2: HOTOUT | AT2: F&L BYPASS | AX2: MTR | AY2: WEIGHT
C3: %C | D3: % Mn | E3: %Si | F3: %S | G3: % P | J3: 3M | K3: 4M | L3: 5M | M3: 6M | P3: 3M | Q3: 4M | R3: 5M | S3: 6M | V3: 3M | W3: 4M | X3: 5M | Y3: 6M | AC3: 3M | AD3: 4M | AE3: 5M | AF3: 6M | AK3: 3MTR | AL3: 4MTR | AM3: 5MTR | AN3: 6MTR | AO3: 130 | AT3: 3M | AU3: 4M | AV3: 5M | AW3: 6M
A4: 46296 | B4: 1.10.1 | I4: =IF(H4=130,0.132335,IF(H4=100,0.0785,IF(H4=110,0.095,IF(H4=160,0.198005,"")))) | N4: =J4*3+K4*4+L4*5+M4*6 -> 0 | O4: =IF($J$2="160 X 160",N4*0.198005,IF($J$2="110 X 110",N4*0.095,IF($J$2="130 X 130",N4*0.132335,0))) -> 0 | T4: =P4*3+Q4*4+R4*5+S4*6 -> 0 | U4: =IFERROR(T4*I4,"") | Z4: =V4*3+W4*4+X4*5+Y4*6 -> 0 | AA4: =IFERROR(Z4*I4,"") | AB4: =IFERROR(U4+AA4+O4,"") | AG4: =AC4*3+AD4*4+AE4*5+AF4*6 -> 0 | AH4: =IFERROR(AG4*I4,"") | AJ4: =IF(H4=130,0.132335,IF(H4=100,0.0785,IF(H4=110,0.095,IF(H4=160,0.198005,"")))) | AK4: =IFERROR(P4*3*AJ4,"") | AL4: =IFERROR(Q4*4*AJ4,"") | AM4: =IFERROR(R4*5*AJ4,"") | AN4: =IFERROR(S4*6*AJ4,"") | AX4: =AT4*3+AU4*4+AV4*5+AW4*6 -> 0 | AY4: =AX4*I4 -> #VALUE!
B5: 1.10.2 | I5: =IF(H5=130,0.132335,IF(H5=100,0.0785,IF(H5=110,0.095,IF(H5=160,0.198005,"")))) | N5: =J5*3+K5*4+L5*5+M5*6 -> 0 | O5: =IF($J$2="160 X 160",N5*0.198005,IF($J$2="110 X 110",N5*0.095,IF($J$2="130 X 130",N5*0.132335,0))) -> 0 | T5: =P5*3+Q5*4+R5*5+S5*6 -> 0 | U5: =IFERROR(T5*I5,"") | Z5: =V5*3+W5*4+X5*5+Y5*6 -> 0 | AA5: =IFERROR(Z5*I5,"") | AB5: =IFERROR(U5+AA5+O5,"") | AG5: =AC5*3+AD5*4+AE5*5+AF5*6 -> 0 | AH5: =IFERROR(AG5*I5,"") | AJ5: =IF(H5=130,0.132335,IF(H5=100,0.0785,IF(H5=110,0.095,IF(H5=160,0.198005,"")))) | AK5: =IFERROR(P5*3*AJ5,"") | AL5: =IFERROR(Q5*4*AJ5,"") | AM5: =IFERROR(R5*5*AJ5,"") | AN5: =IFERROR(S5*6*AJ5,"") | AP5: 6 | AR5: =IFERROR(AP5*AQ5*AS8,0) -> 0 | AX5: =AT5*3+AU5*4+AV5*5+AW5*6 -> 0 | AY5: =AX5*I5 -> #VALUE!
B6: 1.10.3 | I6: =IF(H6=130,0.132335,IF(H6=100,0.0785,IF(H6=110,0.095,IF(H6=160,0.198005,"")))) | N6: =J6*3+K6*4+L6*5+M6*6 -> 0 | O6: =IF($J$2="160 X 160",N6*0.198005,IF($J$2="110 X 110",N6*0.095,IF($J$2="130 X 130",N6*0.132335,0))) -> 0 | T6: =P6*3+Q6*4+R6*5+S6*6 -> 0 | U6: =IFERROR(T6*I6,"") | Z6: =V6*3+W6*4+X6*5+Y6*6 -> 0 | AA6: =IFERROR(Z6*I6,"") | AB6: =IFERROR(U6+AA6+O6,"") | AG6: =AC6*3+AD6*4+AE6*5+AF6*6 -> 0 | AH6: =IFERROR(AG6*I6,"") | AJ6: =IF(H6=130,0.132335,IF(H6=100,0.0785,IF(H6=110,0.095,IF(H6=160,0.198005,"")))) | AK6: =IFERROR(P6*3*AJ6,"") | AL6: =IFERROR(Q6*4*AJ6,"") | AM6: =IFERROR(R6*5*AJ6,"") | AN6: =IFERROR(S6*6*AJ6,"") | AP6: 5 | AR6: =IFERROR(AP6*AQ6*AS8,0) -> 0 | AX6: =AT6*3+AU6*4+AV6*5+AW6*6 -> 0 | AY6: =AX6*I6 -> #VALUE!
B7: 1.10.4 | I7: =IF(H7=130,0.132335,IF(H7=100,0.0785,IF(H7=110,0.095,IF(H7=160,0.198005,"")))) | N7: =J7*3+K7*4+L7*5+M7*6 -> 0 | O7: =IF($J$2="160 X 160",N7*0.198005,IF($J$2="110 X 110",N7*0.095,IF($J$2="130 X 130",N7*0.132335,0))) -> 0 | T7: =P7*3+Q7*4+R7*5+S7*6 -> 0 | U7: =IFERROR(T7*I7,"") | Z7: =V7*3+W7*4+X7*5+Y7*6 -> 0 | AA7: =IFERROR(Z7*I7,"") | AB7: =IFERROR(U7+AA7+O7,"") | AG7: =AC7*3+AD7*4+AE7*5+AF7*6 -> 0 | AH7: =IFERROR(AG7*I7,"") | AJ7: =IF(H7=130,0.132335,IF(H7=100,0.0785,IF(H7=110,0.095,IF(H7=160,0.198005,"")))) | AK7: =IFERROR(P7*3*AJ7,"") | AL7: =IFERROR(Q7*4*AJ7,"") | AM7: =IFERROR(R7*5*AJ7,"") | AN7: =IFERROR(S7*6*AJ7,"") | AP7: 4 | AR7: =IFERROR(AP7*AQ7*AS8,0) -> 0 | AX7: =AT7*3+AU7*4+AV7*5+AW7*6 -> 0 | AY7: =AX7*I7 -> #VALUE!
B8: 1.10.5 | I8: =IF(H8=130,0.132335,IF(H8=100,0.0785,IF(H8=110,0.095,IF(H8=160,0.198005,"")))) | N8: =J8*3+K8*4+L8*5+M8*6 -> 0 | O8: =IF($J$2="160 X 160",N8*0.198005,IF($J$2="110 X 110",N8*0.095,IF($J$2="130 X 130",N8*0.132335,0))) -> 0 | T8: =P8*3+Q8*4+R8*5+S8*6 -> 0 | U8: =IFERROR(T8*I8,"") | Z8: =V8*3+W8*4+X8*5+Y8*6 -> 0 | AA8: =IFERROR(Z8*I8,"") | AB8: =IFERROR(U8+AA8+O8,"") | AG8: =AC8*3+AD8*4+AE8*5+AF8*6 -> 0 | AH8: =IFERROR(AG8*I8,"") | AJ8: =IF(H8=130,0.132335,IF(H8=100,0.0785,IF(H8=110,0.095,IF(H8=160,0.198005,"")))) | AK8: =IFERROR(P8*3*AJ8,"") | AL8: =IFERROR(Q8*4*AJ8,"") | AM8: =IFERROR(R8*5*AJ8,"") | AN8: =IFERROR(S8*6*AJ8,"") | AP8: 3 | AR8: =IFERROR(AP8*AQ8*AS8,0) -> 0 | AS8: =IFERROR(AR9/((AP8*AQ8)+(AP7*AQ7)+(AP6*AQ6)+(AP5*AQ5)),0) -> 0 | AX8: =AT8*3+AU8*4+AV8*5+AW8*6 -> 0 | AY8: =AX8*I8 -> #VALUE!
B9: 1.10.6 | I9: =IF(H9=130,0.132335,IF(H9=100,0.0785,IF(H9=110,0.095,IF(H9=160,0.198005,"")))) | N9: =J9*3+K9*4+L9*5+M9*6 -> 0 | O9: =IF($J$2="160 X 160",N9*0.198005,IF($J$2="110 X 110",N9*0.095,IF($J$2="130 X 130",N9*0.132335,0))) -> 0 | T9: =P9*3+Q9*4+R9*5+S9*6 -> 0 | U9: =IFERROR(T9*I9,"") | Z9: =V9*3+W9*4+X9*5+Y9*6 -> 0 | AA9: =IFERROR(Z9*I9,"") | AB9: =IFERROR(U9+AA9+O9,"") | AG9: =AC9*3+AD9*4+AE9*5+AF9*6 -> 0 | AH9: =IFERROR(AG9*I9,"") | AJ9: =IF(H9=130,0.132335,IF(H9=100,0.0785,IF(H9=110,0.095,IF(H9=160,0.198005,"")))) | AK9: =IFERROR(P9*3*AJ9,"") | AL9: =IFERROR(Q9*4*AJ9,"") | AM9: =IFERROR(R9*5*AJ9,"") | AN9: =IFERROR(S9*6*AJ9,"") | AX9: =AT9*3+AU9*4+AV9*5+AW9*6 -> 0 | AY9: =AX9*I9 -> #VALUE!
B10: 1.10.7 | I10: =IF(H10=130,0.132335,IF(H10=100,0.0785,IF(H10=110,0.095,IF(H10=160,0.198005,"")))) | N10: =J10*3+K10*4+L10*5+M10*6 -> 0 | O10: =IF($J$2="160 X 160",N10*0.198005,IF($J$2="110 X 110",N10*0.095,IF($J$2="130 X 130",N10*0.132335,0))) -> 0 | T10: =P10*3+Q10*4+R10*5+S10*6 -> 0 | U10: =IFERROR(T10*I10,"") | Z10: =V10*3+W10*4+X10*5+Y10*6 -> 0 | AA10: =IFERROR(Z10*I10,"") | AB10: =IFERROR(U10+AA10+O10,"") | AG10: =AC10*3+AD10*4+AE10*5+AF10*6 -> 0 | AH10: =IFERROR(AG10*I10,"") | AJ10: =IF(H10=130,0.132335,IF(H10=100,0.0785,IF(H10=110,0.095,IF(H10=160,0.198005,"")))) | AK10: =IFERROR(P10*3*AJ10,"") | AL10: =IFERROR(Q10*4*AJ10,"") | AM10: =IFERROR(R10*5*AJ10,"") | AN10: =IFERROR(S10*6*AJ10,"") | AP10: HOTOUT | AX10: =AT10*3+AU10*4+AV10*5+AW10*6 -> 0 | AY10: =AX10*I10 -> #VALUE!
B11: 1.10.8 | I11: =IF(H11=130,0.132335,IF(H11=100,0.0785,IF(H11=110,0.095,IF(H11=160,0.198005,"")))) | N11: =J11*3+K11*4+L11*5+M11*6 -> 0 | O11: =IF($J$2="160 X 160",N11*0.198005,IF($J$2="110 X 110",N11*0.095,IF($J$2="130 X 130",N11*0.132335,0))) -> 0 | T11: =P11*3+Q11*4+R11*5+S11*6 -> 0 | U11: =IFERROR(T11*I11,"") | Z11: =V11*3+W11*4+X11*5+Y11*6 -> 0 | AA11: =IFERROR(Z11*I11,"") | AB11: =IFERROR(U11+AA11+O11,"") | AG11: =AC11*3+AD11*4+AE11*5+AF11*6 -> 0 | AH11: =IFERROR(AG11*I11,"") | AJ11: =IF(H11=130,0.132335,IF(H11=100,0.0785,IF(H11=110,0.095,IF(H11=160,0.198005,"")))) | AK11: =IFERROR(P11*3*AJ11,"") | AL11: =IFERROR(Q11*4*AJ11,"") | AM11: =IFERROR(R11*5*AJ11,"") | AN11: =IFERROR(S11*6*AJ11,"") | AO11: 160 | AX11: =AT11*3+AU11*4+AV11*5+AW11*6 -> 0 | AY11: =AX11*I11 -> #VALUE!
B12: 1.10.9 | I12: =IF(H12=130,0.132335,IF(H12=100,0.0785,IF(H12=110,0.095,IF(H12=160,0.198005,"")))) | N12: =J12*3+K12*4+L12*5+M12*6 -> 0 | O12: =IF($J$2="160 X 160",N12*0.198005,IF($J$2="110 X 110",N12*0.095,IF($J$2="130 X 130",N12*0.132335,0))) -> 0 | T12: =P12*3+Q12*4+R12*5+S12*6 -> 0 | U12: =IFERROR(T12*I12,"") | Z12: =V12*3+W12*4+X12*5+Y12*6 -> 0 | AA12: =IFERROR(Z12*I12,"") | AB12: =IFERROR(U12+AA12+O12,"") | AG12: =AC12*3+AD12*4+AE12*5+AF12*6 -> 0 | AH12: =IFERROR(AG12*I12,"") | AJ12: =IF(H12=130,0.132335,IF(H12=100,0.0785,IF(H12=110,0.095,IF(H12=160,0.198005,"")))) | AK12: =IFERROR(P12*3*AJ12,"") | AL12: =IFERROR(Q12*4*AJ12,"") | AM12: =IFERROR(R12*5*AJ12,"") | AN12: =IFERROR(S12*6*AJ12,"") | AX12: =AT12*3+AU12*4+AV12*5+AW12*6 -> 0 | AY12: =AX12*I12 -> #VALUE!
B13: 1.10.10 | I13: =IF(H13=130,0.132335,IF(H13=100,0.0785,IF(H13=110,0.095,IF(H13=160,0.198005,"")))) | N13: =J13*3+K13*4+L13*5+M13*6 -> 0 | O13: =IF($J$2="160 X 160",N13*0.198005,IF($J$2="110 X 110",N13*0.095,IF($J$2="130 X 130",N13*0.132335,0))) -> 0 | T13: =P13*3+Q13*4+R13*5+S13*6 -> 0 | U13: =IFERROR(T13*I13,"") | Z13: =V13*3+W13*4+X13*5+Y13*6 -> 0 | AA13: =IFERROR(Z13*I13,"") | AB13: =IFERROR(U13+AA13+O13,"") | AG13: =AC13*3+AD13*4+AE13*5+AF13*6 -> 0 | AH13: =IFERROR(AG13*I13,"") | AJ13: =IF(H13=130,0.132335,IF(H13=100,0.0785,IF(H13=110,0.095,IF(H13=160,0.198005,"")))) | AK13: =IFERROR(P13*3*AJ13,"") | AL13: =IFERROR(Q13*4*AJ13,"") | AM13: =IFERROR(R13*5*AJ13,"") | AN13: =IFERROR(S13*6*AJ13,"") | AP13: 6 | AR13: =IFERROR(AP13*AQ13*AS16,0) -> 0 | AX13: =AT13*3+AU13*4+AV13*5+AW13*6 -> 0 | AY13: =AX13*I13 -> #VALUE!
B14: 1.10.11 | I14: =IF(H14=130,0.132335,IF(H14=100,0.0785,IF(H14=110,0.095,IF(H14=160,0.198005,"")))) | N14: =J14*3+K14*4+L14*5+M14*6 -> 0 | O14: =IF($J$2="160 X 160",N14*0.198005,IF($J$2="110 X 110",N14*0.095,IF($J$2="130 X 130",N14*0.132335,0))) -> 0 | T14: =P14*3+Q14*4+R14*5+S14*6 -> 0 | U14: =IFERROR(T14*I14,"") | Z14: =V14*3+W14*4+X14*5+Y14*6 -> 0 | AA14: =IFERROR(Z14*I14,"") | AB14: =IFERROR(U14+AA14+O14,"") | AG14: =AC14*3+AD14*4+AE14*5+AF14*6 -> 0 | AH14: =IFERROR(AG14*I14,"") | AJ14: =IF(H14=130,0.132335,IF(H14=100,0.0785,IF(H14=110,0.095,IF(H14=160,0.198005,"")))) | AK14: =IFERROR(P14*3*AJ14,"") | AL14: =IFERROR(Q14*4*AJ14,"") | AM14: =IFERROR(R14*5*AJ14,"") | AN14: =IFERROR(S14*6*AJ14,"") | AP14: 5 | AR14: =IFERROR(AP14*AQ14*AS16,0) -> 0 | AX14: =AT14*3+AU14*4+AV14*5+AW14*6 -> 0 | AY14: =AX14*I14 -> #VALUE!
B15: 1.10.12 | I15: =IF(H15=130,0.132335,IF(H15=100,0.0785,IF(H15=110,0.095,IF(H15=160,0.198005,"")))) | N15: =J15*3+K15*4+L15*5+M15*6 -> 0 | O15: =IF($J$2="160 X 160",N15*0.198005,IF($J$2="110 X 110",N15*0.095,IF($J$2="130 X 130",N15*0.132335,0))) -> 0 | T15: =P15*3+Q15*4+R15*5+S15*6 -> 0 | U15: =IFERROR(T15*I15,"") | Z15: =V15*3+W15*4+X15*5+Y15*6 -> 0 | AA15: =IFERROR(Z15*I15,"") | AB15: =IFERROR(U15+AA15+O15,"") | AG15: =AC15*3+AD15*4+AE15*5+AF15*6 -> 0 | AH15: =IFERROR(AG15*I15,"") | AJ15: =IF(H15=130,0.132335,IF(H15=100,0.0785,IF(H15=110,0.095,IF(H15=160,0.198005,"")))) | AK15: =IFERROR(P15*3*AJ15,"") | AL15: =IFERROR(Q15*4*AJ15,"") | AM15: =IFERROR(R15*5*AJ15,"") | AN15: =IFERROR(S15*6*AJ15,"") | AP15: 4 | AR15: =IFERROR(AP15*AQ15*AS16,0) -> 0 | AX15: =AT15*3+AU15*4+AV15*5+AW15*6 -> 0 | AY15: =AX15*I15 -> #VALUE!
B16: MIN | C16: =MIN(C4:C15) -> 0 | D16: =MIN(D4:D15) -> 0 | E16: =MIN(E4:E15) -> 0 | F16: =MIN(F4:F15) -> 0 | G16: =MIN(G4:G15) -> 0 | J16: =IF(J2="110 X 110",SUM(J4:J15),0) -> 0 | K16: =IF(J2="110 X 110",SUM(K4:K15),0) -> 0 | L16: =IF(J2="110 X 110",SUM(L4:L15),0) -> 0 | M16: =IF(J2="110 X 110",SUM(M4:M15),0) -> 0 | O16: =SUM(O4:O15) -> 0 | AP16: 3 | AR16: =IFERROR(AP16*AQ16*AS16,0) -> 0 | AS16: =IFERROR(AR17/((AP16*AQ16)+(AP15*AQ15)+(AP14*AQ14)+(AP13*AQ13)),0) -> 0
B17: MAX | C17: =MAX(C4:C16) -> 0 | D17: =MAX(D4:D16) -> 0 | E17: =MAX(E4:E16) -> 0 | F17: =MAX(F4:F16) -> 0 | G17: =MAX(G4:G16) -> 0 | H17: 130 | I17: =IF(H17=130,0.132335,IF(H17=100,0.0785,IF(H17=110,0.095,IF(H17=160,0.198005,"")))) -> 0.132335 | N17: =J17*3+K17*4+L17*5+M17*6 -> 0 | O17: =IFERROR(N17*I17,"") -> 0 | P17: =SUMIF(H4:H15,130,P4:P15) -> 0 | Q17: =SUMIF(H4:H15,130,Q4:Q15) -> 0 | R17: =SUMIF(H4:H15,130,R4:R15) -> 0 | S17: =SUMIF(H4:H15,130,S4:S15) -> 0 | V17: =SUMIF(H4:H15,130,V4:V15)+IF(J2="130 X 130",SUM(J4:J15),0) -> 0 | W17: =SUMIF(H4:H15,130,W4:W15)+IF(J2="130 X 130",SUM(K4:K15),0) -> 0 | X17: =SUMIF(H4:H15,130,X4:X15)+IF(J2="130 X 130",SUM(L4:L15),0) -> 0 | Y17: =SUMIF(H4:H15,130,Y4:Y15)+IF(J2="130 X 130",SUM(M4:M15),0) -> 0 | AC17: =SUMIF(H4:H15,130,AC4:AC15) -> 0 | AD17: =SUMIF(H4:H15,130,AD4:AD15) -> 0 | AE17: =SUMIF(H4:H15,130,AE4:AE15) -> 0 | AF17: =SUMIF(H4:H15,130,AF4:AF15) -> 0 | AK17: =SUM(AK4:AK16) -> 0 | AL17: =SUM(AL4:AL16) -> 0 | AM17: =SUM(AM4:AM16) -> 0 | AN17: =SUM(AN4:AN16) -> 0
A18: =COUNTA(B4:B15) -> 12 | H18: 160 | I18: =IF(H18=130,0.132335,IF(H18=100,0.0785,IF(H18=110,0.095,IF(H18=160,0.198005,"")))) -> 0.198005 | N18: =J18*3+K18*4+L18*5+M18*6 -> 0 | O18: =(IFERROR(N18*I18,""))+O17 -> 0 | P18: =SUMIF(H4:H15,160,P4:P15) -> 0 | Q18: =SUMIF(H4:H15,160,Q4:Q15) -> 0 | R18: =SUMIF(H4:H15,160,R4:R15) -> 0 | S18: =SUMIF(H4:H15,160,S4:S15) -> 0 | T18: ='Daily Stock'!I33 -> 0 | U18: =SUM(U4:U17) -> 0 | V18: =SUMIF(H4:H15,160,V4:V15)+IF(J2="160 X 160",SUM(J4:J15),0) -> 0 | W18: =SUMIF(H4:H15,160,W4:W15)+IF(J2="160 X 160",SUM(K4:K15),0) -> 0 | X18: =SUMIF(H4:H15,160,X4:X15)+IF(J2="160 X 160",SUM(L4:L15),0) -> 0 | Y18: =SUMIF(H4:H15,160,Y4:Y15)+IF(J2="160 X 160",SUM(M4:M15),0) -> 0 | AA18: =SUM(AA4:AA17) -> 0 | AB18: =SUM(AB4:AB17) -> 0 | AC18: =SUMIF(H4:H15,160,AC4:AC15) -> 0 | AD18: =SUMIF(H4:H15,160,AD4:AD15) -> 0 | AE18: =SUMIF(H4:H15,160,AE4:AE15) -> 0 | AF18: =SUMIF(H4:H15,160,AF4:AF15) -> 0 | AH18: =SUM(AH4:AH17) -> 0 | AR18: =AR9+AR17 -> 0
AK20: HEAT WISE TRANSFER | AP20: HOTOUT | AT20: F&L BYPASS | AX20: MTR | AY20: WEIGHT
AK21: 3MTR | AL21: 4MTR | AM21: 5MTR | AN21: 6MTR | AO21: 130 | AT21: 3M | AU21: 4M | AV21: 5M | AW21: 6M
AJ22: =IF(H22=130,0.132335,IF(H22=100,0.0785,IF(H22=110,0.095,IF(H22=160,0.198005,"")))) | AK22: =IFERROR(P22*3*AJ22,"") | AL22: =IFERROR(Q22*4*AJ22,"") | AM22: =IFERROR(R22*5*AJ22,"") | AN22: =IFERROR(S22*6*AJ22,"") | AX22: =AT22*3+AU22*4+AV22*5+AW22*6 -> 0 | AY22: =AX22*I22 -> 0
AJ23: =IF(H23=130,0.132335,IF(H23=100,0.0785,IF(H23=110,0.095,IF(H23=160,0.198005,"")))) | AK23: =IFERROR(P23*3*AJ23,"") | AL23: =IFERROR(Q23*4*AJ23,"") | AM23: =IFERROR(R23*5*AJ23,"") | AN23: =IFERROR(S23*6*AJ23,"") | AP23: 6 | AR23: =IFERROR(AP23*AQ23*AS26,0) -> 0 | AX23: =AT23*3+AU23*4+AV23*5+AW23*6 -> 0 | AY23: =AX23*I23 -> 0
AJ24: =IF(H24=130,0.132335,IF(H24=100,0.0785,IF(H24=110,0.095,IF(H24=160,0.198005,"")))) | AK24: =IFERROR(P24*3*AJ24,"") | AL24: =IFERROR(Q24*4*AJ24,"") | AM24: =IFERROR(R24*5*AJ24,"") | AN24: =IFERROR(S24*6*AJ24,"") | AP24: 5 | AR24: =IFERROR(AP24*AQ24*AS26,0) -> 0 | AX24: =AT24*3+AU24*4+AV24*5+AW24*6 -> 0 | AY24: =AX24*I24 -> 0
AJ25: =IF(H25=130,0.132335,IF(H25=100,0.0785,IF(H25=110,0.095,IF(H25=160,0.198005,"")))) | AK25: =IFERROR(P25*3*AJ25,"") | AL25: =IFERROR(Q25*4*AJ25,"") | AM25: =IFERROR(R25*5*AJ25,"") | AN25: =IFERROR(S25*6*AJ25,"") | AP25: 4 | AR25: =IFERROR(AP25*AQ25*AS26,0) -> 0 | AX25: =AT25*3+AU25*4+AV25*5+AW25*6 -> 0 | AY25: =AX25*I25 -> 0
AJ26: =IF(H26=130,0.132335,IF(H26=100,0.0785,IF(H26=110,0.095,IF(H26=160,0.198005,"")))) | AK26: =IFERROR(P26*3*AJ26,"") | AL26: =IFERROR(Q26*4*AJ26,"") | AM26: =IFERROR(R26*5*AJ26,"") | AN26: =IFERROR(S26*6*AJ26,"") | AP26: 3 | AR26: =IFERROR(AP26*AQ26*AS26,0) -> 0 | AS26: =IFERROR(AR27/((AP26*AQ26)+(AP25*AQ25)+(AP24*AQ24)+(AP23*AQ23)),0) -> 0 | AX26: =AT26*3+AU26*4+AV26*5+AW26*6 -> 0 | AY26: =AX26*I26 -> 0
AJ27: =IF(H27=130,0.132335,IF(H27=100,0.0785,IF(H27=110,0.095,IF(H27=160,0.198005,"")))) | AK27: =IFERROR(P27*3*AJ27,"") | AL27: =IFERROR(Q27*4*AJ27,"") | AM27: =IFERROR(R27*5*AJ27,"") | AN27: =IFERROR(S27*6*AJ27,"") | AX27: =AT27*3+AU27*4+AV27*5+AW27*6 -> 0 | AY27: =AX27*I27 -> 0
AJ28: =IF(H28=130,0.132335,IF(H28=100,0.0785,IF(H28=110,0.095,IF(H28=160,0.198005,"")))) | AK28: =IFERROR(P28*3*AJ28,"") | AL28: =IFERROR(Q28*4*AJ28,"") | AM28: =IFERROR(R28*5*AJ28,"") | AN28: =IFERROR(S28*6*AJ28,"") | AP28: HOTOUT | AX28: =AT28*3+AU28*4+AV28*5+AW28*6 -> 0 | AY28: =AX28*I28 -> 0
AJ29: =IF(H29=130,0.132335,IF(H29=100,0.0785,IF(H29=110,0.095,IF(H29=160,0.198005,"")))) | AK29: =IFERROR(P29*3*AJ29,"") | AL29: =IFERROR(Q29*4*AJ29,"") | AM29: =IFERROR(R29*5*AJ29,"") | AN29: =IFERROR(S29*6*AJ29,"") | AO29: 160 | AX29: =AT29*3+AU29*4+AV29*5+AW29*6 -> 0 | AY29: =AX29*I29 -> 0
AJ30: =IF(H30=130,0.132335,IF(H30=100,0.0785,IF(H30=110,0.095,IF(H30=160,0.198005,"")))) | AK30: =IFERROR(P30*3*AJ30,"") | AL30: =IFERROR(Q30*4*AJ30,"") | AM30: =IFERROR(R30*5*AJ30,"") | AN30: =IFERROR(S30*6*AJ30,"") | AX30: =AT30*3+AU30*4+AV30*5+AW30*6 -> 0 | AY30: =AX30*I30 -> 0
AJ31: =IF(H31=130,0.132335,IF(H31=100,0.0785,IF(H31=110,0.095,IF(H31=160,0.198005,"")))) | AK31: =IFERROR(P31*3*AJ31,"") | AL31: =IFERROR(Q31*4*AJ31,"") | AM31: =IFERROR(R31*5*AJ31,"") | AN31: =IFERROR(S31*6*AJ31,"") | AP31: 6 | AR31: =IFERROR(AP31*AQ31*AS34,0) -> 0 | AX31: =AT31*3+AU31*4+AV31*5+AW31*6 -> 0 | AY31: =AX31*I31 -> 0
AJ32: =IF(H32=130,0.132335,IF(H32=100,0.0785,IF(H32=110,0.095,IF(H32=160,0.198005,"")))) | AK32: =IFERROR(P32*3*AJ32,"") | AL32: =IFERROR(Q32*4*AJ32,"") | AM32: =IFERROR(R32*5*AJ32,"") | AN32: =IFERROR(S32*6*AJ32,"") | AP32: 5 | AR32: =IFERROR(AP32*AQ32*AS34,0) -> 0 | AX32: =AT32*3+AU32*4+AV32*5+AW32*6 -> 0 | AY32: =AX32*I32 -> 0
AJ33: =IF(H33=130,0.132335,IF(H33=100,0.0785,IF(H33=110,0.095,IF(H33=160,0.198005,"")))) | AK33: =IFERROR(P33*3*AJ33,"") | AL33: =IFERROR(Q33*4*AJ33,"") | AM33: =IFERROR(R33*5*AJ33,"") | AN33: =IFERROR(S33*6*AJ33,"") | AP33: 4 | AR33: =IFERROR(AP33*AQ33*AS34,0) -> 0 | AX33: =AT33*3+AU33*4+AV33*5+AW33*6 -> 0 | AY33: =AX33*I33 -> 0
AP34: 3 | AR34: =IFERROR(AP34*AQ34*AS34,0) -> 0 | AS34: =IFERROR(AR35/((AP34*AQ34)+(AP33*AQ33)+(AP32*AQ32)+(AP31*AQ31)),0) -> 0
AK35: =SUM(AK22:AK34) -> 0 | AL35: =SUM(AL22:AL34) -> 0 | AM35: =SUM(AM22:AM34) -> 0 | AN35: =SUM(AN22:AN34) -> 0
AR36: =AR27+AR35 -> 0
AK38: HEAT WISE TRANSFER | AP38: HOTOUT | AT38: F&L BYPASS | AX38: MTR | AY38: WEIGHT
AK39: 3MTR | AL39: 4MTR | AM39: 5MTR | AN39: 6MTR | AO39: 130 | AT39: 3M | AU39: 4M | AV39: 5M | AW39: 6M
AJ40: =IF(H40=130,0.132335,IF(H40=100,0.0785,IF(H40=110,0.095,IF(H40=160,0.198005,"")))) | AK40: =IFERROR(P40*3*AJ40,"") | AL40: =IFERROR(Q40*4*AJ40,"") | AM40: =IFERROR(R40*5*AJ40,"") | AN40: =IFERROR(S40*6*AJ40,"") | AX40: =AT40*3+AU40*4+AV40*5+AW40*6 -> 0 | AY40: =AX40*I40 -> 0
AJ41: =IF(H41=130,0.132335,IF(H41=100,0.0785,IF(H41=110,0.095,IF(H41=160,0.198005,"")))) | AK41: =IFERROR(P41*3*AJ41,"") | AL41: =IFERROR(Q41*4*AJ41,"") | AM41: =IFERROR(R41*5*AJ41,"") | AN41: =IFERROR(S41*6*AJ41,"") | AP41: 6 | AR41: =IFERROR(AP41*AQ41*AS44,0) -> 0 | AX41: =AT41*3+AU41*4+AV41*5+AW41*6 -> 0 | AY41: =AX41*I41 -> 0
AJ42: =IF(H42=130,0.132335,IF(H42=100,0.0785,IF(H42=110,0.095,IF(H42=160,0.198005,"")))) | AK42: =IFERROR(P42*3*AJ42,"") | AL42: =IFERROR(Q42*4*AJ42,"") | AM42: =IFERROR(R42*5*AJ42,"") | AN42: =IFERROR(S42*6*AJ42,"") | AP42: 5 | AR42: =IFERROR(AP42*AQ42*AS44,0) -> 0 | AX42: =AT42*3+AU42*4+AV42*5+AW42*6 -> 0 | AY42: =AX42*I42 -> 0
...

Sheet Strip Mill
A1: COLD BILLET CHARGING SMS TO STRIP MILL
A2: DATE | C2: Analysis Report | H2: SIZE | I2: 130 X 130 | M2: TOTAL MTR | N2: Quantity (MT) | S2: TOTAL MTR | T2: Quantity (MT) | U2: Total Prod. (in Heat)
B3: H.No. | C3: % C | D3: % Mn | E3: % Si | F3: % S | G3: % P | I3: 3M | J3: 4M | K3: 5M | L3: 6M | O3: 3 M | P3: 4M | Q3: 5M | R3: 6M
A4: =Prod.!A4 -> 46296 | B4: =Prod.!B4 -> 1.10.1 | C4: =Prod.!C4 -> 0 | D4: =Prod.!D4 -> 0 | E4: =Prod.!E4 -> 0 | F4: =Prod.!F4 -> 0 | G4: =Prod.!G4 -> 0 | H4: =IF(Prod.!H4=130,"130 × 130",IF(Prod.!H4=160,"160 × 160",IF(Prod.!H4=110,"110 × 110",""))) | I4: =Prod.!J4 -> 0 | J4: =Prod.!K4 -> 0 | K4: =Prod.!L4 -> 0 | L4: =Prod.!M4 -> 0 | M4: =Prod.!N4 -> 0 | N4: =Prod.!O4 -> 0 | O4: =Prod.!P4 -> 0 | P4: =Prod.!Q4 -> 0 | ... R4: =Prod.!S4 -> 0 | S4: =O4*3+P4*4+Q4*5+R4*6 -> 0 | T4: =Prod.!U4 | U4: =Prod.!AB4
B5: =Prod.!B5 -> 1.10.2 | C5: =Prod.!C5 -> 0 | D5: =Prod.!D5 -> 0 | E5: =Prod.!E5 -> 0 | F5: =Prod.!F5 -> 0 | G5: =Prod.!G5 -> 0 | H5: =IF(Prod.!H5=130,"130 × 130",IF(Prod.!H5=160,"160 × 160",IF(Prod.!H5=110,"110 × 110",""))) | I5: =Prod.!J5 -> 0 | J5: =Prod.!K5 -> 0 | K5: =Prod.!L5 -> 0 | L5: =Prod.!M5 -> 0 | M5: =Prod.!N5 -> 0 | N5: =Prod.!O5 -> 0 | O5: =Prod.!P5 -> 0 | P5: =Prod.!Q5 -> 0 | ... R5: =Prod.!S5 -> 0 | S5: =O5*3+P5*4+Q5*5+R5*6 -> 0 | T5: =Prod.!U5 | U5: =Prod.!AB5
B6: =Prod.!B6 -> 1.10.3 | C6: =Prod.!C6 -> 0 | D6: =Prod.!D6 -> 0 | E6: =Prod.!E6 -> 0 | F6: =Prod.!F6 -> 0 | G6: =Prod.!G6 -> 0 | H6: =IF(Prod.!H6=130,"130 × 130",IF(Prod.!H6=160,"160 × 160",IF(Prod.!H6=110,"110 × 110",""))) | I6: =Prod.!J6 -> 0 | J6: =Prod.!K6 -> 0 | K6: =Prod.!L6 -> 0 | L6: =Prod.!M6 -> 0 | M6: =Prod.!N6 -> 0 | N6: =Prod.!O6 -> 0 | O6: =Prod.!P6 -> 0 | P6: =Prod.!Q6 -> 0 | ... R6: =Prod.!S6 -> 0 | S6: =O6*3+P6*4+Q6*5+R6*6 -> 0 | T6: =Prod.!U6 | U6: =Prod.!AB6
B7: =Prod.!B7 -> 1.10.4 | C7: =Prod.!C7 -> 0 | D7: =Prod.!D7 -> 0 | E7: =Prod.!E7 -> 0 | F7: =Prod.!F7 -> 0 | G7: =Prod.!G7 -> 0 | H7: =IF(Prod.!H7=130,"130 × 130",IF(Prod.!H7=160,"160 × 160",IF(Prod.!H7=110,"110 × 110",""))) | I7: =Prod.!J7 -> 0 | J7: =Prod.!K7 -> 0 | K7: =Prod.!L7 -> 0 | L7: =Prod.!M7 -> 0 | M7: =Prod.!N7 -> 0 | N7: =Prod.!O7 -> 0 | O7: =Prod.!P7 -> 0 | P7: =Prod.!Q7 -> 0 | ... R7: =Prod.!S7 -> 0 | S7: =O7*3+P7*4+Q7*5+R7*6 -> 0 | T7: =Prod.!U7 | U7: =Prod.!AB7
B8: =Prod.!B8 -> 1.10.5 | C8: =Prod.!C8 -> 0 | D8: =Prod.!D8 -> 0 | E8: =Prod.!E8 -> 0 | F8: =Prod.!F8 -> 0 | G8: =Prod.!G8 -> 0 | H8: =IF(Prod.!H8=130,"130 × 130",IF(Prod.!H8=160,"160 × 160",IF(Prod.!H8=110,"110 × 110",""))) | I8: =Prod.!J8 -> 0 | J8: =Prod.!K8 -> 0 | K8: =Prod.!L8 -> 0 | L8: =Prod.!M8 -> 0 | M8: =Prod.!N8 -> 0 | N8: =Prod.!O8 -> 0 | O8: =Prod.!P8 -> 0 | P8: =Prod.!Q8 -> 0 | ... R8: =Prod.!S8 -> 0 | S8: =O8*3+P8*4+Q8*5+R8*6 -> 0 | T8: =Prod.!U8 | U8: =Prod.!AB8
B9: =Prod.!B9 -> 1.10.6 | C9: =Prod.!C9 -> 0 | D9: =Prod.!D9 -> 0 | E9: =Prod.!E9 -> 0 | F9: =Prod.!F9 -> 0 | G9: =Prod.!G9 -> 0 | H9: =IF(Prod.!H9=130,"130 × 130",IF(Prod.!H9=160,"160 × 160",IF(Prod.!H9=110,"110 × 110",""))) | I9: =Prod.!J9 -> 0 | J9: =Prod.!K9 -> 0 | K9: =Prod.!L9 -> 0 | L9: =Prod.!M9 -> 0 | M9: =Prod.!N9 -> 0 | N9: =Prod.!O9 -> 0 | O9: =Prod.!P9 -> 0 | P9: =Prod.!Q9 -> 0 | ... R9: =Prod.!S9 -> 0 | S9: =O9*3+P9*4+Q9*5+R9*6 -> 0 | T9: =Prod.!U9 | U9: =Prod.!AB9
B10: =Prod.!B10 -> 1.10.7 | C10: =Prod.!C10 -> 0 | D10: =Prod.!D10 -> 0 | E10: =Prod.!E10 -> 0 | F10: =Prod.!F10 -> 0 | G10: =Prod.!G10 -> 0 | H10: =IF(Prod.!H10=130,"130 × 130",IF(Prod.!H10=160,"160 × 160",IF(Prod.!H10=110,"110 × 110",""))) | I10: =Prod.!J10 -> 0 | J10: =Prod.!K10 -> 0 | K10: =Prod.!L10 -> 0 | L10: =Prod.!M10 -> 0 | M10: =Prod.!N10 -> 0 | N10: =Prod.!O10 -> 0 | O10: =Prod.!P10 -> 0 | P10: =Prod.!Q10 -> 0 | ... R10: =Prod.!S10 -> 0 | S10: =O10*3+P10*4+Q10*5+R10*6 -> 0 | T10: =Prod.!U10 | U10: =Prod.!AB10
B11: =Prod.!B11 -> 1.10.8 | C11: =Prod.!C11 -> 0 | D11: =Prod.!D11 -> 0 | E11: =Prod.!E11 -> 0 | F11: =Prod.!F11 -> 0 | G11: =Prod.!G11 -> 0 | H11: =IF(Prod.!H11=130,"130 × 130",IF(Prod.!H11=160,"160 × 160",IF(Prod.!H11=110,"110 × 110",""))) | I11: =Prod.!J11 -> 0 | J11: =Prod.!K11 -> 0 | K11: =Prod.!L11 -> 0 | L11: =Prod.!M11 -> 0 | M11: =Prod.!N11 -> 0 | N11: =Prod.!O11 -> 0 | O11: =Prod.!P11 -> 0 | P11: =Prod.!Q11 -> 0 | ... R11: =Prod.!S11 -> 0 | S11: =O11*3+P11*4+Q11*5+R11*6 -> 0 | T11: =Prod.!U11 | U11: =Prod.!AB11
B12: =Prod.!B12 -> 1.10.9 | C12: =Prod.!C12 -> 0 | D12: =Prod.!D12 -> 0 | E12: =Prod.!E12 -> 0 | F12: =Prod.!F12 -> 0 | G12: =Prod.!G12 -> 0 | H12: =IF(Prod.!H12=130,"130 × 130",IF(Prod.!H12=160,"160 × 160",IF(Prod.!H12=110,"110 × 110",""))) | I12: =Prod.!J12 -> 0 | J12: =Prod.!K12 -> 0 | K12: =Prod.!L12 -> 0 | L12: =Prod.!M12 -> 0 | M12: =Prod.!N12 -> 0 | N12: =Prod.!O12 -> 0 | O12: =Prod.!P12 -> 0 | P12: =Prod.!Q12 -> 0 | ... R12: =Prod.!S12 -> 0 | S12: =O12*3+P12*4+Q12*5+R12*6 -> 0 | T12: =Prod.!U12 | U12: =Prod.!AB12
B13: =Prod.!B13 -> 1.10.10 | C13: =Prod.!C13 -> 0 | D13: =Prod.!D13 -> 0 | E13: =Prod.!E13 -> 0 | F13: =Prod.!F13 -> 0 | G13: =Prod.!G13 -> 0 | H13: =IF(Prod.!H13=130,"130 × 130",IF(Prod.!H13=160,"160 × 160",IF(Prod.!H13=110,"110 × 110",""))) | I13: =Prod.!J13 -> 0 | J13: =Prod.!K13 -> 0 | K13: =Prod.!L13 -> 0 | L13: =Prod.!M13 -> 0 | M13: =Prod.!N13 -> 0 | N13: =Prod.!O13 -> 0 | O13: =Prod.!P13 -> 0 | P13: =Prod.!Q13 -> 0 | ... R13: =Prod.!S13 -> 0 | S13: =O13*3+P13*4+Q13*5+R13*6 -> 0 | T13: =Prod.!U13 | U13: =Prod.!AB13
B14: =Prod.!B14 -> 1.10.11 | C14: =Prod.!C14 -> 0 | D14: =Prod.!D14 -> 0 | E14: =Prod.!E14 -> 0 | F14: =Prod.!F14 -> 0 | G14: =Prod.!G14 -> 0 | H14: =IF(Prod.!H14=130,"130 × 130",IF(Prod.!H14=160,"160 × 160",IF(Prod.!H14=110,"110 × 110",""))) | I14: =Prod.!J14 -> 0 | J14: =Prod.!K14 -> 0 | K14: =Prod.!L14 -> 0 | L14: =Prod.!M14 -> 0 | M14: =Prod.!N14 -> 0 | N14: =Prod.!O14 -> 0 | O14: =Prod.!P14 -> 0 | P14: =Prod.!Q14 -> 0 | ... R14: =Prod.!S14 -> 0 | S14: =O14*3+P14*4+Q14*5+R14*6 -> 0 | T14: =Prod.!U14 | U14: =Prod.!AB14
B15: =Prod.!B15 -> 1.10.12 | C15: =Prod.!C15 -> 0 | D15: =Prod.!D15 -> 0 | E15: =Prod.!E15 -> 0 | F15: =Prod.!F15 -> 0 | G15: =Prod.!G15 -> 0 | H15: =IF(Prod.!H15=130,"130 × 130",IF(Prod.!H15=160,"160 × 160",IF(Prod.!H15=110,"110 × 110",""))) | I15: =Prod.!J15 -> 0 | J15: =Prod.!K15 -> 0 | K15: =Prod.!L15 -> 0 | L15: =Prod.!M15 -> 0 | M15: =Prod.!N15 -> 0 | N15: =Prod.!O15 -> 0 | O15: =Prod.!P15 -> 0 | P15: =Prod.!Q15 -> 0 | ... R15: =Prod.!S15 -> 0 | S15: =O15*3+P15*4+Q15*5+R15*6 -> 0 | T15: =Prod.!U15 | U15: =Prod.!AB15
N16: =SUM(N4:N15) -> 0
B17: RHF | H17: 160 × 160 | I17: =Prod.!J18 -> 0 | J17: =Prod.!K18 -> 0 | K17: =Prod.!L18 -> 0 | L17: =Prod.!M18 -> 0 | N17: =Prod.!O18-N18 -> 0
H18: 130 × 130 | I18: =Prod.!J17 -> 0 | J18: =Prod.!K17 -> 0 | K18: =Prod.!L17 -> 0 | L18: =Prod.!M17 -> 0 | N18: =Prod.!O17 -> 0 | O18: =SUM(O4:O16) -> 0 | P18: =SUM(P4:P16) -> 0 | Q18: =SUM(Q4:Q16) -> 0 | R18: =SUM(R4:R16) -> 0 | S18: =SUM(S4:S17) -> 0 | T18: =SUM(T4:T17) -> 0 | U18: =SUM(U4:U17) -> 0

Sheet Monthly Prod
A1: Date | B1: =SUM(B3:B33) -> 0 | C1: =SUM(C3:C33) -> 0 | D1: =SUM(D3:D33) -> 0 | E1: =SUM(E3:E33) -> 0 | F1: =SUM(F3:F33) -> 0 | G1: =SUM(G3:G33) -> 0 | H1: =SUM(H3:H33) -> 0 | I1: =SUM(I3:I33) -> 12 | Q1: =B1/(COUNTA(B3:B33)) -> 0 | R1: =B1/I1 -> 0
B2: Total Prod | C2: Hot Charging | D2: RHF | E2: Bypass | F2: Hotout Net Weight | G2: Hotout Calculated Weight | H2: Dispatch | I2: HEAT | J2: OPENING | K2: M2M | L2: CONSUMPTION IN STRIP MILL | M2: COIL | N2: MISSROLL | O2: MILL SCALE | P2: TOTAL | Q2: MT/DAY | R2: MT/HEAT | S2: =Q1*30 -> 0 | T2: =S2-10750 -> -10750 | U2: =T2*350 -> -3762500 | V2: =U2*18% -> -677250 | W2: =V2/18 -> -37625
A3: 46296 | B3: =IF(INDIRECT("Prod.!AB" & (ROW()-3)*18+18)<>0, INDIRECT("Prod.!AB" & (ROW()-3)*18+18), 0) -> 0 | C3: =IF(INDIRECT("Prod.!U" & (ROW()-3)*18+18)<>0, INDIRECT("Prod.!U" & (ROW()-3)*18+18), 0) -> 0 | D3: =IF(INDIRECT("Prod.!O" & (ROW()-3)*18+18)<>0, INDIRECT("Prod.!O" & (ROW()-3)*18+18), 0) -> 0 | E3: =IF(INDIRECT("Prod.!AA" & (ROW()-3)*18+18)<>0, INDIRECT("Prod.!AA" & (ROW()-3)*18+18), 0) -> 0 | F3: =IF(INDIRECT("Prod.!AR" & (ROW()-3)*18+18)<>0, INDIRECT("Prod.!AR" & (ROW()-3)*18+18), 0) -> 0 | G3: =IF(INDIRECT("Prod.!AH" & (ROW()-3)*18+18)<>0, INDIRECT("Prod.!AH" & (ROW()-3)*18+18), 0) -> 0 | H3: =IF(INDIRECT("Prod.!T" & (ROW()-3)*18+18)<>0, INDIRECT("Prod.!T" & (ROW()-3)*18+18), 0) -> 0 | I3: =IF(INDIRECT("Prod.!A" & (ROW()-3)*18+18)<>0, INDIRECT("Prod.!A" & (ROW()-3)*18+18), 0) -> 12 | J3: 109.811 | K3: =C3+D3-F3 -> 0 | L3: 179.843 | M3: 177.145 | O3: 2.698 | P3: =M3+N3+O3 -> 179.843
A4: 46297 | J4: -2.204 | K4: =C4+D4-F4 -> 0 | L4: 172.035 | M4: 169.454 | O4: 2.581 | P4: =M4+N4+O4 -> 172.035 | R4: STOCK
A5: 46298 | K5: =C5+D5-F5 -> 0 | L5: 239.128 | M5: 228.906 | N5: 6.352 | O5: 3.87 | P5: =M5+N5+O5 -> 239.128 | R5: =ROUND('Daily Stock'!Q15+B1-C1-D1+F1-H1,3) -> 662.854
A6: 46299 | K6: =C6+D6-F6 -> 0 | L6: 453.248 | M6: 429.531 | N6: 15.748 | O6: 7.969 | P6: =M6+N6+O6 -> 453.248 | Q6: OFFGRADE HEAT
A7: 46300 | K7: =C7+D7-F7 -> 0 | L7: 105.867 | M7: 97.648 | N7: 6.483 | O7: 1.736 | P7: =M7+N7+O7 -> 105.867 | Q7: =COUNTIFS(Prod.!B:B, ">0.12", Prod.!A:A, "<>MAX") -> 0
A8: 46301 | K8: =C8+D8-F8 -> 0 | L8: 473.23 | M8: 456.519 | N8: 8.337 | O8: 8.374 | P8: =M8+N8+O8 -> 473.23 | R8: =B2 -> Total Prod | S8: =B1 -> 0
A9: 46302 | K9: =C9+D9-F9 -> 0 | L9: 375.434 | M9: 365.527 | N9: 3.308 | O9: 6.599 | P9: =M9+N9+O9 -> 375.434 | Q9: =C1+D1-F1 -> 0 | R9: =C2 -> Hot Charging | S9: =C1 -> 0
A10: 46303 | K10: =C10+D10-F10 -> 0 | L10: 404.036 | M10: 424.122 | N10: 7.41 | O10: 7.819 | P10: =M10+N10+O10 -> 439.351 | R10: =D2 -> RHF | S10: =D1 -> 0
A11: 46304 | J11: TOTAL | K11: =SUM(K3:K10) -> 0 | L11: =SUM(L3:L10) -> 2402.821 | M11: =SUM(M3:M10) -> 2348.852 | N11: =SUM(N3:N10) -> 47.638 | O11: =SUM(O3:O10) -> 41.646 | P11: =SUM(P3:P10) -> 2438.136 | R11: =E2 -> Bypass | S11: =E1 -> 0
A12: 46305 | R12: =F2 -> Hotout Net Weight | S12: =F1 -> 0
A13: 46306 | R13: =H2 -> Dispatch | S13: =H1 -> 0
A14: 46307
A15: 46308
A16: 46309
A17: 46310
A18: 46311
A19: 46312
A20: 46313
A21: 46314
A22: 46315
A23: 46316
A24: 46317
A25: 46318
... A33: 46326

Sheet Billet Stock Format
A1: Calculation of physical verification of finished goods
A2: =R6 -> As on 01.10.2026
A4: Sl No. | B4: Particular | C4: Size | D4: Length (In Mtr) | E4: As per physical verification | H4: Quantity as per ERP (In Mt) | I4: Remarks
E5: No of Pieces/ Meter | F5: Standard Weight (Mt / piece) | G5: Quantity (In Mt)
A6: 1 | B6: MS BILLET | C6: 100*100 | D6: 6 | E6: 0 | F6: =D6*0.078 -> 0.468 | G6: =E6*F6 -> 0 | H6: 0 | K6: 110 X 6 | L6: ='Daily Stock'!Q22 -> 0 | R6: As on 01.10.2026
A7: 2 | B7: MS BILLET | C7: 100*100 | D7: short length | E7: 0 | F7: 0.078 | G7: =E7*F7 -> 0 | H7: 0 | K7: 110 X 5.25 | L7: ='Daily Stock'!Q23 -> 0 | R7: Size | T7: ERP STOCK | U7: Dispatchable | V7: Remark
A8: 3 | B8: SWADESH | C8: 160*160 | D8: 3 | E8: 1 | F8: =G8/E8 -> 0.58 | G8: 0.58 | H8: 0 | I8: =SUM(H8:H10) -> 6.911 | K8: 110 X R | L8: ='Daily Stock'!Q24 -> 6.911 | R8: 110x110 | S8: 6 | T8: =U8 -> 0 | U8: =H8 -> 0 | V8: Normal
A9: 4 | B9: MS BILLET | C9: 110*110 | D9: 5.25 | E9: =H9/F9 -> 0 | F9: =D9*0.095 -> 0.49875 | G9: =E9*F9 -> 0 | K9: 130 X 6 | L9: ='Daily Stock'!Q25 -> 74.87 | U9: 0
A10: 5 | B10: MS BILLET | C10: 110*110 | D10: short length | E10: =H10/F10 -> 72.747368 | F10: 0.095 | G10: =E10*F10 -> 6.911 | H10: =L8 -> 6.911 | K10: 130 X 5 | L10: ='Daily Stock'!Q26 -> 33.084 | S10: Random | T10: 0 | U10: 0
A11: 6 | B11: MS BILLET | C11: 130*130 | D11: 3 | E11: =H11/F11 -> 308.00116 | F11: =0.132335*D11 -> 0.397005 | G11: =E11*F11 -> 122.278 | H11: =L12 -> 122.278 | I11: =SUM(H11:H15) -> 263.326 | K11: 130 X 4 | L11: ='Daily Stock'!Q27 -> 33.094 | R11: 130x130 | S11: 6 | T11: =U11 -> 74.87 | U11: =H12 -> 74.87 | V11: Normal
A12: 7 | B12: MS BILLET | C12: 130*130 | D12: 6 | E12: =H12/F12 -> 94.293523 | F12: =0.132335*D12 -> 0.79401 | G12: =E12*F12 -> 74.87 | H12: =L9 -> 74.87 | K12: 130 X 3 | L12: ='Daily Stock'!Q28 -> 122.278
A13: 8 | B13: MS BILLET | C13: 130*130 | D13: 5 | E13: =H13/F13 -> 50.000378 | F13: =0.132335*D13 -> 0.661675 | G13: =E13*F13 -> 33.084 | H13: =L10 -> 33.084 | K13: 160 X R | L13: ='Daily Stock'!Q29 -> 0 | S13: 4 | T13: =U13 -> 33.094 | U13: =G14 -> 33.094 | V13: Normal | X13: As on 01.10.2026
A14: 9 | B14: MS BILLET | C14: 130*130 | D14: 4 | E14: =H14/F14 -> 62.519364 | F14: =0.132335*D14 -> 0.52934 | G14: =E14*F14 -> 33.094 | H14: =L11 -> 33.094 | K14: 160 X 5 | L14: ='Daily Stock'!Q30 -> 50.54 | X14: Current Stock | Y14: 110 x 110 | Z14: 130 x 130 | AA14: 160 x 160
A15: 10 | B15: MS BILLET | C15: 130*130 | D15: short length | E15: =H15/F15 -> 0 | F15: =0.132335 -> 0.132335 | G15: =E15*F15 -> 0 | H15: 0 | K15: 160 X 4 | L15: ='Daily Stock'!Q31 -> 82.29 | S15: 3 | T15: =U15 -> 122.278 | U15: =G11 -> 122.278 | V15: Normal | X15: Internal Billets | Y15: =I8 -> 6.911 | Z15: =I11 -> 263.326 | AA15: =I18 -> 392.617
A16: 11 | B16: AKASH | C16: 130*130 | D16: 6 | E16: =45+43+3-88 -> 3 | F16: =G16/E16 -> 0.78333333 | G16: =35.99+34.37+2.35-70.36 -> 2.35 | H16: 0 | I16: . | K16: 160 X 3 | L16: ='Daily Stock'!Q32 -> 259.787 | X16: Inward Billets | Z16: =G17+G16 -> 19.84 | AA16: =G22+G21+G23+G8 -> 1665.8
A17: 12 | B17: SHYAM | C17: 130x130 | D17: 6 | E17: =265+2+180+264+94+93+7-80-182-59-149-313-93-7 -> 22 | F17: 0.795 | G17: =E17*F17 -> 17.49 | H17: 0 | S17: 5 | T17: =U17 -> 33.084 | U17: =G13 -> 33.084 | V17: Normal
A18: 13 | B18: MS BILLET | C18: 160*160 | D18: 3 | E18: =H18/F18 -> 437.34081 | F18: =0.198005*D18 -> 0.594015 | G18: =E18*F18 -> 259.787 | H18: =L16 -> 259.787 | I18: =SUM(H18:H23) -> 392.617 | K18: ='Monthly Prod'!B3 -> 0 | L18: ='Monthly Prod'!C3 -> 0 | M18: ='Monthly Prod'!D3 -> 0 | N18: ='Monthly Prod'!E3 -> 0 | O18: ='Monthly Prod'!F3 -> 0 | P18: ='Monthly Prod'!H3 -> 0 | Q18: DAILY | S18: Random | T18: =U18 -> 0 | U18: =G15 -> 0 | V18: Normal | X18: Total- | Y18: =SUM(Y15:Y17) -> 6.911 | Z18: =SUM(Z15:Z17) -> 283.166 | AA18: =SUM(AA15:AA17) -> 2058.417
A19: 14 | B19: MS BILLET | C19: 160*160 | D19: 4 | E19: =H19/F19 -> 103.89889 | F19: =0.198005*D19 -> 0.79202 | G19: =E19*F19 -> 82.29 | H19: =L15 -> 82.29 | K19: TP | L19: HC | M19: RHF | N19: BP | O19: HO | P19: DISP | R19: 160x160 | S19: 6 | T19: 0 | U19: 0
A20: 15 | B20: MS BILLET | C20: 160*160 | D20: 5 | E20: =H20/F20 -> 51.049216 | F20: =0.198005*D20 -> 0.990025 | G20: =E20*F20 -> 50.54 | H20: =L14 -> 50.54 | K20: =SUM('Monthly Prod'!B3) -> 0 | L20: =SUM('Monthly Prod'!C3) -> 0 | M20: =SUM('Monthly Prod'!D3) -> 0 | N20: =SUM('Monthly Prod'!E3) -> 0 | O20: =SUM('Monthly Prod'!F3) -> 0 | P20: =SUM('Monthly Prod'!H3) -> 0 | Q20: MONTHLY | S20: 4.8 | X20: Pending As Per PO | Z20: 130 x 130 | AA20: 160 x 160
A21: 16 | B21: AR ISPAT | C21: 160*160 | D21: 6 | E21: =67+117+251+80+45 -> 560 | F21: =G21/E21 -> 1.2022321 | G21: =80.75+140.64+301.61+34.93+80.59+34.73 -> 673.25 | H21: 0 | S21: 4 | T21: =U21 -> 82.29 | U21: =G19 -> 82.29 | V21: Normal | Y21: Akash Sales | Z21: =400+10-69.71-140.17-34.22-65.36-35.99-34.37 -> 30.18 | AA21: -
A22: 17 | B22: MASHIVA | C22: 160*160 | D22: 6 | E22: =340+84+318+100+134+6+92+133+25+307+82+0.5+29+29-220-120-85-417-140 -> 697.5 | F22: =G22/E22 -> 1.2017061 | G22: =109.37+159.53+29.74+370.26+99.63+34.5+0.58+34.58 -> 838.19 | H22: 0 | Y22: VRKP | Z22: 30.79
A23: 18 | B23: SHYAM | C23: 160*160 | D23: 6 | E23: =62+66 -> 128 | F23: =G23/E23 -> 1.2014063 | G23: =74.38+79.4 -> 153.78 | H23: =L13 -> 0 | S23: 3 | T23: =U23 -> 259.787 | U23: =G18 -> 259.787 | V23: Normal | Y23: SHYAM | Z23: 0 | AA23: =320-74.38-79.4 -> 166.22
A24: Total | G24: =SUM(G6:G23) -> 2348.494 | H24: =SUM(H6:H23) -> 662.854 | I24: =H24-G24 -> -1685.64 | Y24: AR Ispat | AA24: =1000-80.75-140.64-301.61-34.93-80.59-34.73 -> 326.75
A25: Opening Stock | B25: Hot Out receive | C25: Production | D25: Hot Charging | E25: Cold Charging | F25: Dispatch | G25: Closing Stock | H25: VRKP Cold Charging Pcs | I25: Hot Out received | S25: 5 | T25: =U25 -> 50.54 | U25: =G20 -> 50.54 | V25: Normal | Y25: Mashiva | AA25: =400.91+500-370.26-99.63-69.08-80.1-109.37-159.53-29.74 -> -16.8
S26: 4.8 | T26: 0 | U26: 0 | V26: Normal | X26: HOLD DETAILS | Z26: TEST PENDING
A27: 662.854 | B27: =O18 -> 0 | C27: =K18 -> 0 | D27: =L18 -> 0 | E27: =M18 -> 0 | F27: =P18 -> 0 | G27: =A27+B27+C27-D27-E27-F27 -> 662.854 | S27: Random | T27: 0 | U27: 0 | V27: Normal | X27: 160 x 160 x 6MTR
D28: =D27+E27+F27 -> 0 | S28: 5 | T28: 0 | U28: 0 | X28: AR Ispat | Y28: =523+34.93+80.59+34.73 -> 673.25
A29: Monthly production | T29: =SUM(T8:T28) -> 655.943 | U29: =SUM(U8:U28) -> 655.943 | X29: Mashiva | Y29: =668.9+49.82+34.5+34.58 -> 787.8
A30: Opening stock of September | B30: Hot Out Receive | C30: Production | D30: Total Hotcharging | E30: Cold Charging | F30: dispatch | G30: closing
A31: 662.854 | B31: =O20 -> 0 | C31: =K20 -> 0 | D31: =L20 -> 0 | E31: =M20 -> 0 | F31: =P20 -> 0 | G31: =A31+B31+C31-D31-E31-F31+H31 -> 662.854
D32: =D31+E31+F31 -> 0
K38: 110 X 6 | L38: ='Daily Stock'!Q40 -> 0 | R38: As on 02.10.2026
K39: 110 X 5.25 | L39: ='Daily Stock'!Q41 -> 0 | R39: Size | T39: ERP STOCK | U39: Dispatchable | V39: Remark
K40: 110 X R | L40: ='Daily Stock'!Q42 -> 0 | R40: 110x110 | S40: 6 | T40: =U40 -> 0 | U40: =H40 -> 0 | V40: Normal
K41: 130 X 6 | L41: ='Daily Stock'!Q43 -> 0 | U41: 0
K42: 130 X 5 | L42: ='Daily Stock'!Q44 -> 0 | S42: Random | T42: 0 | U42: 0
K43: 130 X 4 | L43: ='Daily Stock'!Q45 -> 0 | R43: 130x130 | S43: 6 | T43: =U43 -> 0 | U43: =H44 -> 0 | V43: Normal
K44: 130 X 3 | L44: ='Daily Stock'!Q46 -> 0
K45: 160 X R | L45: ='Daily Stock'!Q47 -> 0 | S45: 4 | T45: =U45 -> 0 | U45: =G46 -> 0 | V45: Normal
K46: 160 X 5 | L46: ='Daily Stock'!Q48 -> 0
...

Sheet Cumulative Stock
B1: =NOW() -> 46309.519
B2: Supplier
B3: Section | C3: Quality Status | D3: MIPPL | E3: AR ISPAT | F3: MAHASHIVA | G3: SHYAM | H3: AKASH | I3: SWADESH | J3: Total
B4: 110 | C4: OK | D4: 6.911 | J4: =SUM(D4:H4) -> 6.911
B5: 130 | C5: OK | D5: =D7-D6 -> 0 | E5: =E7-E6 -> 0 | F5: =F7-F6 -> 0 | G5: =G7-G6 -> 0 | H5: =H7-H6 -> 0 | I5: =I7-I6 -> 0.58 | J5: =SUM(D5:I5) -> 0.58
C6: HOLD | D6: 0 | E6: 0 | F6: 0 | G6: =G7 -> 0 | J6: =SUM(D6:I6) -> 0
C7: TOTAL | D7: =IFERROR(SUMIFS(INDEX('Billet Stock Format'!$G:$G,MATCH("As on "&TEXT($B$1,"dd.mm.yyyy"),'Billet Stock Format'!$R:$R,0)+5):INDEX('Billet Stock Format'!$G:$G,MATCH("As on "&TEXT($B$1,"dd.mm.yyyy"),'Billet Stock Format'!$R:$R,0)+17),INDEX('Billet Stock Format'!$B:$B,MATCH("As on "&TEXT($B$1,"dd.mm.yyyy"),'Billet Stock Format'!$R:$R,0)+5):INDEX('Billet Stock Format'!$B:$B,MATCH("As on "&TEXT($B$1,"dd.mm.yyyy"),'Billet Stock Format'!$R:$R,0)+17),IF(D3="MIPPL","MS BILLET",IF(D3="MAHASHIVA","MASHIVA",D3)),INDEX('Billet Stock Format'!$C:$C,MATCH("As on "&TEXT($B$1,"dd.mm.yyyy"),'Billet Stock Format'!$R:$R,0)+5):INDEX('Billet Stock Format'!$C:$C,MATCH("As on "&TEXT($B$1,"dd.mm.yyyy"),'Billet Stock Format'!$R:$R,0)+17),$B5&"*"),0) -> 0 | E7: =IFERROR(SUMIFS(INDEX('Billet Stock Format'!$G:$G,MATCH("As on "&TEXT($B$1,"dd.mm.yyyy"),'Billet Stock Format'!$R:$R,0)+5):INDEX('Billet Stock Format'!$G:$G,MATCH("As on "&TEXT($B$1,"dd.mm.yyyy"),'Billet Stock Format'!$R:$R,0)+17),INDEX('Billet Stock Format'!$B:$B,MATCH("As on "&TEXT($B$1,"dd.mm.yyyy"),'Billet Stock Format'!$R:$R,0)+5):INDEX('Billet Stock Format'!$B:$B,MATCH("As on "&TEXT($B$1,"dd.mm.yyyy"),'Billet Stock Format'!$R:$R,0)+17),IF(E3="MIPPL","MS BILLET",IF(E3="MAHASHIVA","MASHIVA",E3)),INDEX('Billet Stock Format'!$C:$C,MATCH("As on "&TEXT($B$1,"dd.mm.yyyy"),'Billet Stock Format'!$R:$R,0)+5):INDEX('Billet Stock Format'!$C:$C,MATCH("As on "&TEXT($B$1,"dd.mm.yyyy"),'Billet Stock Format'!$R:$R,0)+17),$B5&"*"),0) -> 0 | F7: =IFERROR(SUMIFS(INDEX('Billet Stock Format'!$G:$G,MATCH("As on "&TEXT($B$1,"dd.mm.yyyy"),'Billet Stock Format'!$R:$R,0)+5):INDEX('Billet Stock Format'!$G:$G,MATCH("As on "&TEXT($B$1,"dd.mm.yyyy"),'Billet Stock Format'!$R:$R,0)+17),INDEX('Billet Stock Format'!$B:$B,MATCH("As on "&TEXT($B$1,"dd.mm.yyyy"),'Billet Stock Format'!$R:$R,0)+5):INDEX('Billet Stock Format'!$B:$B,MATCH("As on "&TEXT($B$1,"dd.mm.yyyy"),'Billet Stock Format'!$R:$R,0)+17),IF(F3="MIPPL","MS BILLET",IF(F3="MAHASHIVA","MASHIVA",F3)),INDEX('Billet Stock Format'!$C:$C,MATCH("As on "&TEXT($B$1,"dd.mm.yyyy"),'Billet Stock Format'!$R:$R,0)+5):INDEX('Billet Stock Format'!$C:$C,MATCH("As on "&TEXT($B$1,"dd.mm.yyyy"),'Billet Stock Format'!$R:$R,0)+17),$B5&"*"),0) -> 0 | G7: =IFERROR(SUMIFS(INDEX('Billet Stock Format'!$G:$G,MATCH("As on "&TEXT($B$1,"dd.mm.yyyy"),'Billet Stock Format'!$R:$R,0)+5):INDEX('Billet Stock Format'!$G:$G,MATCH("As on "&TEXT($B$1,"dd.mm.yyyy"),'Billet Stock Format'!$R:$R,0)+17),INDEX('Billet Stock Format'!$B:$B,MATCH("As on "&TEXT($B$1,"dd.mm.yyyy"),'Billet Stock Format'!$R:$R,0)+5):INDEX('Billet Stock Format'!$B:$B,MATCH("As on "&TEXT($B$1,"dd.mm.yyyy"),'Billet Stock Format'!$R:$R,0)+17),IF(G3="MIPPL","MS BILLET",IF(G3="MAHASHIVA","MASHIVA",G3)),INDEX('Billet Stock Format'!$C:$C,MATCH("As on "&TEXT($B$1,"dd.mm.yyyy"),'Billet Stock Format'!$R:$R,0)+5):INDEX('Billet Stock Format'!$C:$C,MATCH("As on "&TEXT($B$1,"dd.mm.yyyy"),'Billet Stock Format'!$R:$R,0)+17),$B5&"*"),0) -> 0 | H7: =IFERROR(SUMIFS(INDEX('Billet Stock Format'!$G:$G,MATCH("As on "&TEXT($B$1,"dd.mm.yyyy"),'Billet Stock Format'!$R:$R,0)+5):INDEX('Billet Stock Format'!$G:$G,MATCH("As on "&TEXT($B$1,"dd.mm.yyyy"),'Billet Stock Format'!$R:$R,0)+17),INDEX('Billet Stock Format'!$B:$B,MATCH("As on "&TEXT($B$1,"dd.mm.yyyy"),'Billet Stock Format'!$R:$R,0)+5):INDEX('Billet Stock Format'!$B:$B,MATCH("As on "&TEXT($B$1,"dd.mm.yyyy"),'Billet Stock Format'!$R:$R,0)+17),IF(H3="MIPPL","MS BILLET",IF(H3="MAHASHIVA","MASHIVA",H3)),INDEX('Billet Stock Format'!$C:$C,MATCH("As on "&TEXT($B$1,"dd.mm.yyyy"),'Billet Stock Format'!$R:$R,0)+5):INDEX('Billet Stock Format'!$C:$C,MATCH("As on "&TEXT($B$1,"dd.mm.yyyy"),'Billet Stock Format'!$R:$R,0)+17),$B5&"*"),0) -> 0 | I7: 0.58 | J7: =SUM(D7:I7) -> 0.58
J8: =SUM(D8:I8) -> 0
B9: 160 | C9: OK | D9: =D11-D10 -> 0 | E9: =E11-E10 -> 0 | F9: =F11-F10 -> 0 | G9: =G11-G10 -> 0 | H9: =H11-H10 -> 0 | I9: =SUMIFS('Billet Stock Format'!$G$871:$G$883,'Billet Stock Format'!$B$871:$B$883,"SWADESH") -> 0 | J9: =SUM(D9:I9) -> 0
C10: HOLD | D10: =IFERROR(SUMIFS(INDEX('Billet Stock Format'!$Y:$Y,MATCH("As on "&TEXT($B$1,"dd.mm.yyyy"),'Billet Stock Format'!$R:$R,0)+20):INDEX('Billet Stock Format'!$Y:$Y,MATCH("As on "&TEXT($B$1,"dd.mm.yyyy"),'Billet Stock Format'!$R:$R,0)+24),INDEX('Billet Stock Format'!$X:$X,MATCH("As on "&TEXT($B$1,"dd.mm.yyyy"),'Billet Stock Format'!$R:$R,0)+20):INDEX('Billet Stock Format'!$X:$X,MATCH("As on "&TEXT($B$1,"dd.mm.yyyy"),'Billet Stock Format'!$R:$R,0)+24),IF(D3="MAHASHIVA","Mashiva",IF(D3="SHYAM","Shyam Metalics",D3))&"*"),0) -> 0 | E10: =IFERROR(SUMIFS(INDEX('Billet Stock Format'!$Y:$Y,MATCH("As on "&TEXT($B$1,"dd.mm.yyyy"),'Billet Stock Format'!$R:$R,0)+20):INDEX('Billet Stock Format'!$Y:$Y,MATCH("As on "&TEXT($B$1,"dd.mm.yyyy"),'Billet Stock Format'!$R:$R,0)+24),INDEX('Billet Stock Format'!$X:$X,MATCH("As on "&TEXT($B$1,"dd.mm.yyyy"),'Billet Stock Format'!$R:$R,0)+20):INDEX('Billet Stock Format'!$X:$X,MATCH("As on "&TEXT($B$1,"dd.mm.yyyy"),'Billet Stock Format'!$R:$R,0)+24),IF(E3="MAHASHIVA","Mashiva",IF(E3="SHYAM","Shyam Metalics",E3))&"*"),0) -> 0 | F10: =IFERROR(SUMIFS(INDEX('Billet Stock Format'!$Y:$Y,MATCH("As on "&TEXT($B$1,"dd.mm.yyyy"),'Billet Stock Format'!$R:$R,0)+20):INDEX('Billet Stock Format'!$Y:$Y,MATCH("As on "&TEXT($B$1,"dd.mm.yyyy"),'Billet Stock Format'!$R:$R,0)+24),INDEX('Billet Stock Format'!$X:$X,MATCH("As on "&TEXT($B$1,"dd.mm.yyyy"),'Billet Stock Format'!$R:$R,0)+20):INDEX('Billet Stock Format'!$X:$X,MATCH("As on "&TEXT($B$1,"dd.mm.yyyy"),'Billet Stock Format'!$R:$R,0)+24),IF(F3="MAHASHIVA","Mashiva",IF(F3="SHYAM","Shyam Metalics",F3))&"*"),0) -> 0 | G10: =IFERROR(SUMIFS(INDEX('Billet Stock Format'!$Y:$Y,MATCH("As on "&TEXT($B$1,"dd.mm.yyyy"),'Billet Stock Format'!$R:$R,0)+20):INDEX('Billet Stock Format'!$Y:$Y,MATCH("As on "&TEXT($B$1,"dd.mm.yyyy"),'Billet Stock Format'!$R:$R,0)+24),INDEX('Billet Stock Format'!$X:$X,MATCH("As on "&TEXT($B$1,"dd.mm.yyyy"),'Billet Stock Format'!$R:$R,0)+20):INDEX('Billet Stock Format'!$X:$X,MATCH("As on "&TEXT($B$1,"dd.mm.yyyy"),'Billet Stock Format'!$R:$R,0)+24),IF(G3="MAHASHIVA","Mashiva",IF(G3="SHYAM","Shyam Metalics",G3))&"*"),0) -> 0 | H10: =IFERROR(SUMIFS(INDEX('Billet Stock Format'!$Y:$Y,MATCH("As on "&TEXT($B$1,"dd.mm.yyyy"),'Billet Stock Format'!$R:$R,0)+20):INDEX('Billet Stock Format'!$Y:$Y,MATCH("As on "&TEXT($B$1,"dd.mm.yyyy"),'Billet Stock Format'!$R:$R,0)+24),INDEX('Billet Stock Format'!$X:$X,MATCH("As on "&TEXT($B$1,"dd.mm.yyyy"),'Billet Stock Format'!$R:$R,0)+20):INDEX('Billet Stock Format'!$X:$X,MATCH("As on "&TEXT($B$1,"dd.mm.yyyy"),'Billet Stock Format'!$R:$R,0)+24),IF(H3="MAHASHIVA","Mashiva",IF(H3="SHYAM","Shyam Metalics",H3))&"*"),0) -> 0 | J10: =SUM(D10:I10) -> 0
C11: TOTAL | D11: =IFERROR(SUMIFS(INDEX('Billet Stock Format'!$G:$G,MATCH("As on "&TEXT($B$1,"dd.mm.yyyy"),'Billet Stock Format'!$R:$R,0)+5):INDEX('Billet Stock Format'!$G:$G,MATCH("As on "&TEXT($B$1,"dd.mm.yyyy"),'Billet Stock Format'!$R:$R,0)+17),INDEX('Billet Stock Format'!$B:$B,MATCH("As on "&TEXT($B$1,"dd.mm.yyyy"),'Billet Stock Format'!$R:$R,0)+5):INDEX('Billet Stock Format'!$B:$B,MATCH("As on "&TEXT($B$1,"dd.mm.yyyy"),'Billet Stock Format'!$R:$R,0)+17),IF(D3="MIPPL","MS BILLET",IF(D3="MAHASHIVA","MASHIVA",D3)),INDEX('Billet Stock Format'!$C:$C,MATCH("As on "&TEXT($B$1,"dd.mm.yyyy"),'Billet Stock Format'!$R:$R,0)+5):INDEX('Billet Stock Format'!$C:$C,MATCH("As on "&TEXT($B$1,"dd.mm.yyyy"),'Billet Stock Format'!$R:$R,0)+17),$B9&"*"),0) -> 0 | E11: =IFERROR(SUMIFS(INDEX('Billet Stock Format'!$G:$G,MATCH("As on "&TEXT($B$1,"dd.mm.yyyy"),'Billet Stock Format'!$R:$R,0)+5):INDEX('Billet Stock Format'!$G:$G,MATCH("As on "&TEXT($B$1,"dd.mm.yyyy"),'Billet Stock Format'!$R:$R,0)+17),INDEX('Billet Stock Format'!$B:$B,MATCH("As on "&TEXT($B$1,"dd.mm.yyyy"),'Billet Stock Format'!$R:$R,0)+5):INDEX('Billet Stock Format'!$B:$B,MATCH("As on "&TEXT($B$1,"dd.mm.yyyy"),'Billet Stock Format'!$R:$R,0)+17),IF(E3="MIPPL","MS BILLET",IF(E3="MAHASHIVA","MASHIVA",E3)),INDEX('Billet Stock Format'!$C:$C,MATCH("As on "&TEXT($B$1,"dd.mm.yyyy"),'Billet Stock Format'!$R:$R,0)+5):INDEX('Billet Stock Format'!$C:$C,MATCH("As on "&TEXT($B$1,"dd.mm.yyyy"),'Billet Stock Format'!$R:$R,0)+17),$B9&"*"),0) -> 0 | F11: =IFERROR(SUMIFS(INDEX('Billet Stock Format'!$G:$G,MATCH("As on "&TEXT($B$1,"dd.mm.yyyy"),'Billet Stock Format'!$R:$R,0)+5):INDEX('Billet Stock Format'!$G:$G,MATCH("As on "&TEXT($B$1,"dd.mm.yyyy"),'Billet Stock Format'!$R:$R,0)+17),INDEX('Billet Stock Format'!$B:$B,MATCH("As on "&TEXT($B$1,"dd.mm.yyyy"),'Billet Stock Format'!$R:$R,0)+5):INDEX('Billet Stock Format'!$B:$B,MATCH("As on "&TEXT($B$1,"dd.mm.yyyy"),'Billet Stock Format'!$R:$R,0)+17),IF(F3="MIPPL","MS BILLET",IF(F3="MAHASHIVA","MASHIVA",F3)),INDEX('Billet Stock Format'!$C:$C,MATCH("As on "&TEXT($B$1,"dd.mm.yyyy"),'Billet Stock Format'!$R:$R,0)+5):INDEX('Billet Stock Format'!$C:$C,MATCH("As on "&TEXT($B$1,"dd.mm.yyyy"),'Billet Stock Format'!$R:$R,0)+17),$B9&"*"),0) -> 0 | G11: =IFERROR(SUMIFS(INDEX('Billet Stock Format'!$G:$G,MATCH("As on "&TEXT($B$1,"dd.mm.yyyy"),'Billet Stock Format'!$R:$R,0)+5):INDEX('Billet Stock Format'!$G:$G,MATCH("As on "&TEXT($B$1,"dd.mm.yyyy"),'Billet Stock Format'!$R:$R,0)+17),INDEX('Billet Stock Format'!$B:$B,MATCH("As on "&TEXT($B$1,"dd.mm.yyyy"),'Billet Stock Format'!$R:$R,0)+5):INDEX('Billet Stock Format'!$B:$B,MATCH("As on "&TEXT($B$1,"dd.mm.yyyy"),'Billet Stock Format'!$R:$R,0)+17),IF(G3="MIPPL","MS BILLET",IF(G3="MAHASHIVA","MASHIVA",G3)),INDEX('Billet Stock Format'!$C:$C,MATCH("As on "&TEXT($B$1,"dd.mm.yyyy"),'Billet Stock Format'!$R:$R,0)+5):INDEX('Billet Stock Format'!$C:$C,MATCH("As on "&TEXT($B$1,"dd.mm.yyyy"),'Billet Stock Format'!$R:$R,0)+17),$B9&"*"),0) -> 0 | H11: =IFERROR(SUMIFS(INDEX('Billet Stock Format'!$G:$G,MATCH("As on "&TEXT($B$1,"dd.mm.yyyy"),'Billet Stock Format'!$R:$R,0)+5):INDEX('Billet Stock Format'!$G:$G,MATCH("As on "&TEXT($B$1,"dd.mm.yyyy"),'Billet Stock Format'!$R:$R,0)+17),INDEX('Billet Stock Format'!$B:$B,MATCH("As on "&TEXT($B$1,"dd.mm.yyyy"),'Billet Stock Format'!$R:$R,0)+5):INDEX('Billet Stock Format'!$B:$B,MATCH("As on "&TEXT($B$1,"dd.mm.yyyy"),'Billet Stock Format'!$R:$R,0)+17),IF(H3="MIPPL","MS BILLET",IF(H3="MAHASHIVA","MASHIVA",H3)),INDEX('Billet Stock Format'!$C:$C,MATCH("As on "&TEXT($B$1,"dd.mm.yyyy"),'Billet Stock Format'!$R:$R,0)+5):INDEX('Billet Stock Format'!$C:$C,MATCH("As on "&TEXT($B$1,"dd.mm.yyyy"),'Billet Stock Format'!$R:$R,0)+17),$B9&"*"),0) -> 0 | I11: =SUMIFS('Billet Stock Format'!$G$871:$G$883,'Billet Stock Format'!$B$871:$B$883,"SWADESH") -> 0 | J11: =SUM(D11:I11) -> 0
H13: NOT OK | J13: =J6+J10 -> 0
H14: OK INWARD | J14: =J4+J7+J11-J13-J15 -> 7.491
H15: OK MIPPL | J15: =D7+D11 -> 0
H17: TOTAL | J17: =J13+J14+J15 -> 7.491

Sheet Daily Prod Format
A1: =J2 -> DATE-01-10-2026 | H1: PELLETS | I1: =IFERROR(W3/W2,0) -> 0 | U1: FINES. | V1: LUMPS. | W1: PELLET | X1: LUMPS | Y1: FINES
A2: TOTAL HEAT | B2: 12 | H2: FINES | I2: =IFERROR((U3+Y3)/(U2+Y2),0) -> 0 | J2: DATE-01-10-2026 | U2: =SUMIF(E:E, "OUT SIDE FINES", F:F) -> 0 | V2: =SUMIF(E:E, "OUT SIDE LUMPS", F:F) -> 0 | W2: =SUMIF(E:E, "PELLET", F:F) -> 0 | X2: =SUMIF(E:E, "LUMPS", F:F) -> 0 | Y2: =SUMIF(E:E, "FINES", F:F) -> 0
A3: PRODUCTION | B3: =D13+D19+D31 -> 0 | H3: LUMPS | I3: =IFERROR((V3+X3)/(V2+X2),0) -> 0 | J3: SIZE | K3: 3M | L3: 4M | M3: 5M | N3: 6M | O3: 3M | P3: 4M | Q3: 5M | R3: 6M | U3: =SUMIF(E:E, "OUT SIDE FINES", H:H) -> 0 | V3: =SUMIF(E:E, "OUT SIDE LUMPS", H:H) -> 0 | W3: =SUMIF(E:E, "PELLET", H:H) -> 0 | X3: =SUMIF(E:E, "LUMPS", H:H) -> 0 | Y3: =SUMIF(E:E, "FINES", H:H) -> 0
A4: SIZE (F/L) | D4: QUANTITY(MT) | E4: Raw Slag | J4: 160 | K4: {=INDIRECT("'Prod.'!P18")} -> 0 | L4: {=INDIRECT("'Prod.'!Q18")} -> 0 | M4: {=INDIRECT("'Prod.'!R18")} -> 0 | N4: {=INDIRECT("'Prod.'!S18")} -> 0 | O4: {=INDIRECT("'Prod.'!V18")} -> 0 | P4: {=INDIRECT("'Prod.'!W18")} -> 0 | Q4: {=INDIRECT("'Prod.'!X18")} -> 0 | R4: {=INDIRECT("'Prod.'!Y18")} -> 0 | U4: RAW MATERIAL
A5: (130X130)MMX6M | B5: =R10 -> 0 | D5: =B5*6*0.132335 -> 0 | E5: Slag Jam | J5: 110 | K5: =Prod.!J16 -> 0 | L5: =Prod.!K16 -> 0 | M5: =Prod.!L16 -> 0 | N5: =Prod.!M16 -> 0 | U5: =A1 -> DATE-01-10-2026 | W5: DAILY AVG | X5: MONTHLY AVG
A6: (130X130)MMX4M | B6: =P10 -> 0 | D6: =(B6*4*0.132335) -> 0 | E6: Mag. Material
A7: (130X130)MMX5M | B7: =Q10 -> 0 | D7: =B7*5*0.132335 -> 0 | E7: BILLET END CUT | U7: =E6 -> Mag. Material | V7: =F6 -> 0
A8: (130X130)MMX3M | B8: =O10 -> 0 | D8: =B8*3*0.132335 -> 0 | E8: LUMPS | H8: =F8*G8 -> 0 | U8: =E8 -> LUMPS | V8: =F8 -> 0 | W8: =G8 -> 0
A9: (160X160)MMX3M | B9: =O4 -> 0 | D9: =B9*3*0.198005 -> 0 | E9: PELLET | H9: =F9*G9 -> 0 | J9: SIZE | K9: 3M | L9: 4M | M9: 5M | N9: 6M | O9: 3M | P9: 4M | Q9: 5M | R9: 6M | U9: =E9 -> PELLET | V9: =F9 -> 0 | W9: =G9 -> 0 | X9: =IFERROR($I$1,0) -> 0
A10: (160X160)MMX4M | B10: =P4 -> 0 | D10: =B10*4*0.198005 -> 0 | E10: FINES | H10: =F10*G10 -> 0 | J10: 130 | K10: {=INDIRECT("'Prod.'!P17")} -> 0 | L10: {=INDIRECT("'Prod.'!Q17")} -> 0 | M10: {=INDIRECT("'Prod.'!R17")} -> 0 | N10: {=INDIRECT("'Prod.'!S17")} -> 0 | O10: {=INDIRECT("'Prod.'!V17")} -> 0 | P10: {=INDIRECT("'Prod.'!W17")} -> 0 | Q10: {=INDIRECT("'Prod.'!X17")} -> 0 | R10: {=INDIRECT("'Prod.'!Y17")} -> 0 | U10: =E10 -> FINES | V10: =F10 -> 0 | W10: =G10 -> 0 | X10: =IFERROR($I$2,0) -> 0
A11: (160X160)MMX5M | B11: =Q4 -> 0 | D11: =B11*5*0.198005 -> 0 | E11: OUT SIDE FINES | H11: =F11*G11 -> 0 | U11: =E11 -> OUT SIDE FINES | V11: =F11 -> 0 | W11: =G11 -> 0
A12: (110X110)MMX6M | B12: =N5 -> 0 | D12: =B12*6*0.095 -> 0 | E12: OUT SIDE LUMPS | H12: =F12*G12 -> 0 | U12: =E12 -> OUT SIDE LUMPS | V12: =F12 -> 0 | W12: =G12 -> 0 | X12: =IFERROR($I$3,0) -> 0
A13: TOTAL | D13: =SUM(D5:D12) -> 0 | E13: SCRAP | J13: MIN | K13: =Prod.!C16 -> 0 | L13: =Prod.!D16 -> 0 | M13: =Prod.!E16 -> 0 | N13: =Prod.!F16 -> 0 | O13: =Prod.!G16 -> 0 | U13: =E13 -> SCRAP | V13: =F13-V16 -> 0
A14: SHORT LENGTH | D14: QUANTITY(MT) | E14: MS SCRAP | J14: MAX | K14: =Prod.!C17 -> 0 | L14: =Prod.!D17 -> 0 | M14: =Prod.!E17 -> 0 | N14: =Prod.!F17 -> 0 | O14: =Prod.!G17 -> 0 | U14: =E14 -> MS SCRAP | V14: =F14 -> 0
A15: 160X160XR | D15: =B15*0.199 -> 0 | E15: MS SCRAP-ROLLING MILL | U15: =E15 -> MS SCRAP-ROLLING MILL | V15: =F15 -> 0
A16: 110X110XR | B16: =K5*3+L5*4+M5*5 -> 0 | D16: =B16*0.095 -> 0 | E16: SUPER HEAVY | L16: HOTOUT | U16: =E20 -> C I SCRAP | V16: =F20 -> 0
A17: 130X130XR | D17: =B17*0.133 -> 0 | E17: HEAVY | K17: 160 | U17: TOTAL WEIGHT | V17: =V7+V8+V9+V10+V11+V12+V13+V14+V15+V16 -> 0
